Workbook

Sheet Perfil_Egreso
A1: ANEXO Nº9 PERFIL DE EGRESO CETPRO
A3: DENOMINACIÓN DE LA INSTITUCIÓN | B3: CETPRO JUANJUI | D3: CÓDIGO MODULAR DEL CETPRO | E3: 0533836
A5: SECTOR ECONÓMICO | B5: Actividades profesionales, científicas y técnicas | C5: FAMILIA PRODUCTIVA | D5: Servicios prestados a empresas
A7: ACTIVIDAD ECONÓMICA | B7: Actividades administrativas y de apoyo de oficina y otras actividades de apoyo a las empresas
A10: DENOMINACIÓN DEL PROGRAMA DE ESTUDIOS SEGÚN CNOF (según corresponda) | B10: APOYO ADMINISTRATIVO | D10: CÓDIGO * | E10: M2982-1-002
A12: FORMACIÓN** | B12: AUXILIAR TECNICO | C12: MODALIDAD DEL SERVICIO EDUCATIVO | D12: PRESENCIAL
A14: NIVEL FORMATIVO | B14: AUXILIAR TÉCNICO
A16: DESCRIPCIÓN DEL PERFIL DE EGRESO | F16: Filtrar
A17: El Auxiliar Técnico de Apoyo administrativo es capaz de proveer información, procesar documentación de las distintas áreas de la organización, custodiar la documentación, según políticas y procedimientos de la organización, y normativa correspondiente. Asimismo, se comunica con otros en forma efectiva, busca y analiza información haciendo uso de herramientas informáticas, desarrolla y lidera proyectos o negocios que generen valor y sean sostenibles; estableciendo relaciones con respeto y justicia en el ámbito personal y colectivo, contribuyendo a una convivencia democrática, orientada al bien común, promoviendo prácticas orientadas al cuidado del medio ambiente. | F17: =A17 -> El Auxiliar Técnico de Apoyo administrativo es capaz de proveer información, procesar documentación de las distintas áreas de la organización, custodiar la documentación, según políticas y procedimientos de la organización, y normativa correspondiente. Asimismo, se comunica con otros en forma efectiva, busca y analiza información haciendo uso de herramientas informáticas, desarrolla y lidera proyectos o negocios que generen valor y sean sostenibles; estableciendo relaciones con respeto y justicia en el ámbito personal y colectivo, contribuyendo a una convivencia democrática, orientada al bien común, promoviendo prácticas orientadas al cuidado del medio ambiente.
A18: COMPETENCIAS ESPECÍFICAS (UNIDAD DE COMPETENCIA) | F18: =A18 -> COMPETENCIAS ESPECÍFICAS (UNIDAD DE COMPETENCIA)
A19: UC1. Proveer información, según políticas y procedimientos de la organización, y normativa correspondiente. | F19: =A19 -> UC1. Proveer información, según políticas y procedimientos de la organización, y normativa correspondiente.
A20: UC2. Procesar la documentación de las distintas áreas de la organización, en función a sus políticas y normativa correspondiente. | F20: =A20 -> UC2. Procesar la documentación de las distintas áreas de la organización, en función a sus políticas y normativa correspondiente.
A21: UC3. Custodiar la documentación, según políticas y procedimientos de la organización, y normativa correspondiente. | F21: =A21 -> UC3. Custodiar la documentación, según políticas y procedimientos de la organización, y normativa correspondiente.
F22: =A22 -> 0
F23: =A23 -> 0
F24: =A24 -> 0
F25: =A25 -> 0
F26: =A26 -> 0
F27: =A27 -> 0
F28: =A28 -> 0
A29: COMPETENCIAS PARA LA EMPLEABILIDAD | F29: =A29 -> COMPETENCIAS PARA LA EMPLEABILIDAD
A30: CE1 Comunicación efectiva.- Expresar de manera clara los conceptos, ideas, sentimientos, hechos y opiniones en forma oral y escrita para comunicarse e interactuar con otras personas en contextos sociales y laborales diversos. (UD) | F30: =A30 -> CE1 Comunicación efectiva.- Expresar de manera clara los conceptos, ideas, sentimientos, hechos y opiniones en forma oral y escrita para comunicarse e interactuar con otras personas en contextos sociales y laborales diversos. (UD)
A31: CE2 Tecnologías de la información.- Manejar herramientas informáticas de las TIC para buscar y analizar información, comunicarse y realizar procedimientos o tareas vinculadas al área profesional, de acuerdo a los requerimientos de su entorno laboral.(UD) | F31: =A31 -> CE2 Tecnologías de la información.- Manejar herramientas informáticas de las TIC para buscar y analizar información, comunicarse y realizar procedimientos o tareas vinculadas al área profesional, de acuerdo a los requerimientos de su entorno laboral.(UD)
A32: CE3 Emprendimiento.- Identificar nuevas oportunidades de proyectos o negocios que generen valor y sean sostenibles, gestionando recursos para su funcionamiento con creatividad y ética, articulando acciones que permitan desarrollar innovaciones en la creación de bienes y/o servicios, así como en procesos o productos ya existentes. (UD) | F32: =A32 -> CE3 Emprendimiento.- Identificar nuevas oportunidades de proyectos o negocios que generen valor y sean sostenibles, gestionando recursos para su funcionamiento con creatividad y ética, articulando acciones que permitan desarrollar innovaciones en la creación de bienes y/o servicios, así como en procesos o productos ya existentes. (UD)
A33: CE4 Ética.-Establecer relaciones con respeto y justicia en los ámbitos personal, colectivo e institucional, contribuyendo a una convivencia democrática, orientada al bien común que considere la diversidad y dignidad de las personas, teniendo en cuenta las consideraciones aplicadas en su contexto laboral.(UD) | F33: =A33 -> CE4 Ética.-Establecer relaciones con respeto y justicia en los ámbitos personal, colectivo e institucional, contribuyendo a una convivencia democrática, orientada al bien común que considere la diversidad y dignidad de las personas, teniendo en cuenta las consideraciones aplicadas en su contexto laboral.(UD)
A34: CE5 Liderazgo personal y profesional.- Articular recursos y potencialidades de cada integrante de su equipo logrando un trabajo comprometido, colaborativo, creativo, ético, sensible a su contexto social y ambiente, en pro del bien común. (T) | F34: =A34 -> CE5 Liderazgo personal y profesional.- Articular recursos y potencialidades de cada integrante de su equipo logrando un trabajo comprometido, colaborativo, creativo, ético, sensible a su contexto social y ambiente, en pro del bien común. (T)
A35: CE6 Cultura ambiental.- Convivir de manera ética, autónoma, responsable y sostenible, previniendo, reduciendo y controlando permanente y progresivamente los impactos ambientales. (T) | F35: =A35 -> CE6 Cultura ambiental.- Convivir de manera ética, autónoma, responsable y sostenible, previniendo, reduciendo y controlando permanente y progresivamente los impactos ambientales. (T)
F36: =A36 -> 0
F37: =A37 -> 0
F38: =A38 -> 0
F39: =A39 -> 0
F40: =A40 -> 0
F41: =A41 -> 0
A42: ÁMBITOS DE DESEMPEÑO | F42: =A42 -> ÁMBITOS DE DESEMPEÑO
A43: Desarrolla su actividad en las siguientes áreas: - Area administrativa. - Área de atención al cliente o usuario. - Área de archivo de documentos. - Area administrativa de Call Center. -Area de información -Area de recepción -Area de lógistica y almacén -Mesa de partes -Area de digitalización | F43: =A43 -> Desarrolla su actividad en las siguientes áreas: - Area administrativa. - Área de atención al cliente o usuario. - Área de archivo de documentos. - Area administrativa de Call Center. -Area de información -Area de recepción -Area de lógistica y almacén -Mesa de partes -Area de digitalización
A44: Pautas Generales: 1. Descripción del perfil de egreso: Descripción general y breve de los desempeños que será capaz de realizar el egresado en el campo laboral, al concluir el programa de estudio en correspondencia con las competencias técnicas y de empleabilidad. 2. Competencias específicas: Transcripción de las unidades de competencia del programa de estudio, establecido en el CNOF. En caso de que el programa no se encuentre en el CNOF se tomarán las Unidades de Competencias definidas mediante el análisis de la actividad económica correspondiente. 3. Las competencias para la empleabilidad: son priorizadas por la institución educativa, en concordancia con los Lineamientos Académicos Generales establecidos por el MINEDU y su modelo educativo. Se debe distinguir los que se abordarán como unidad didáctica (UD), de manera transversal (T) o ambas (UD/T) 4. Ámbitos de desempeño: Listar los campos o áreas laborales en los cuales el egresado del programa de estudio se podrá insertar. *Se considera el código del programa de estudios del CNOF, de ser el caso. ** Indicar sólo en el caso de que sea Dual o En Alternancia, caso contrario dejar la celda en blanco. | F44: =A44 -> Pautas Generales: 1. Descripción del perfil de egreso: Descripción general y breve de los desempeños que será capaz de realizar el egresado en el campo laboral, al concluir el programa de estudio en correspondencia con las competencias técnicas y de empleabilidad. 2. Competencias específicas: Transcripción de las unidades de competencia del programa de estudio, establecido en el CNOF. En caso de que el programa no se encuentre en el CNOF se tomarán las Unidades de Competencias definidas mediante el análisis de la actividad económica correspondiente. 3. Las competencias para la empleabilidad: son priorizadas por la institución educativa, en concordancia con los Lineamientos Académicos Generales establecidos por el MINEDU y su modelo educativo. Se debe distinguir los que se abordarán como unidad didáctica (UD), de manera transversal (T) o ambas (UD/T) 4. Ámbitos de desempeño: Listar los campos o áreas laborales en los cuales el egresado del programa de estudio se podrá insertar. *Se considera el código del programa de estudios del CNOF, de ser el caso. ** Indicar sólo en el caso de que sea Dual o En Alternancia, caso contrario dejar la celda en blanco.

Sheet Programa_Estudio
A1: ANEXO Nº 8 PROGRAMA DE ESTUDIOS CETPRO
A3: =Perfil_Egreso!A3 -> DENOMINACIÓN DE LA INSTITUCIÓN | B3: =Perfil_Egreso!B3 -> CETPRO JUANJUI | D3: =Perfil_Egreso!D3 -> CÓDIGO MODULAR DEL CETPRO | E3: =Perfil_Egreso!E3 -> 0533836
A5: SECTOR ECONÓMICO | B5: =Perfil_Egreso!B5 -> Actividades profesionales, científicas y técnicas | C5: FAMILIA PRODUCTIVA | D5: =Perfil_Egreso!D5 -> Servicios prestados a empresas | E5: ACTIVIDAD ECONÓMICA | F5: =Perfil_Egreso!B7 -> Actividades administrativas y de apoyo de oficina y otras actividades de apoyo a las empresas
A7: DENOMINACIÓN DEL PROGRAMA DE ESTUDIOS SEGÚN CNOF (según corresponda) | B7: =Perfil_Egreso!B10 -> APOYO ADMINISTRATIVO | E7: CÓDIGO DE SER EL CASO * | F7: =Perfil_Egreso!E10 -> M2982-1-002
A9: NIVEL FORMATIVO | B9: =Perfil_Egreso!B14 -> AUXILIAR TÉCNICO | C9: N°. HORAS: | D9: =Itinerario!W17 -> 1072 | E9: N° CRÉDITOS: | F9: =Itinerario!T17 -> 40
A11: FORMACIÓN** | D11: MODALIDAD DEL SERVICIO EDUCATIVO | E11: =Perfil_Egreso!D12 -> PRESENCIAL
A13: COMPETENCIAS ESPECÍFICAS (UNIDAD DE COMPETENCIA)
A14: UNIDAD DE COMPETENCIA | C14: INDICADORES DE LOGRO DE LA COMPETENCIA | G14: Filtro
A15: =CONCATENATE("Unidad de Competencia N° 01 (UC1): ",Perfil_Egreso!A19) -> Unidad de Competencia N° 01 (UC1): UC1. Proveer información, según políticas y procedimientos de la organización, y normativa correspondiente. | C15: 1. Recopila datos o documentación, según políticas, procedimientos, y normativa de la organización. | G15: =C15 -> 1. Recopila datos o documentación, según políticas, procedimientos, y normativa de la organización.
C16: 2. Prepara datos o documentación, según políticas, procedimientos y normativa de la organización. | G16: =C16 -> 2. Prepara datos o documentación, según políticas, procedimientos y normativa de la organización.
C17: 3. Realiza el trámite de datos y documentos, según políticas, procedimientos y normativa de la organización. | G17: =C17 -> 3. Realiza el trámite de datos y documentos, según políticas, procedimientos y normativa de la organización.
G18: =C18 -> 0
G19: =C19 -> 0
G20: =C20 -> 0
G21: =C21 -> 0
G22: =C22 -> 0
G23: =C23 -> 0
G29: =C29 -> 0
A30: =CONCATENATE("Unidad de Competencia N° 02 (UC2): ",Perfil_Egreso!A20) -> Unidad de Competencia N° 02 (UC2): UC2. Procesar la documentación de las distintas áreas de la organización, en función a sus políticas y normativa correspondiente. | C30: 1. Recepciona y atiende los documentos, en función a los objetivos de la organización y procedimientos establecidos. | G30: =C30 -> 1. Recepciona y atiende los documentos, en función a los objetivos de la organización y procedimientos establecidos.
C31: 2. Realiza actividades administrativas de apoyo2, en función de los objetivos de la organización y el área asignada. | G31: =C31 -> 2. Realiza actividades administrativas de apoyo2, en función de los objetivos de la organización y el área asignada.
C32: 3. Atiende las comunicaciones y/o centro de atención virtual, en función a los objetivos de la organización y procedimientos establecidos. | G32: =C32 -> 3. Atiende las comunicaciones y/o centro de atención virtual, en función a los objetivos de la organización y procedimientos establecidos.
C33: 4. Atiende los consultas, según los procedimientos establecidos y normativa correspondiente. | G33: =C33 -> 4. Atiende los consultas, según los procedimientos establecidos y normativa correspondiente.
C34: 5. Revisa la información, en función a los requerimientos de la organización y procedimientos establecidos. | G34: =C34 -> 5. Revisa la información, en función a los requerimientos de la organización y procedimientos establecidos.
G35: =C35 -> 0
G36: =C36 -> 0
G37: =C37 -> 0
G38: =C38 -> 0
G44: =C44 -> 0
A45: =CONCATENATE("Unidad de Competencia N° 03 (UC3): ",Perfil_Egreso!A21) -> Unidad de Competencia N° 03 (UC3): UC3. Custodiar la documentación, según políticas y procedimientos de la organización, y normativa correspondiente. | C45: 1. Cataloga datos de los documentos, según políticas, procedimientos de la organización, y normativa correspondiente. | G45: =C45 -> 1. Cataloga datos de los documentos, según políticas, procedimientos de la organización, y normativa correspondiente.
C46: 2. Archiva los documentos, según políticas y procedimientos de la organización, y normativa correspondiente. | G46: =C46 -> 2. Archiva los documentos, según políticas y procedimientos de la organización, y normativa correspondiente.
G47: =C47 -> 0
G48: =C48 -> 0
G49: =C49 -> 0
G50: =C50 -> 0
G51: =C51 -> 0
G52: =C52 -> 0
G53: =C53 -> 0
G59: =C59 -> 0
A60: =CONCATENATE("Unidad de Competencia N° 04 (UC4): ",Perfil_Egreso!A22) -> Unidad de Competencia N° 04 (UC4): | G60: =C60 -> 0
G61: =C61 -> 0
...

Sheet Capacidades
C1: FORMATO DE PROCESO - FORMULACIÓN DE CAPACIDADES E INDICADORES POR UNIDAD DE COMPETENCIA
C5: Programa de estudios: | E5: =Perfil_Egreso!B10 -> APOYO ADMINISTRATIVO | L5: RESUMEN
D7: Capacidades asociadas a la Unidad de Competencia Específica y de Empleabilidad | H7: Indicadores de la Capacidad
A9: MÓDULOS | B9: Tipo de capacidad | C9: Código Capacidad | D9: Verbo | E9: Objeto | F9: Condición | G9: Código Indicador | H9: Verbo | I9: Objeto | J9: Condición | K9: Observaciones de los facilitadores opcional | L9: Capacidades | M9: Indicadores
A10: Módulo I | B10: Capacidad técnica | C10: UC1 C1 | D10: Organizar | E10: el área de trabajo, equipos y materiales | F10: teniendo en cuenta las normas de seguridad laboral y ambiental. | G10: C1 I1 | H10: Explica | I10: la estructura organizacional de la empresa | J10: de acuerdo a los manuales internos de organización. | L10: =CONCATENATE(C10," ",D10," ",E10," ",F10," ",C11," ",D11," ",E11," ",F11) -> UC1 C1 Organizar el área de trabajo, equipos y materiales teniendo en cuenta las normas de seguridad laboral y ambiental. | M10: =CONCATENATE(G10," ",H10," ",I10," ",J10) -> C1 I1 Explica la estructura organizacional de la empresa de acuerdo a los manuales internos de organización.
G11: C1 I2 | H11: Identifica | I11: los ambientes de trabajo, equipos y materiales | J11: tomando en cuenta sus características y funcionalidad. | M11: =CONCATENATE(G11," ",H11," ",I11," ",J11) -> C1 I2 Identifica los ambientes de trabajo, equipos y materiales tomando en cuenta sus características y funcionalidad.
G12: C1 I3 | H12: Opera | I12: los equipos de oficina | J12: de acuerdo al manual de operaciones. | M12: =CONCATENATE(G12," ",H12," ",I12," ",J12) -> C1 I3 Opera los equipos de oficina de acuerdo al manual de operaciones.
G13: C1 I4 | H13: Realiza | I13: la organización del ambiente de trabajo, equipos y materiales, | J13: teniendo en cuenta las normas de seguridad e higiene y protocolos de bioseguridad | M13: =CONCATENATE(G13," ",H13," ",I13," ",J13) -> C1 I4 Realiza la organización del ambiente de trabajo, equipos y materiales, teniendo en cuenta las normas de seguridad e higiene y protocolos de bioseguridad
M14: =CONCATENATE(G14," ",H14," ",I14," ",J14)
M15: =CONCATENATE(G15," ",H15," ",I15," ",J15)
M16: =CONCATENATE(G16," ",H16," ",I16," ",J16)
M17: =CONCATENATE(G17," ",H17," ",I17," ",J17)
M18: =CONCATENATE(G18," ",H18," ",I18," ",J18)
M19: =CONCATENATE(G19," ",H19," ",I19," ",J19)
A20: Módulo I | B20: Capacidad técnica | C20: UC1 C2 | D20: Elaborar | E20: documentos administrativos y/o mercantiles | F20: de acuerdo a las características y estructuras de las mismas, aplicando técnicas de redacción, reglas ortográficas y gramaticales . | G20: C2 I1 | H20: Identifica | I20: los diverso tipos de documentos administrativos | J20: de acuerdo a las políticas y normativas de la organización. | L20: =CONCATENATE(C20," ",D20," ",E20," ",F20," ",C21," ",D21," ",E21," ",F21) -> UC1 C2 Elaborar documentos administrativos y/o mercantiles de acuerdo a las características y estructuras de las mismas, aplicando técnicas de redacción, reglas ortográficas y gramaticales . | M20: =CONCATENATE(G20," ",H20," ",I20," ",J20) -> C2 I1 Identifica los diverso tipos de documentos administrativos de acuerdo a las políticas y normativas de la organización.
G21: C2 I2 | H21: Redacta | I21: los documentos administrativos | J21: aplicando las técnicas de redacción, reglas ortográficas y gramaticales, de acuerdo a las políticas y normativas de la organización. | M21: =CONCATENATE(G21," ",H21," ",I21," ",J21) -> C2 I2 Redacta los documentos administrativos aplicando las técnicas de redacción, reglas ortográficas y gramaticales, de acuerdo a las políticas y normativas de la organización.
G22: C2 I3 | H22: Realiza | I22: el llenado de los documentos administrativos y/o mercantiles | J22: aplicando reglas ortográficas y gramaticales, de acuerdo a las políticas y normativas de la organización. | M22: =CONCATENATE(G22," ",H22," ",I22," ",J22) -> C2 I3 Realiza el llenado de los documentos administrativos y/o mercantiles aplicando reglas ortográficas y gramaticales, de acuerdo a las políticas y normativas de la organización.
G23: C2 I4 | H23: Verifica | I23: la calidad de los documentos administrativos y/o mercantiles | J23: de acuerdo a la información correspondiente, aplicando reglas ortográficas y gramaticales. | M23: =CONCATENATE(G23," ",H23," ",I23," ",J23) -> C2 I4 Verifica la calidad de los documentos administrativos y/o mercantiles de acuerdo a la información correspondiente, aplicando reglas ortográficas y gramaticales.
M24: =CONCATENATE(G24," ",H24," ",I24," ",J24)
M25: =CONCATENATE(G25," ",H25," ",I25," ",J25)
M26: =CONCATENATE(G26," ",H26," ",I26," ",J26)
M27: =CONCATENATE(G27," ",H27," ",I27," ",J27)
M28: =CONCATENATE(G28," ",H28," ",I28," ",J28)
M29: =CONCATENATE(G29," ",H29," ",I29," ",J29)
A30: Módulo I | B30: Capacidad técnica | C30: UC1 C3 | D30: Realizar | E30: el trámite de datos y documentos, | F30: de acuerdo a los procedimientos, normativa vigente y políticas de la organización. | G30: C3 I1 | H30: Explica | I30: un diagrama de flujo documentario | J30: de acuerdo a los procedimientos, normativa vigente y políticas de la organización. | L30: =CONCATENATE(C30," ",D30," ",E30," ",F30," ",C31," ",D31," ",E31," ",F31) -> UC1 C3 Realizar el trámite de datos y documentos, de acuerdo a los procedimientos, normativa vigente y políticas de la organización. | M30: =CONCATENATE(G30," ",H30," ",I30," ",J30) -> C3 I1 Explica un diagrama de flujo documentario de acuerdo a los procedimientos, normativa vigente y políticas de la organización.
G31: C3 I2 | H31: Organiza | I31: el procedimiento de registro y recepción del flujo documentario | J31: de acuerdo a los procedimientos, normativa vigente y políticas de la organización. | M31: =CONCATENATE(G31," ",H31," ",I31," ",J31) -> C3 I2 Organiza el procedimiento de registro y recepción del flujo documentario de acuerdo a los procedimientos, normativa vigente y políticas de la organización.
G32: C3 I3 | H32: Ejecuta | I32: la organización y traslado de expedientes | J32: de acuerdo a los procedimientos, normativa vigente y políticas de la organización. | M32: =CONCATENATE(G32," ",H32," ",I32," ",J32) -> C3 I3 Ejecuta la organización y traslado de expedientes de acuerdo a los procedimientos, normativa vigente y políticas de la organización.
G33: C3 I4 | H33: Efectúa | I33: el control del traslado de los expedientes y/o documentos | J33: de acuerdo a los procedimientos, normativa vigente y políticas de la organización. | M33: =CONCATENATE(G33," ",H33," ",I33," ",J33) -> C3 I4 Efectúa el control del traslado de los expedientes y/o documentos de acuerdo a los procedimientos, normativa vigente y políticas de la organización.
G34: C3 I5 | H34: Informa | I34: al usuario sobre el trámite documentario | J34: de acuerdo a los procedimientos, normativa vigente y políticas de la organización. | M34: =CONCATENATE(G34," ",H34," ",I34," ",J34) -> C3 I5 Informa al usuario sobre el trámite documentario de acuerdo a los procedimientos, normativa vigente y políticas de la organización.
M35: =CONCATENATE(G35," ",H35," ",I35," ",J35)
M36: =CONCATENATE(G36," ",H36," ",I36," ",J36)
M37: =CONCATENATE(G37," ",H37," ",I37," ",J37)
M38: =CONCATENATE(G38," ",H38," ",I38," ",J38)
M39: =CONCATENATE(G39," ",H39," ",I39," ",J39)
A40: Módulo I | B40: Capacidad técnica | L40: =CONCATENATE(C40," ",D40," ",E40," ",F40," ",C41," ",D41," ",E41," ",F41) | M40: =CONCATENATE(G40," ",H40," ",I40," ",J40)
M41: =CONCATENATE(G41," ",H41," ",I41," ",J41)
M42: =CONCATENATE(G42," ",H42," ",I42," ",J42)
M43: =CONCATENATE(G43," ",H43," ",I43," ",J43)
M44: =CONCATENATE(G44," ",H44," ",I44," ",J44)
M45: =CONCATENATE(G45," ",H45," ",I45," ",J45)
...

Sheet Organización_Modular
A1: ORGANIZACIÓN MODULAR
A3: DENOMINACIÓN DE LA INSTITUCIÓN | C3: =Perfil_Egreso!B3 -> CETPRO JUANJUI | F3: CÓDIGO MODULAR | G3: =Perfil_Egreso!E3 -> 0533836
A5: =Perfil_Egreso!A10 -> DENOMINACIÓN DEL PROGRAMA DE ESTUDIOS SEGÚN CNOF (según corresponda) | C5: =Perfil_Egreso!B10 -> APOYO ADMINISTRATIVO | D5: CÓDIGO * | E5: =Perfil_Egreso!E10 -> M2982-1-002 | F5: NIVEL FORMATIVO | G5: =Perfil_Egreso!B14 -> AUXILIAR TÉCNICO
A7: =Perfil_Egreso!A12 -> FORMACIÓN** | C7: =Perfil_Egreso!B12 -> AUXILIAR TECNICO | E7: MODALIDAD DEL SERVICIO EDUCATIVO | F7: =Perfil_Egreso!D12 -> PRESENCIAL
H8: Información solo de proceso
A9: MÓDULO | B9: DESCRIPCIÓN DE LA COMPETENCIA | D9: CAPACIDADES | F9: UNIDAD DIDÁCTICA | G9: PERIODO ACADÉMICO | H9: Crédito teórico | I9: Crédito práctico | J9: T.créditos (Filtrar)
A10: MÓDULO I: REDACCIÓN Y TRÁMITE DOCUMENTARIO | B10: Competencias técnicas (Unidad de competencia) | C10: UC1 Proveer información, según políticas y procedimientos de la organización, y normativa correspondiente. | D10: =OFFSET(Capacidades!$A$1,(ROW()-9)*10-1,11) -> UC1 C1 Organizar el área de trabajo, equipos y materiales teniendo en cuenta las normas de seguridad laboral y ambiental. | F10: Organización del área de trabajo | G10: I | H10: 1 | I10: 1 | J10: =SUM(H10:I10) -> 2
D11: =OFFSET(Capacidades!$A$1,(ROW()-9)*10-1,11) -> UC1 C2 Elaborar documentos administrativos y/o mercantiles de acuerdo a las características y estructuras de las mismas, aplicando técnicas de redacción, reglas ortográficas y gramaticales . | F11: Redacción de documentos | G11: I | H11: 2 | I11: 2 | J11: =SUM(H11:I11) -> 4
D12: =OFFSET(Capacidades!$A$1,(ROW()-9)*10-1,11) -> UC1 C3 Realizar el trámite de datos y documentos, de acuerdo a los procedimientos, normativa vigente y políticas de la organización. | F12: Trámite documentario | G12: I | H12: 2 | I12: 2 | J12: =SUM(H12:I12) -> 4
D13: =OFFSET(Capacidades!$A$1,(ROW()-9)*10-1,11)
D14: =OFFSET(Capacidades!$A$1,(ROW()-9)*10-1,11) | J14: =SUM(H14:I14) -> 0
D15: =OFFSET(Capacidades!$A$1,(ROW()-9)*10-1,11) | J15: =SUM(H15:I15) -> 0
D16: =OFFSET(Capacidades!$A$1,(ROW()-9)*10-1,11) | J16: =SUM(H16:I16) -> 0
D17: =OFFSET(Capacidades!$A$1,(ROW()-9)*10-1,11) | J17: =SUM(H17:I17) -> 0
D18: =OFFSET(Capacidades!$A$1,(ROW()-9)*10-1,11) | J18: =SUM(H18:I18) -> 0
D19: =OFFSET(Capacidades!$A$1,(ROW()-9)*10-1,11) | J19: =SUM(H19:I19) -> 0
D20: =OFFSET(Capacidades!$A$1,(ROW()-9)*10-1,11) | J20: =SUM(H20:I20) -> 0
D21: =OFFSET(Capacidades!$A$1,(ROW()-9)*10-1,11) | J21: =SUM(H21:I21) -> 0
D22: =OFFSET(Capacidades!$A$1,(ROW()-9)*10-1,11) | J22: =SUM(H22:I22) -> 0
D23: =OFFSET(Capacidades!$A$1,(ROW()-9)*10-1,11) | J23: =SUM(H23:I23) -> 0
D24: =OFFSET(Capacidades!$A$1,(ROW()-9)*10-1,11) | J24: =SUM(H24:I24) -> 0
D25: =OFFSET(Capacidades!$A$1,(ROW()-9)*10-1,11) | J25: =SUM(H25:I25) -> 0
... D29: =OFFSET(Capacidades!$A$1,(ROW()-9)*10-1,11) | J29: =SUM(H29:I29) -> 0
B30: Competencias para la empleabilidad | C30: CE1 Comunicación efectiva. - Expresar de manera clara los conceptos, ideas, sentimientos, hechos y opiniones en forma oral y escrita para comunicarse e interactuar con otras personas en contextos sociales y laborales diversos. (UD) CE2 Tecnologías de la información. - Manejar herramientas informáticas de las TIC para buscar y analizar información, Comunicarse y realizar procedimientos o tareas vinculadas al área profesional, de acuerdo a los requerimientos de su entorno laboral. (UD) | D30: =OFFSET(Capacidades!$A$1,(ROW()-9)*10-1,11) -> CE1 C1 Comunicar conceptos, ideas, opiniones, sentimientos y hechos en forma oral en situaciones relacionadas a su entorno personal y profesional. CE1 C2 Transmitir conceptos, ideas, opiniones, sentimientos y hechos en forma escrita en situaciones relacionadas a su entorno social y laboral. | F30: Comunicación para el desarrollo personal y profesional | G30: I | H30: 1 | I30: 1 | J30: =SUM(H30:I30) -> 2
D31: =OFFSET(Capacidades!$A$1,(ROW()-9)*10-1,11) -> CE2 C1 Utilizar aplicaciones y herramientas informáticas de las TIC de manera responsable y técnica. CE2 C2 Emplear software en la realización de tareas y requerimientos vinculados a su programa de estudios. | F31: Aplicaciones de herramientas informáticas | G31: I | H31: 1 | I31: 1 | J31: =SUM(H31:I31) -> 2
D32: =OFFSET(Capacidades!$A$1,(ROW()-9)*10-1,11) | J32: =SUM(H32:I32) -> 0
D33: =OFFSET(Capacidades!$A$1,(ROW()-9)*10-1,11) | J33: =SUM(H33:I33) -> 0
D34: =OFFSET(Capacidades!$A$1,(ROW()-9)*10-1,11) | J34: =SUM(H34:I34) -> 0
D35: =OFFSET(Capacidades!$A$1,(ROW()-9)*10-1,11) | J35: =SUM(H35:I35) -> 0
D36: =OFFSET(Capacidades!$A$1,(ROW()-9)*10-1,11) | J36: =SUM(H36:I36) -> 0
D37: =OFFSET(Capacidades!$A$1,(ROW()-9)*10-1,11) | J37: =SUM(H37:I37) -> 0
D38: =OFFSET(Capacidades!$A$1,(ROW()-9)*10-1,11) | J38: =SUM(H38:I38) -> 0
D39: =OFFSET(Capacidades!$A$1,(ROW()-9)*10-1,11) | J39: =SUM(H39:I39) -> 0
B40: Experiencias formativas en situaciones reales de trabajo (ESRT) | G40: Taller del programa "Apoyo administrativo" | H40: 0 | I40: 6 | J40: 6
A41: MÓDULO II: PROCESAMIENTO Y ARCHIVO DOCUMENTARIO | B41: =$B$10 -> Competencias técnicas (Unidad de competencia) | C41: UC2 Procesar la documentación de las distintas áreas de la organización, en función a sus políticas y normativa correspondiente. UC3 Custodiar la documentación, según políticas y procedimientos de la organización, y normativa correspondiente. | D41: =OFFSET(Capacidades!$A$302,(ROW()-40)*10-1,11) -> UC2 C1 Realizar el procesamiento y transmisión de la información y/o documentación, teniendo en cuenta los medios adecuados, la confiabilidad, en función a los objetivos de la organización y procedimientos establecidos. | F41: Recepción y procesamiento de la información | G41: II | H41: 1 | I41: 1 | J41: =SUM(H41:I41) -> 2
D42: =OFFSET(Capacidades!$A$302,(ROW()-40)*10-1,11) -> UC2 C2 Ejecutar actividades administrativas de apoyo2, en función de los objetivos de la organización, los procedimientos establecidos y el área asignada. | F42: Actividades administrativas | G42: II | H42: 0 | I42: 1 | J42: =SUM(H42:I42) -> 1
D43: =OFFSET(Capacidades!$A$302,(ROW()-40)*10-1,11) -> UC2 C3 Atender las comunicaciones, consultas, y/o centro de atención virtual, utilizando los medios adecuados y protocolos de la organización. | F43: Atención al público | G43: II | H43: 1 | I43: 1 | J43: =SUM(H43:I43) -> 2
D44: =OFFSET(Capacidades!$A$302,(ROW()-40)*10-1,11) -> UC2 C4 Realiza la revisisón de información y/o documentación en función a los requerimientos de la organización y procedimientos establecidos. | F44: Control y registro documentario | G44: II | H44: 0 | I44: 1 | J44: =SUM(H44:I44) -> 1
D45: =OFFSET(Capacidades!$A$302,(ROW()-40)*10-1,11) -> UC3 C1 Organizar el sistema de gestión de archivos según políticas de la organización y normativa vigente. UC3 C2 Realizar la clasificación de documentos según políticas de la organización y normativa vigente. | F45: Organización del sistema de gestión de archivos | G45: II | H45: 1 | I45: 1 | J45: =SUM(H45:I45) -> 2
D46: =OFFSET(Capacidades!$A$302,(ROW()-40)*10-1,11) -> UC3 C3 Archivar los documentos de gestión según políticas de la organización y normativa vigente. UC3 C4 Realizar el archivo, mantenimiento y conservación de los documentos según políticas de la organización y normativa vigente. | F46: Archivos, mantenimiento y conservación de documentos | G46: II | H46: 1 | I46: 1 | J46: =SUM(H46:I46) -> 2
...

Sheet M1
A1: ORGANIZACIÓN DE LOS ELEMENTOS DEL MÓDULO
A3: DENOMINACIÓN DE LA INSTITUCIÓN | B3: =Perfil_Egreso!B3 -> CETPRO JUANJUI | F3: CÓDIGO MODULAR DEL INSTITUTO | I3: =Perfil_Egreso!E3 -> 0533836
A5: SECTOR ECONÓMICO | B5: =Perfil_Egreso!B5 -> Actividades profesionales, científicas y técnicas | C5: FAMILIA PRODUCTIVA | D5: =Perfil_Egreso!D5 -> Servicios prestados a empresas | F5: ACTIVIDAD ECONÓMICA | I5: =Perfil_Egreso!B7 -> Actividades administrativas y de apoyo de oficina y otras actividades de apoyo a las empresas
A7: =Perfil_Egreso!A10 -> DENOMINACIÓN DEL PROGRAMA DE ESTUDIOS SEGÚN CNOF (según corresponda) | B7: =Perfil_Egreso!B10 -> APOYO ADMINISTRATIVO | F7: CÓDIGO * | I7: =Perfil_Egreso!E10 -> M2982-1-002
A9: =Perfil_Egreso!A12 -> FORMACIÓN** | B9: =Perfil_Egreso!B12 -> AUXILIAR TECNICO | C9: N°. HORAS: | D9: =Itinerario!W17 -> 1072 | F9: N° CRÉDITOS: | I9: =Itinerario!T17 -> 40
A11: =Perfil_Egreso!C12 -> MODALIDAD DEL SERVICIO EDUCATIVO | B11: =Perfil_Egreso!D12 -> PRESENCIAL | F11: =Perfil_Egreso!A14 -> NIVEL FORMATIVO | I11: =Perfil_Egreso!B14 -> AUXILIAR TÉCNICO
A13: UNIDAD DE COMPETENCIA DEL CATÁLOGO NACIONAL DE LA OFERTA FORMATIVA
A14: =Organización_Modular!C10 -> UC1 Proveer información, según políticas y procedimientos de la organización, y normativa correspondiente.
A15: DENOMINACIÓN DEL MÓDULO | B15: =Organización_Modular!A10 -> MÓDULO I: REDACCIÓN Y TRÁMITE DOCUMENTARIO
A16: CAPACIDADES TÉCNICAS O ESPECÍFICAS | B16: INDICADORES DE LOGRO DE LA CAPACIDAD | C16: CONTENIDOS | D16: UNIDAD DIDÁCTICA | E16: Periodo | F16: CRÉDITOS | H16: CRÉDITOS | I16: HORAS | K16: HORAS | L16: PERFIL DOCENTE | M16: Filtrar
F17: Teórico | G17: Práctica | I17: Teórico | J17: Práctica
A18: =Capacidades!L10 -> UC1 C1 Organizar el área de trabajo, equipos y materiales teniendo en cuenta las normas de seguridad laboral y ambiental. | B18: =Capacidades!M10 -> C1 I1 Explica la estructura organizacional de la empresa de acuerdo a los manuales internos de organización. | C18: Empresa. Tipos de Empresa. Instituciones gubernamentales, no gubernamentales.- Estructura organizacional: - Organigramas, tipos. | D18: =Organización_Modular!F10 -> Organización del área de trabajo | E18: =Organización_Modular!G10 -> I | F18: =Organización_Modular!H10 -> 1 | G18: =Organización_Modular!I10 -> 1 | H18: =SUM(F18:G18) -> 2 | I18: =F18*16 -> 16 | J18: =G18*32 -> 32 | K18: =SUM(I18:J18) -> 48 | L18: TECNICO PROFESIONAL EN ADMINISTRACION DE EMPRESAS, CONTABILIDAD Y PROFESIONAL EN PEDAGOGIA | M18: =B18 -> C1 I1 Explica la estructura organizacional de la empresa de acuerdo a los manuales internos de organización.
B19: =Capacidades!M11 -> C1 I2 Identifica los ambientes de trabajo, equipos y materiales tomando en cuenta sus características y funcionalidad. | C19: - Organización del ambiente, muebles, equipos, herramientas y materiales. - normas de seguridad laboral y ambiental. - La PC, aplicaciones y dispositivos. - Entorno Windows. - Herramientas digitales. | M19: =B19 -> C1 I2 Identifica los ambientes de trabajo, equipos y materiales tomando en cuenta sus características y funcionalidad.
B20: =Capacidades!M12 -> C1 I3 Opera los equipos de oficina de acuerdo al manual de operaciones. | C20: Equipo manuales. Tipos. Características. Funcionalidad. Equipos electrónicos. Tipos. Características. Funcionalidad. | M20: =B20 -> C1 I3 Opera los equipos de oficina de acuerdo al manual de operaciones.
B21: =Capacidades!M13 -> C1 I4 Realiza la organización del ambiente de trabajo, equipos y materiales, teniendo en cuenta las normas de seguridad e higiene y protocolos de bioseguridad | C21: Distribución de equipos, materiales en el ambiente de trabajo Señalización Normas de seguridad e higiene Protocolos de bioseguridad | M21: =B21 -> C1 I4 Realiza la organización del ambiente de trabajo, equipos y materiales, teniendo en cuenta las normas de seguridad e higiene y protocolos de bioseguridad
B22: =Capacidades!M14 | M22: =B22
B23: =Capacidades!M15 | M23: =B23
B24: =Capacidades!M16 | M24: =B24
B25: =Capacidades!M17 | M25: =B25
B26: =Capacidades!M18 | M26: =B26
B27: =Capacidades!M19 | M27: =B27
A28: =Capacidades!L20 -> UC1 C2 Elaborar documentos administrativos y/o mercantiles de acuerdo a las características y estructuras de las mismas, aplicando técnicas de redacción, reglas ortográficas y gramaticales . | B28: =Capacidades!M20 -> C2 I1 Identifica los diverso tipos de documentos administrativos de acuerdo a las políticas y normativas de la organización. | C28: Documentos administrativos. Tipos Estructuras y diseños de documentos administrativos Carta, oficio, certificados, constancias, informes, memorándums, actas, avisos, solicitudes, entre otros. | D28: =Organización_Modular!F11 -> Redacción de documentos | E28: =Organización_Modular!G11 -> I | F28: =Organización_Modular!H11 -> 2 | G28: =Organización_Modular!I11 -> 2 | H28: =SUM(F28:G28) -> 4 | I28: =F28*16 -> 32 | J28: =G28*32 -> 64 | K28: =SUM(I28:J28) -> 96 | L28: TECNICO PROFESIONAL EN ADMINISTRACION DE EMPRESAS, CONTABILIDAD Y PROFESIONAL EN PEDAGOGIA | M28: =B28 -> C2 I1 Identifica los diverso tipos de documentos administrativos de acuerdo a las políticas y normativas de la organización.
B29: =Capacidades!M21 -> C2 I2 Redacta los documentos administrativos aplicando las técnicas de redacción, reglas ortográficas y gramaticales, de acuerdo a las políticas y normativas de la organización. | C29: Técnicas de redacción. Reglas ortográficas y gramaticales Redacción de documentos administrativos Combinar correspondencia. Impresión de documentos | M29: =B29 -> C2 I2 Redacta los documentos administrativos aplicando las técnicas de redacción, reglas ortográficas y gramaticales, de acuerdo a las políticas y normativas de la organización.
B30: =Capacidades!M22 -> C2 I3 Realiza el llenado de los documentos administrativos y/o mercantiles aplicando reglas ortográficas y gramaticales, de acuerdo a las políticas y normativas de la organización. | C30: Documento empresarial. Comprobantes de pago: Boleta, recibo por honorarios profesionales, factura, guías de remisión. Nota de pedido de compra y venta. FUT | M30: =B30 -> C2 I3 Realiza el llenado de los documentos administrativos y/o mercantiles aplicando reglas ortográficas y gramaticales, de acuerdo a las políticas y normativas de la organización.
B31: =Capacidades!M23 -> C2 I4 Verifica la calidad de los documentos administrativos y/o mercantiles de acuerdo a la información correspondiente, aplicando reglas ortográficas y gramaticales. | C31: Técnicas de revisión de documentos Prácticas de revisión de documentos | M31: =B31 -> C2 I4 Verifica la calidad de los documentos administrativos y/o mercantiles de acuerdo a la información correspondiente, aplicando reglas ortográficas y gramaticales.
B32: =Capacidades!M24 | M32: =B32
B33: =Capacidades!M25 | M33: =B33
B34: =Capacidades!M26 | M34: =B34
B35: =Capacidades!M27 | M35: =B35
B36: =Capacidades!M28 | M36: =B36
B37: =Capacidades!M29 | M37: =B37
A38: =Capacidades!L30 -> UC1 C3 Realizar el trámite de datos y documentos, de acuerdo a los procedimientos, normativa vigente y políticas de la organización. | B38: =Capacidades!M30 -> C3 I1 Explica un diagrama de flujo documentario de acuerdo a los procedimientos, normativa vigente y políticas de la organización. | C38: Diagrama de flujo documentario según el tipo de organización Ley 27444, Ley del Procedimiento Administativo General Orientación del sistema de trámite documentario en línea | D38: =Organización_Modular!F12 -> Trámite documentario | E38: =Organización_Modular!G12 -> I | F38: =Organización_Modular!H12 -> 2 | G38: =Organización_Modular!I12 -> 2 | H38: =SUM(F38:G38) -> 4 | I38: =F38*16 -> 32 | J38: =G38*32 -> 64 | K38: =SUM(I38:J38) -> 96 | L38: TECNICO PROFESIONAL EN ADMINISTRACION DE EMPRESAS, CONTABILIDAD Y PROFESIONAL EN PEDAGOGIA | M38: =B38 -> C3 I1 Explica un diagrama de flujo documentario de acuerdo a los procedimientos, normativa vigente y políticas de la organización.
B39: =Capacidades!M31 -> C3 I2 Organiza el procedimiento de registro y recepción del flujo documentario de acuerdo a los procedimientos, normativa vigente y políticas de la organización. | C39: Sistema de gestión administrativa Procedimiento de Recepción documentario Procedimiento de Registro documentario Prodimientos de Tramitación Procedimientos de notificación y entrega del documento. | M39: =B39 -> C3 I2 Organiza el procedimiento de registro y recepción del flujo documentario de acuerdo a los procedimientos, normativa vigente y políticas de la organización.
B40: =Capacidades!M32 -> C3 I3 Ejecuta la organización y traslado de expedientes de acuerdo a los procedimientos, normativa vigente y políticas de la organización. | C40: Registro de ingreso y salida de documentos. Hoja de envío y hoja de ruta | M40: =B40 -> C3 I3 Ejecuta la organización y traslado de expedientes de acuerdo a los procedimientos, normativa vigente y políticas de la organización.
B41: =Capacidades!M33 -> C3 I4 Efectúa el control del traslado de los expedientes y/o documentos de acuerdo a los procedimientos, normativa vigente y políticas de la organización. | C41: Hoja, cuaderno o registro de control de cargo Formato digital de control del traslado documentario | M41: =B41 -> C3 I4 Efectúa el control del traslado de los expedientes y/o documentos de acuerdo a los procedimientos, normativa vigente y políticas de la organización.
M42: =B42 -> 0
B43: =Capacidades!M35 | M43: =B43
B44: =Capacidades!M36 | M44: =B44
B45: =Capacidades!M37 | M45: =B45
B46: =Capacidades!M38 | M46: =B46
...

Sheet M2
A1: ='M1'!A1:L1 -> ORGANIZACIÓN DE LOS ELEMENTOS DEL MÓDULO
A3: DENOMINACIÓN DE LA INSTITUCIÓN | B3: =Perfil_Egreso!B3 -> CETPRO JUANJUI | F3: CÓDIGO MODULAR DEL INSTITUTO | I3: =Perfil_Egreso!E3 -> 0533836
A5: SECTOR ECONÓMICO | B5: =Perfil_Egreso!B5 -> Actividades profesionales, científicas y técnicas | C5: FAMILIA PRODUCTIVA | D5: =Perfil_Egreso!D5 -> Servicios prestados a empresas | F5: ACTIVIDAD ECONÓMICA | I5: =Perfil_Egreso!B7 -> Actividades administrativas y de apoyo de oficina y otras actividades de apoyo a las empresas
A7: =Perfil_Egreso!A10 -> DENOMINACIÓN DEL PROGRAMA DE ESTUDIOS SEGÚN CNOF (según corresponda) | B7: =Perfil_Egreso!B10 -> APOYO ADMINISTRATIVO | F7: CÓDIGO * | I7: =Perfil_Egreso!E10 -> M2982-1-002
A9: =Perfil_Egreso!A12 -> FORMACIÓN** | B9: =Perfil_Egreso!B12 -> AUXILIAR TECNICO | C9: N°. HORAS: | D9: =Itinerario!W17 -> 1072 | F9: N° CRÉDITOS: | I9: =Itinerario!T17 -> 40
A11: =Perfil_Egreso!C12 -> MODALIDAD DEL SERVICIO EDUCATIVO | B11: =Perfil_Egreso!D12 -> PRESENCIAL | F11: =Perfil_Egreso!A14 -> NIVEL FORMATIVO | I11: =Perfil_Egreso!B14 -> AUXILIAR TÉCNICO
A13: UNIDAD DE COMPETENCIA DEL CATÁLOGO NACIONAL DE LA OFERTA FORMATIVA
A14: =Organización_Modular!C41 -> UC2 Procesar la documentación de las distintas áreas de la organización, en función a sus políticas y normativa correspondiente. UC3 Custodiar la documentación, según políticas y procedimientos de la organización, y normativa correspondiente.
A15: DENOMINACIÓN DEL MÓDULO | B15: =Organización_Modular!A41 -> MÓDULO II: PROCESAMIENTO Y ARCHIVO DOCUMENTARIO
A16: CAPACIDADES TÉCNICAS O ESPECÍFICAS | B16: INDICADORES DE LOGRO DE LA CAPACIDAD | C16: CONTENIDOS | D16: UNIDAD DIDÁCTICA | E16: Periodo | F16: CRÉDITOS | H16: CRÉDITOS | I16: HORAS | K16: HORAS | L16: PERFIL DOCENTE | M16: Filtrar
F17: Teórico | G17: Práctica | I17: Teórico | J17: Práctica
A18: =Capacidades!L311 -> UC2 C1 Realizar el procesamiento y transmisión de la información y/o documentación, teniendo en cuenta los medios adecuados, la confiabilidad, en función a los objetivos de la organización y procedimientos establecidos. | B18: =Capacidades!M311 -> C1 I1 Identifica el flujo de información en función a los objetivos de la organización y procedimientos establecidos. | C18: - Flujo de la información - Tratamiento de la información de salida. - Protocolos de bioseguridad. - Confiabilidad -Confidencialidad | D18: =Organización_Modular!F41 -> Recepción y procesamiento de la información | E18: =Organización_Modular!G41 -> II | F18: =Organización_Modular!H41 -> 1 | G18: =Organización_Modular!I41 -> 1 | H18: =SUM(F18:G18) -> 2 | I18: =F18*16 -> 16 | J18: =G18*32 -> 32 | K18: =SUM(I18:J18) -> 48 | L18: TECNICO PROFESIONAL EN ADMINISTRACION DE EMPRESAS, CONTABILIDAD Y PROFESIONAL EN PEDAGOGIA | M18: =B18 -> C1 I1 Identifica el flujo de información en función a los objetivos de la organización y procedimientos establecidos.
B19: =Capacidades!M312 -> C1 I2 Procesa la información utilizando los medios electrónicos y digitales, teniendo en la confiabilidad y procedimientos establecidos. | C19: Procesamiento de documentos Operaciones con el sotfwar especializado. | M19: =B19 -> C1 I2 Procesa la información utilizando los medios electrónicos y digitales, teniendo en la confiabilidad y procedimientos establecidos.
B20: =Capacidades!M313 -> C1 I3 Transmite la información y/o documentación teniendo en cuenta los medios adecuados, la confiabilidad, en función a los objetivos de la organización y procedimientos establecidos. | C20: Distribución interna y externa de las comunicaciones. Formatos de transmisión. Proveido/nota de proveido. Hoja de ruta | M20: =B20 -> C1 I3 Transmite la información y/o documentación teniendo en cuenta los medios adecuados, la confiabilidad, en función a los objetivos de la organización y procedimientos establecidos.
B21: =Capacidades!M314 -> C1 I4 Ejecuta el control de la información teniendo en cuenta los medios adecuados, la confiabilidad, en función a los objetivos de la organización y procedimientos establecidos. | C21: Procedimientos para el control de la información Elaboración de la estructura de almacenamiento. Formatos para la impresión. Comunicación de la información | M21: =B21 -> C1 I4 Ejecuta el control de la información teniendo en cuenta los medios adecuados, la confiabilidad, en función a los objetivos de la organización y procedimientos establecidos.
B22: =Capacidades!M315 | M22: =B22
B23: =Capacidades!M316 | M23: =B23
B24: =Capacidades!M317 | M24: =B24
B25: =Capacidades!M318 | M25: =B25
B26: =Capacidades!M319 | M26: =B26
B27: =Capacidades!M320 | M27: =B27
A28: =Capacidades!L321 -> UC2 C2 Ejecutar actividades administrativas de apoyo2, en función de los objetivos de la organización, los procedimientos establecidos y el área asignada. | B28: =Capacidades!M321 -> C2 I1 Notifica la culminación del trámite documentario en función de los objetivos de la organización, los procedimientos establecidos y el área asignada. | C28: .Notificaciones administrativas. Tipo de notificaciones. .Procedimiento de notificaciones: -Organización de documentación según el lugar de entrega -Registro de la notificación -Entrega de la fichas de notificaciones -Informe diario de noticiaciones -Culminación del trámite | D28: =Organización_Modular!F42 -> Actividades administrativas | E28: =Organización_Modular!G42 -> II | F28: =Organización_Modular!H42 -> 0 | G28: =Organización_Modular!I42 -> 1 | H28: =SUM(F28:G28) -> 1 | I28: =F28*16 -> 0 | J28: =G28*32 -> 32 | K28: =SUM(I28:J28) -> 32 | L28: TECNICO PROFESIONAL EN ADMINISTRACION DE EMPRESAS, CONTABILIDAD Y PROFESIONAL EN PEDAGOGIA | M28: =B28 -> C2 I1 Notifica la culminación del trámite documentario en función de los objetivos de la organización, los procedimientos establecidos y el área asignada.
B29: =Capacidades!M322 -> C2 I2 Digita los documentos administrativos y/o comerciales en función de los objetivos de la organización, los procedimientos establecidos y el área asignada. | C29: Técnicas de digitación. Importancia. Prácticas de digitación. Scaner. Operación de scaner. | M29: =B29 -> C2 I2 Digita los documentos administrativos y/o comerciales en función de los objetivos de la organización, los procedimientos establecidos y el área asignada.
B30: =Capacidades!M323 -> C2 I3 Imprime los documentos administrativos y/o comerciales en función de los objetivos de la organización, los procedimientos establecidos y el área asignada. | C30: Impresiones. Características. funcionalidad. Operaciones de impresiones | M30: =B30 -> C2 I3 Imprime los documentos administrativos y/o comerciales en función de los objetivos de la organización, los procedimientos establecidos y el área asignada.
B31: =Capacidades!M324 -> C2 I4 Realiza el fotocopiado los documentos administrativos y/o comerciales en función de los objetivos de la organización, los procedimientos establecidos y el área asignada. | C31: Fotocopiadoras. Características. funcionalidad. Operaciones de fotocopiado | M31: =B31 -> C2 I4 Realiza el fotocopiado los documentos administrativos y/o comerciales en función de los objetivos de la organización, los procedimientos establecidos y el área asignada.
B32: =Capacidades!M325 -> C2 I5 Realiza el mantenimiento e higienes de los ambientes en función de los objetivos de la organización, los procedimientos establecidos y el área asignada. | C32: Normas de higiene y salud laboral Mantenimineto de los ambientes | M32: =B32 -> C2 I5 Realiza el mantenimiento e higienes de los ambientes en función de los objetivos de la organización, los procedimientos establecidos y el área asignada.
B33: =Capacidades!M326 | M33: =B33
B34: =Capacidades!M327 | M34: =B34
B35: =Capacidades!M328 | M35: =B35
B36: =Capacidades!M329 | M36: =B36
B37: =Capacidades!M330 | M37: =B37
A38: =Capacidades!L331 -> UC2 C3 Atender las comunicaciones, consultas, y/o centro de atención virtual, utilizando los medios adecuados y protocolos de la organización. | B38: =Capacidades!M331 -> C3 I1 Identifica la tipología del cliente considerando las caracteríscas personales y los protocolos de atención la organización | C38: Cliente. Tipología del cliente. Atención al cliente. Características de atención. Importancia. Protocolos de atención al cliente. | D38: =Organización_Modular!F43 -> Atención al público | E38: =Organización_Modular!G43 -> II | F38: =Organización_Modular!H43 -> 1 | G38: =Organización_Modular!I43 -> 1 | H38: =SUM(F38:G38) -> 2 | I38: =F38*16 -> 16 | J38: =G38*32 -> 32 | K38: =SUM(I38:J38) -> 48 | L38: TECNICO PROFESIONAL EN ADMINISTRACION DE EMPRESAS, CONTABILIDAD Y PROFESIONAL EN PEDAGOGIA | M38: =B38 -> C3 I1 Identifica la tipología del cliente considerando las caracteríscas personales y los protocolos de atención la organización
B39: =Capacidades!M332 -> C3 I2 Maneja los protocolos de atención al cliente según las políticas de la organización. | C39: Normas técnicas para la gestión de calidad para el servicio al cliente. Protocolos de la comunicación de la empresa. Aplicación de protocolos. Agendar y confirmar citas. | M39: =B39 -> C3 I2 Maneja los protocolos de atención al cliente según las políticas de la organización.
B40: =Capacidades!M333 -> C3 I3 Recibe las llamadas telefónicas teniendo en cuenta las normas de cortesía. | C40: Uso del teléfono. Atención de llamadas telefónicas. Registro de llamadas. Aplicación de protocolos de la comunicación de la empresa.(Cualidades de la voz. Cortesías telefónicas) Asertividad en el tratamiento de la información vía telefónica. | M40: =B40 -> C3 I3 Recibe las llamadas telefónicas teniendo en cuenta las normas de cortesía.
B41: =Capacidades!M334 -> C3 I4 Realiza la identificación del mensaje recibido y la transmisión del mismo de acuerdo los protocolos establecidos y en función a los objetivos de la organización. | C41: Técnicas de comunicación. Medios de comunicación. | M41: =B41 -> C3 I4 Realiza la identificación del mensaje recibido y la transmisión del mismo de acuerdo los protocolos establecidos y en función a los objetivos de la organización.
B42: =Capacidades!M335 -> C3 I5 Ejecuta la atención al cliente considerando la imagen y protocolos de la organización. | C42: - Resolución de conflictos. - Objeción de los clientes. - Libro de reclamaciones. - Negociación con los clientes. | M42: =B42 -> C3 I5 Ejecuta la atención al cliente considerando la imagen y protocolos de la organización.
B43: =Capacidades!M336 | M43: =B43
B44: =Capacidades!M337 | M44: =B44
B45: =Capacidades!M338 | M45: =B45
B46: =Capacidades!M339 | M46: =B46
...

Sheet M3
A1: ='M2'!A1:L1 -> ORGANIZACIÓN DE LOS ELEMENTOS DEL MÓDULO
A3: DENOMINACIÓN DE LA INSTITUCIÓN | B3: =Perfil_Egreso!B3 -> CETPRO JUANJUI | F3: CÓDIGO MODULAR DEL INSTITUTO | I3: =Perfil_Egreso!E3 -> 0533836
A5: SECTOR ECONÓMICO | B5: =Perfil_Egreso!B5 -> Actividades profesionales, científicas y técnicas | C5: FAMILIA PRODUCTIVA | D5: =Perfil_Egreso!D5 -> Servicios prestados a empresas | F5: ACTIVIDAD ECONÓMICA | I5: =Perfil_Egreso!B7 -> Actividades administrativas y de apoyo de oficina y otras actividades de apoyo a las empresas
A7: =Perfil_Egreso!A10 -> DENOMINACIÓN DEL PROGRAMA DE ESTUDIOS SEGÚN CNOF (según corresponda) | B7: =Perfil_Egreso!B10 -> APOYO ADMINISTRATIVO | F7: CÓDIGO * | I7: =Perfil_Egreso!E10 -> M2982-1-002
A9: =Perfil_Egreso!A12 -> FORMACIÓN** | B9: =Perfil_Egreso!B12 -> AUXILIAR TECNICO | C9: N°. HORAS: | D9: =Itinerario!W17 -> 1072 | F9: N° CRÉDITOS: | I9: =Itinerario!T17 -> 40
A11: =Perfil_Egreso!C12 -> MODALIDAD DEL SERVICIO EDUCATIVO | B11: =Perfil_Egreso!D12 -> PRESENCIAL | F11: =Perfil_Egreso!A14 -> NIVEL FORMATIVO | I11: =Perfil_Egreso!B14 -> AUXILIAR TÉCNICO
A13: UNIDAD DE COMPETENCIA DEL CATÁLOGO NACIONAL DE LA OFERTA FORMATIVA
A14: =Organización_Modular!C72 -> 0
A15: DENOMINACIÓN DEL MÓDULO | B15: =Organización_Modular!A72 -> 0
A16: CAPACIDADES TÉCNICAS O ESPECÍFICAS | B16: INDICADORES DE LOGRO DE LA CAPACIDAD | C16: CONTENIDOS | D16: UNIDAD DIDÁCTICA | E16: Periodo | F16: CRÉDITOS | H16: CRÉDITOS | I16: HORAS | K16: HORAS | L16: PERFIL DOCENTE | M16: Filtrar
F17: Teórico | G17: Práctica | I17: Teórico | J17: Práctica
A18: =Capacidades!L612 | B18: =Capacidades!M612 | D18: =Organización_Modular!F72 -> 0 | E18: =Organización_Modular!G72 -> 0 | F18: =Organización_Modular!H72 -> 0 | G18: =Organización_Modular!I72 -> 0 | H18: =SUM(F18:G18) -> 0 | I18: =F18*16 -> 0 | J18: =G18*32 -> 0 | K18: =SUM(I18:J18) -> 0 | M18: =B18
B19: =Capacidades!M613 | M19: =B19
B20: =Capacidades!M614 | M20: =B20
B21: =Capacidades!M615 | M21: =B21
B22: =Capacidades!M616 | M22: =B22
B23: =Capacidades!M617 | M23: =B23
B24: =Capacidades!M618 | M24: =B24
B25: =Capacidades!M619 | M25: =B25
B26: =Capacidades!M620 | M26: =B26
B27: =Capacidades!M621 | M27: =B27
A28: =Capacidades!L622 | B28: =Capacidades!M622 | D28: =Organización_Modular!F73 -> 0 | E28: =Organización_Modular!G73 -> 0 | F28: =Organización_Modular!H73 -> 0 | G28: =Organización_Modular!I73 -> 0 | H28: =SUM(F28:G28) -> 0 | I28: =F28*16 -> 0 | J28: =G28*32 -> 0 | K28: =SUM(I28:J28) -> 0 | M28: =B28
B29: =Capacidades!M623 | M29: =B29
B30: =Capacidades!M624 | M30: =B30
B31: =Capacidades!M625 | M31: =B31
B32: =Capacidades!M626 | M32: =B32
B33: =Capacidades!M627 | M33: =B33
B34: =Capacidades!M628 | M34: =B34
B35: =Capacidades!M629 | M35: =B35
B36: =Capacidades!M630 | M36: =B36
B37: =Capacidades!M631 | M37: =B37
A38: =Capacidades!L632 | B38: =Capacidades!M632 | D38: =Organización_Modular!F74 -> 0 | E38: =Organización_Modular!G74 -> 0 | F38: =Organización_Modular!H74 -> 0 | G38: =Organización_Modular!I74 -> 0 | H38: =SUM(F38:G38) -> 0 | I38: =F38*16 -> 0 | J38: =G38*32 -> 0 | K38: =SUM(I38:J38) -> 0 | M38: =B38
B39: =Capacidades!M633 | M39: =B39
B40: =Capacidades!M634 | M40: =B40
B41: =Capacidades!M635 | M41: =B41
B42: =Capacidades!M636 | M42: =B42
B43: =Capacidades!M637 | M43: =B43
B44: =Capacidades!M638 | M44: =B44
B45: =Capacidades!M639 | M45: =B45
B46: =Capacidades!M640 | M46: =B46
...

Sheet M4
A1: ='M3'!A1:L1 -> ORGANIZACIÓN DE LOS ELEMENTOS DEL MÓDULO
A3: DENOMINACIÓN DE LA INSTITUCIÓN | B3: =Perfil_Egreso!B3 -> CETPRO JUANJUI | F3: CÓDIGO MODULAR DEL INSTITUTO | I3: =Perfil_Egreso!E3 -> 0533836
A5: SECTOR ECONÓMICO | B5: =Perfil_Egreso!B5 -> Actividades profesionales, científicas y técnicas | C5: FAMILIA PRODUCTIVA | D5: =Perfil_Egreso!D5 -> Servicios prestados a empresas | F5: ACTIVIDAD ECONÓMICA | I5: =Perfil_Egreso!B7 -> Actividades administrativas y de apoyo de oficina y otras actividades de apoyo a las empresas
A7: =Perfil_Egreso!A10 -> DENOMINACIÓN DEL PROGRAMA DE ESTUDIOS SEGÚN CNOF (según corresponda) | B7: =Perfil_Egreso!B10 -> APOYO ADMINISTRATIVO | F7: CÓDIGO * | I7: =Perfil_Egreso!E10 -> M2982-1-002
A9: =Perfil_Egreso!A12 -> FORMACIÓN** | B9: =Perfil_Egreso!B12 -> AUXILIAR TECNICO | C9: N°. HORAS: | D9: =Itinerario!W17 -> 1072 | F9: N° CRÉDITOS: | I9: =Itinerario!T17 -> 40
A11: =Perfil_Egreso!C12 -> MODALIDAD DEL SERVICIO EDUCATIVO | B11: =Perfil_Egreso!D12 -> PRESENCIAL | F11: =Perfil_Egreso!A14 -> NIVEL FORMATIVO | I11: =Perfil_Egreso!B14 -> AUXILIAR TÉCNICO
A13: UNIDAD DE COMPETENCIA DEL CATÁLOGO NACIONAL DE LA OFERTA FORMATIVA
A14: =Organización_Modular!C103 -> 0
A15: DENOMINACIÓN DEL MÓDULO | B15: =Organización_Modular!A103 -> MÓDULO II: COCINA NACIONAL E INTERNACIONAL
A16: CAPACIDADES TÉCNICAS O ESPECÍFICAS | B16: INDICADORES DE LOGRO DE LA CAPACIDAD | C16: CONTENIDOS | D16: UNIDAD DIDÁCTICA | E16: Periodo | F16: CRÉDITOS | H16: CRÉDITOS | I16: HORAS | K16: HORAS | L16: PERFIL DOCENTE | M16: Filtrar
F17: Teórico | G17: Práctica | I17: Teórico | J17: Práctica
A18: =Capacidades!L913 | B18: =Capacidades!M913 | D18: =Organización_Modular!F103 -> 0 | E18: =Organización_Modular!G103 -> 0 | F18: =Organización_Modular!H103 -> 0 | G18: =Organización_Modular!I103 -> 0 | H18: =SUM(F18:G18) -> 0 | I18: =F18*16 -> 0 | J18: =G18*32 -> 0 | K18: =SUM(I18:J18) -> 0 | M18: =B18
B19: =Capacidades!M914 | M19: =B19
B20: =Capacidades!M915 | M20: =B20
B21: =Capacidades!M916 | M21: =B21
B22: =Capacidades!M917 | M22: =B22
B23: =Capacidades!M918 | M23: =B23
B24: =Capacidades!M919 | M24: =B24
B25: =Capacidades!M920 | M25: =B25
B26: =Capacidades!M921 | M26: =B26
B27: =Capacidades!M922 | M27: =B27
A28: =Capacidades!L923 | B28: =Capacidades!M923 | D28: =Organización_Modular!F104 -> 0 | E28: =Organización_Modular!G104 -> 0 | F28: =Organización_Modular!H104 -> 0 | G28: =Organización_Modular!I104 -> 0 | H28: =SUM(F28:G28) -> 0 | I28: =F28*16 -> 0 | J28: =G28*32 -> 0 | K28: =SUM(I28:J28) -> 0 | M28: =B28
B29: =Capacidades!M924 | M29: =B29
B30: =Capacidades!M925 | M30: =B30
B31: =Capacidades!M926 | M31: =B31
B32: =Capacidades!M927 | M32: =B32
B33: =Capacidades!M928 | M33: =B33
B34: =Capacidades!M929 | M34: =B34
B35: =Capacidades!M930 | M35: =B35
B36: =Capacidades!M931 | M36: =B36
B37: =Capacidades!M932 | M37: =B37
A38: =Capacidades!L933 | B38: =Capacidades!M933 | D38: =Organización_Modular!F105 -> 0 | E38: =Organización_Modular!G105 -> 0 | F38: =Organización_Modular!H105 -> 0 | G38: =Organización_Modular!I105 -> 0 | H38: =SUM(F38:G38) -> 0 | I38: =F38*16 -> 0 | J38: =G38*32 -> 0 | K38: =SUM(I38:J38) -> 0 | M38: =B38
B39: =Capacidades!M934 | M39: =B39
B40: =Capacidades!M935 | M40: =B40
B41: =Capacidades!M936 | M41: =B41
B42: =Capacidades!M937 | M42: =B42
B43: =Capacidades!M938 | M43: =B43
B44: =Capacidades!M939 | M44: =B44
B45: =Capacidades!M940 | M45: =B45
B46: =Capacidades!M941 | M46: =B46
...

Sheet M5
A1: ='M4'!A1:L1 -> ORGANIZACIÓN DE LOS ELEMENTOS DEL MÓDULO
A3: DENOMINACIÓN DE LA INSTITUCIÓN | B3: =Perfil_Egreso!B3 -> CETPRO JUANJUI | F3: CÓDIGO MODULAR DEL INSTITUTO | I3: =Perfil_Egreso!E3 -> 0533836
A5: SECTOR ECONÓMICO | B5: =Perfil_Egreso!B5 -> Actividades profesionales, científicas y técnicas | C5: FAMILIA PRODUCTIVA | D5: =Perfil_Egreso!D5 -> Servicios prestados a empresas | F5: ACTIVIDAD ECONÓMICA | I5: =Perfil_Egreso!B7 -> Actividades administrativas y de apoyo de oficina y otras actividades de apoyo a las empresas
A7: =Perfil_Egreso!A10 -> DENOMINACIÓN DEL PROGRAMA DE ESTUDIOS SEGÚN CNOF (según corresponda) | B7: =Perfil_Egreso!B10 -> APOYO ADMINISTRATIVO | F7: CÓDIGO * | I7: =Perfil_Egreso!E10 -> M2982-1-002
A9: =Perfil_Egreso!A12 -> FORMACIÓN** | B9: =Perfil_Egreso!B12 -> AUXILIAR TECNICO | C9: N°. HORAS: | D9: =Itinerario!W17 -> 1072 | F9: N° CRÉDITOS: | I9: =Itinerario!T17 -> 40
A11: =Perfil_Egreso!C12 -> MODALIDAD DEL SERVICIO EDUCATIVO | B11: =Perfil_Egreso!D12 -> PRESENCIAL | F11: =Perfil_Egreso!A14 -> NIVEL FORMATIVO | I11: =Perfil_Egreso!B14 -> AUXILIAR TÉCNICO
A13: UNIDAD DE COMPETENCIA DEL CATÁLOGO NACIONAL DE LA OFERTA FORMATIVA
A14: =Organización_Modular!C134 -> 0
A15: DENOMINACIÓN DEL MÓDULO | B15: =Organización_Modular!A134 -> 0
A16: CAPACIDADES TÉCNICAS O ESPECÍFICAS | B16: INDICADORES DE LOGRO DE LA CAPACIDAD | C16: CONTENIDOS | D16: UNIDAD DIDÁCTICA | E16: Periodo | F16: CRÉDITOS | H16: CRÉDITOS | I16: HORAS | K16: HORAS | L16: PERFIL DOCENTE | M16: Filtrar
F17: Teórico | G17: Práctica | I17: Teórico | J17: Práctica
A18: =Capacidades!L1214 | B18: =Capacidades!M1214 | D18: =Organización_Modular!F134 -> 0 | E18: =Organización_Modular!G134 -> 0 | F18: =Organización_Modular!H134 -> 0 | G18: =Organización_Modular!I134 -> 0 | H18: =SUM(F18:G18) -> 0 | I18: =F18*16 -> 0 | J18: =G18*32 -> 0 | K18: =SUM(I18:J18) -> 0 | M18: =B18
B19: =Capacidades!M1215 | M19: =B19
B20: =Capacidades!M1216 | M20: =B20
B21: =Capacidades!M1217 | M21: =B21
B22: =Capacidades!M1218 | M22: =B22
B23: =Capacidades!M1219 | M23: =B23
B24: =Capacidades!M1220 | M24: =B24
B25: =Capacidades!M1221 | M25: =B25
B26: =Capacidades!M1222 | M26: =B26
B27: =Capacidades!M1223 | M27: =B27
A28: =Capacidades!L1224 | B28: =Capacidades!M1224 | D28: =Organización_Modular!F135 -> 0 | E28: =Organización_Modular!G135 -> 0 | F28: =Organización_Modular!H135 -> 0 | G28: =Organización_Modular!I135 -> 0 | H28: =SUM(F28:G28) -> 0 | I28: =F28*16 -> 0 | J28: =G28*32 -> 0 | K28: =SUM(I28:J28) -> 0 | M28: =B28
B29: =Capacidades!M1225 | M29: =B29
B30: =Capacidades!M1226 | M30: =B30
B31: =Capacidades!M1227 | M31: =B31
B32: =Capacidades!M1228 | M32: =B32
B33: =Capacidades!M1229 | M33: =B33
B34: =Capacidades!M1230 | M34: =B34
B35: =Capacidades!M1231 | M35: =B35
B36: =Capacidades!M1232 | M36: =B36
B37: =Capacidades!M1233 | M37: =B37
A38: =Capacidades!L1234 | B38: =Capacidades!M1234 | D38: =Organización_Modular!F136 -> 0 | E38: =Organización_Modular!G136 -> 0 | F38: =Organización_Modular!H136 -> 0 | G38: =Organización_Modular!I136 -> 0 | H38: =SUM(F38:G38) -> 0 | I38: =F38*16 -> 0 | J38: =G38*32 -> 0 | K38: =SUM(I38:J38) -> 0 | M38: =B38
B39: =Capacidades!M1235 | M39: =B39
B40: =Capacidades!M1236 | M40: =B40
B41: =Capacidades!M1237 | M41: =B41
B42: =Capacidades!M1238 | M42: =B42
B43: =Capacidades!M1239 | M43: =B43
B44: =Capacidades!M1240 | M44: =B44
B45: =Capacidades!M1241 | M45: =B45
B46: =Capacidades!M1242 | M46: =B46
...

Sheet M6
