Workbook

Sheet Perfil_Egreso
A1: ANEXO Nº 9 PERFIL DE EGRESO (PARA CICLOS FORMATIVOS: TÉCNICO Y AUXILIAR TÉCNICO)
A3: DENOMINACIÓN DE LA INSTITUCIÓN | B3: CETPRO JUANJUI | D3: CÓDIGO MODULAR DEL CETPRO | E3: 533836
A5: SECTOR ECONÓMICO | B5: OTRAS ACTIVIDADES DE SERVICIO | C5: FAMILIA PRODUCTIVA | D5: SERVICIOS PERSONALES Y DE HOGARES
A7: ACTIVIDAD ECONÓMICA | B7: OTRAS ACTIVIDADES DE SERVICIOS PERSONALES
A9: DENOMINACIÓN VARIANTE
A11: DENOMINACIÓN DEL PROGRAMA DE ESTUDIOS | B11: ESTILISMO | D11: CÓDIGO * | E11: S3496-2-001
A13: FORMACIÓN** | B13: 0 | C13: MODALIDAD DEL SERVICIO EDUCATIVO *** | D13: PRESENCIAL
A15: CICLO FORMATIVO | B15: TÉCNICO
A17: DESCRIPCIÓN DEL PERFIL DE EGRESO | F17: Filtrar
A18: El egresado en estilismo será capaz de ejecutar el servicio de peluquería y barbería, realizar procedimientos técnicos capilares, maquillaje de belleza y de caracterizacion, estética en manos y pies, de acuerdo con los requerimientos del cliente, criterios técnicos, estéticos y de bioseguridad e higiene. Asimismo, utiliza de manera adecuada las diversas herramientas de las TICs; busca y analiza la información; se comunica con otros en forma efectiva, liderando emprendimientos con nuevas oportunidades de negocios y proyectos sostenibles; planteando soluciones a diversos problemas, promoviendo una cultura ambiental en su entorno; estableciendo relaciones de respeto y justicia con los demás. | F18: d
A19: COMPETENCIAS ESPECÍFICAS (UNIDAD DE COMPETENCIA) | F19: =A19 -> COMPETENCIAS ESPECÍFICAS (UNIDAD DE COMPETENCIA)
A20: UC1. Ejecutar el servicio de peluquería y barbería, teniendo en cuenta el diagnóstico capilar, requerimientos del cliente, procedimientos del establecimiento, criterios técnicos, estéticos y de bioseguridad e higiene. | F20: =A20 -> UC1. Ejecutar el servicio de peluquería y barbería, teniendo en cuenta el diagnóstico capilar, requerimientos del cliente, procedimientos del establecimiento, criterios técnicos, estéticos y de bioseguridad e higiene.
A21: UC2. Realizar procedimientos técnicos capilares, tomando en cuenta su diagnóstico, requerimientos del cliente, y de bioseguridad e higiene. | F21: =A21 -> UC2. Realizar procedimientos técnicos capilares, tomando en cuenta su diagnóstico, requerimientos del cliente, y de bioseguridad e higiene.
A22: UC3. Efectuar el servicio de maquillaje de belleza de acuerdo con los requerimientos del cliente, criterios técnicos, estéticos y de bioseguridad e higiene. | F22: =A22 -> UC3. Efectuar el servicio de maquillaje de belleza de acuerdo con los requerimientos del cliente, criterios técnicos, estéticos y de bioseguridad e higiene.
A23: UC4. Efectuar el servicio de maquillaje de caracterización aplicando materiales para efectos especiales, de acuerdo con los requerimientos del cliente, criterios técnicos, estéticos, estéticos éticos y de bioseguridad e higiene. | F23: =A23 -> UC4. Efectuar el servicio de maquillaje de caracterización aplicando materiales para efectos especiales, de acuerdo con los requerimientos del cliente, criterios técnicos, estéticos, estéticos éticos y de bioseguridad e higiene.
A24: UC5. Ejecutar el servicio de estética en manos y pies teniendo en cuenta los requerimientos del cliente, los procedimientos del establecimiento, criterios técnicos, estéticos y de bioseguridad e higiene. | F24: =A24 -> UC5. Ejecutar el servicio de estética en manos y pies teniendo en cuenta los requerimientos del cliente, los procedimientos del establecimiento, criterios técnicos, estéticos y de bioseguridad e higiene.
F25: =A25 -> 0
F26: =A26 -> 0
F27: =A27 -> 0
A28: COMPETENCIAS PARA LA EMPLEABILIDAD | F28: =A28 -> COMPETENCIAS PARA LA EMPLEABILIDAD
A29: CE1 Comunicación efectiva.- expresar y comprender de manera clara conceptos, ideas, sentimientos, hechos y opiniones en forma oral y escrita para comunicarse e interactuar con otras personas en contextos sociales y laborales diversos. (UD) | F29: =A29 -> CE1 Comunicación efectiva.- expresar y comprender de manera clara conceptos, ideas, sentimientos, hechos y opiniones en forma oral y escrita para comunicarse e interactuar con otras personas en contextos sociales y laborales diversos. (UD)
A30: CE2. Tecnologías de la información. - Manejar herramientas informáticas de las TICs para buscar y analizar información, comunicarse y realizar procedimientos o tareas vinculadas al área profesional, de acuerdo con los requerimientos de su entorno laboral. (UD) | F30: =A30 -> CE2. Tecnologías de la información. - Manejar herramientas informáticas de las TICs para buscar y analizar información, comunicarse y realizar procedimientos o tareas vinculadas al área profesional, de acuerdo con los requerimientos de su entorno laboral. (UD)
A31: CE3. Emprendimiento.- identificar nuevas oportunidades de proyectos o negocios que generen valor y sean sostenibles, organizando y distribuyendo los recursos para su funcionamiento con creatividad, liderazgo y ética permanente, articulando acciones que permitan desarrollar innovaciones en la creación de bienes y servicios, así como en procesos de productos ya existentes (UD). | F31: =A31 -> CE3. Emprendimiento.- identificar nuevas oportunidades de proyectos o negocios que generen valor y sean sostenibles, organizando y distribuyendo los recursos para su funcionamiento con creatividad, liderazgo y ética permanente, articulando acciones que permitan desarrollar innovaciones en la creación de bienes y servicios, así como en procesos de productos ya existentes (UD).
A32: CE4. Ética.-Establecer relaciones con respeto y justicia en los ámbitos personal, colectivo e institucional, contribuyendo a una convivencia democrática orientada al bien común, que considere la diversidad y dignidad de las personas, teniendo en cuenta las consideraciones aplicadas en su contexto laboral. (UD) | F32: =A32 -> CE4. Ética.-Establecer relaciones con respeto y justicia en los ámbitos personal, colectivo e institucional, contribuyendo a una convivencia democrática orientada al bien común, que considere la diversidad y dignidad de las personas, teniendo en cuenta las consideraciones aplicadas en su contexto laboral. (UD)
A33: CE5. Solución de problemas, identificar situaciones complejas para evaluar posibles soluciones, aplicando un conjunto de herramienta flexibles que conlleve a la atención de una necesidad. (UD) | F33: =A33 -> CE5. Solución de problemas, identificar situaciones complejas para evaluar posibles soluciones, aplicando un conjunto de herramienta flexibles que conlleve a la atención de una necesidad. (UD)
A34: CE6. Cultura Ambiental.- Interactuar con el entorno de forma ética, autonoma responsable y sostenible preservando y cuidando el ambiente natural y social, contrarestando los efectos negativos generados por la acción humana evitando otros daños. (T) | F34: =A34 -> CE6. Cultura Ambiental.- Interactuar con el entorno de forma ética, autonoma responsable y sostenible preservando y cuidando el ambiente natural y social, contrarestando los efectos negativos generados por la acción humana evitando otros daños. (T)
A35: CE 7. Liderazgo personal y profesional .- Articular recursos y potencialidades de cada integrante de su equipo logrando un trabajo comprometido, colaborativo, creativo, ético, sensible a su contexto social y ambiente, en pro del bien común. (T) | F35: =A35 -> CE 7. Liderazgo personal y profesional .- Articular recursos y potencialidades de cada integrante de su equipo logrando un trabajo comprometido, colaborativo, creativo, ético, sensible a su contexto social y ambiente, en pro del bien común. (T)
F36: =A36 -> 0
F37: =A37 -> 0
F38: =A38 -> 0
F39: =A39 -> 0
F40: =A40 -> 0
A41: ÁMBITOS DE DESEMPEÑO | F41: =A41 -> ÁMBITOS DE DESEMPEÑO
A42: El egresado de este programa de estudios podra desempeñarse en las siguientes áreas o espacios laborales: - Corte de cabellos para damas, caballeros y niños. - Extensiones y postizos. - Peinados. - Tratamiento Capilar - Manicure y Pedicure. - Cortes y diseños para barbería. - Maquillajes para diferentes eventos y de caracterización. - Tinturación - Laceados y ondulaciones temporales y permanentes. - Depilaciones corporales. - O su propio Salón de belleza y/o barbería. | F42: =A42 -> El egresado de este programa de estudios podra desempeñarse en las siguientes áreas o espacios laborales: - Corte de cabellos para damas, caballeros y niños. - Extensiones y postizos. - Peinados. - Tratamiento Capilar - Manicure y Pedicure. - Cortes y diseños para barbería. - Maquillajes para diferentes eventos y de caracterización. - Tinturación - Laceados y ondulaciones temporales y permanentes. - Depilaciones corporales. - O su propio Salón de belleza y/o barbería.
A43: Pautas Generales: 1. Descripción del perfil de egreso: Descripción general y breve de los desempeños que será capaz de realizar el egresado en el campo laboral, al concluir el programa de estudio en correspondencia con las competencias técnicas y de empleabilidad. 2. Competencias específicas: Transcripción de las unidades de competencia del programa de estudio, establecido en el CNOF. En caso de que el programa no se encuentre en el CNOF se tomarán las Unidades de Competencias definidas mediante el análisis de la actividad económica correspondiente. 3. Las competencias para la empleabilidad: son priorizadas por la institución educativa, en concordancia con los Lineamientos Académicos Generales establecidos por el MINEDU y su modelo educativo. Se debe distinguir los que se abordarán como unidad didáctica (UD), de manera transversal (T) o ambas (UD/T) 4. Ámbitos de desempeño: Listar los campos o áreas laborales en los cuales el egresado del programa de estudio se podrá insertar. *Se considera el código del programa de estudios del CNOF, de ser el caso. ** Indicar sólo en el caso de que sea Dual o En Alternancia, caso contrario dejar la celda en blanco. | F43: =A43 -> Pautas Generales: 1. Descripción del perfil de egreso: Descripción general y breve de los desempeños que será capaz de realizar el egresado en el campo laboral, al concluir el programa de estudio en correspondencia con las competencias técnicas y de empleabilidad. 2. Competencias específicas: Transcripción de las unidades de competencia del programa de estudio, establecido en el CNOF. En caso de que el programa no se encuentre en el CNOF se tomarán las Unidades de Competencias definidas mediante el análisis de la actividad económica correspondiente. 3. Las competencias para la empleabilidad: son priorizadas por la institución educativa, en concordancia con los Lineamientos Académicos Generales establecidos por el MINEDU y su modelo educativo. Se debe distinguir los que se abordarán como unidad didáctica (UD), de manera transversal (T) o ambas (UD/T) 4. Ámbitos de desempeño: Listar los campos o áreas laborales en los cuales el egresado del programa de estudio se podrá insertar. *Se considera el código del programa de estudios del CNOF, de ser el caso. ** Indicar sólo en el caso de que sea Dual o En Alternancia, caso contrario dejar la celda en blanco.

Sheet Programa_Estudio
A1: ANEXO Nº 8 PROGRAMA DE ESTUDIO (PARA CICLOS FORMATIVOS: TÉCNICO Y AUXILIAR TÉCNICO)
A3: =Perfil_Egreso!A3 -> DENOMINACIÓN DE LA INSTITUCIÓN | B3: =Perfil_Egreso!B3 -> CETPRO JUANJUI | D3: =Perfil_Egreso!D3 -> CÓDIGO MODULAR DEL CETPRO | E3: =Perfil_Egreso!E3 -> 533836
A5: SECTOR ECONÓMICO | B5: =Perfil_Egreso!B5 -> OTRAS ACTIVIDADES DE SERVICIO | C5: FAMILIA PRODUCTIVA | D5: =Perfil_Egreso!D5 -> SERVICIOS PERSONALES Y DE HOGARES | E5: ACTIVIDAD ECONÓMICA | F5: =Perfil_Egreso!B7 -> OTRAS ACTIVIDADES DE SERVICIOS PERSONALES
A7: DENOMINACIÓN DEL PROGRAMA DE ESTUDIOS | B7: =Perfil_Egreso!B11 -> ESTILISMO | C7: CÓDIGO DE SER EL CASO * | D7: =Perfil_Egreso!E11 -> S3496-2-001
A9: CICLO FORMATIVO | B9: =Perfil_Egreso!B15 -> TÉCNICO | C9: N°. HORAS: | D9: =Itinerario!W17 -> 2272 | E9: N° CRÉDITOS: | F9: =Itinerario!T17 -> 83
A11: FORMACIÓN** | B11: =Perfil_Egreso!B13 -> 0 | D11: MODALIDAD DEL SERVICIO EDUCATIVO *** | E11: =Perfil_Egreso!D13 -> PRESENCIAL
A13: COMPETENCIAS ESPECÍFICAS O TECNICAS (UNIDAD DE COMPETENCIA)
A14: UNIDAD DE COMPETENCIA | C14: INDICADORES DE LOGRO DE LA COMPETENCIA | G14: Filtro
A15: =CONCATENATE("Unidad de Competencia N° 01 (UC1): ",Perfil_Egreso!A20) -> Unidad de Competencia N° 01 (UC1): UC1. Ejecutar el servicio de peluquería y barbería, teniendo en cuenta el diagnóstico capilar, requerimientos del cliente, procedimientos del establecimiento, criterios técnicos, estéticos y de bioseguridad e higiene. | C15: 1. Prepara al cliente, teniendo en cuenta los procedimientos del establecimiento y según el servicio a realizar. | G15: =C15 -> 1. Prepara al cliente, teniendo en cuenta los procedimientos del establecimiento y según el servicio a realizar. | H15: 1 | I15: =CONCATENATE(H15,". ",C15) -> 1. 1. Prepara al cliente, teniendo en cuenta los procedimientos del establecimiento y según el servicio a realizar.
C16: 2. Propone estilos de estética de cabello, tomando en cuenta tendencias y criterios estéticos, así como las diferentes morfologías y requerimientos del cliente | G16: =C16 -> 2. Propone estilos de estética de cabello, tomando en cuenta tendencias y criterios estéticos, así como las diferentes morfologías y requerimientos del cliente | H16: 2 | I16: =CONCATENATE(H16,". ",C16) -> 2. 2. Propone estilos de estética de cabello, tomando en cuenta tendencias y criterios estéticos, así como las diferentes morfologías y requerimientos del cliente
C17: 3. Realiza cortes de cabello según el estilo determinado, aplicando técnicas y utilizando equipamiento de la especialidad. | G17: =C17 -> 3. Realiza cortes de cabello según el estilo determinado, aplicando técnicas y utilizando equipamiento de la especialidad. | H17: 3 | I17: =CONCATENATE(H17,". ",C17) -> 3. 3. Realiza cortes de cabello según el estilo determinado, aplicando técnicas y utilizando equipamiento de la especialidad.
C18: 4. Realiza peinados según estilo determinado, aplicando técnicas y utilizando equipamiento de la especialidad. | G18: =C18 -> 4. Realiza peinados según estilo determinado, aplicando técnicas y utilizando equipamiento de la especialidad. | H18: 4 | I18: =CONCATENATE(H18,". ",C18) -> 4. 4. Realiza peinados según estilo determinado, aplicando técnicas y utilizando equipamiento de la especialidad.
C19: 5. Coloca postizos y/o extensiones según estilo determinado, aplicando criterios técnicos, estéticos y de bioseguridad e higiene. | G19: =C19 -> 5. Coloca postizos y/o extensiones según estilo determinado, aplicando criterios técnicos, estéticos y de bioseguridad e higiene. | H19: 5 | I19: =CONCATENATE(H19,". ",C19) -> 5. 5. Coloca postizos y/o extensiones según estilo determinado, aplicando criterios técnicos, estéticos y de bioseguridad e higiene.
C20: 6. Propone estilos o diseños de estética de barba, tomando en cuenta tendencias y criterios estéticos, así como las diferentes morfologías y requerimientos del cliente. | G20: =C20 -> 6. Propone estilos o diseños de estética de barba, tomando en cuenta tendencias y criterios estéticos, así como las diferentes morfologías y requerimientos del cliente. | H20: 6 | I20: =CONCATENATE(H20,". ",C20) -> 6. 6. Propone estilos o diseños de estética de barba, tomando en cuenta tendencias y criterios estéticos, así como las diferentes morfologías y requerimientos del cliente.
C21: 7. Realiza cortes de barbas según el estilo o diseño determinado, aplicando técnicas y utilizando equipamiento de la especialidad. | G21: =C21 -> 7. Realiza cortes de barbas según el estilo o diseño determinado, aplicando técnicas y utilizando equipamiento de la especialidad. | H21: 7 | I21: =CONCATENATE(H21,". ",C21) -> 7. 7. Realiza cortes de barbas según el estilo o diseño determinado, aplicando técnicas y utilizando equipamiento de la especialidad.
C22: 8. Brinda recomendaciones post servicio realizado, según la técnica y tratamiento empleado. | G22: =C22 -> 8. Brinda recomendaciones post servicio realizado, según la técnica y tratamiento empleado. | H22: 8 | I22: =CONCATENATE(H22,". ",C22) -> 8. 8. Brinda recomendaciones post servicio realizado, según la técnica y tratamiento empleado.
G23: =C23 -> 0 | H23: 9 | I23: =CONCATENATE(H23,". ",C23) -> 9.
G24: =C24 -> 0 | H24: 10 | I24: =CONCATENATE(H24,". ",C24) -> 10.
G25: =C25 -> 0 | H25: 11 | I25: =CONCATENATE(H25,". ",C25) -> 11.
G26: =C26 -> 0 | H26: 12 | I26: =CONCATENATE(H26,". ",C26) -> 12.
G27: =C27 -> 0 | H27: 13 | I27: =CONCATENATE(H27,". ",C27) -> 13.
G28: =C28 -> 0 | H28: 14 | I28: =CONCATENATE(H28,". ",C28) -> 14.
G29: =C29 -> 0 | H29: 15 | I29: =CONCATENATE(H29,". ",C29) -> 15.
A30: =CONCATENATE("Unidad de Competencia N° 02 (UC2): ",Perfil_Egreso!A21) -> Unidad de Competencia N° 02 (UC2): UC2. Realizar procedimientos técnicos capilares, tomando en cuenta su diagnóstico, requerimientos del cliente, y de bioseguridad e higiene. | C30: 1. Realiza el diagnóstico del cuero cabelludo, tomando en cuenta la condición de la hebra capilar, sus alteraciones, características y propiedades. | G30: =C30 -> 1. Realiza el diagnóstico del cuero cabelludo, tomando en cuenta la condición de la hebra capilar, sus alteraciones, características y propiedades. | H30: 1 | I30: =CONCATENATE(H30,". ",C30) -> 1. 1. Realiza el diagnóstico del cuero cabelludo, tomando en cuenta la condición de la hebra capilar, sus alteraciones, características y propiedades.
C31: 2. Verifica las condiciones del producto o productos a utilizar, siguiendo procedimientos del establecimiento y criterios de bioseguridad e higiene. | G31: =C31 -> 2. Verifica las condiciones del producto o productos a utilizar, siguiendo procedimientos del establecimiento y criterios de bioseguridad e higiene. | H31: 2 | I31: =CONCATENATE(H31,". ",C31) -> 2. 2. Verifica las condiciones del producto o productos a utilizar, siguiendo procedimientos del establecimiento y criterios de bioseguridad e higiene.
C32: 3. Realiza tratamiento capilar aplicando productos cosméticos y tomando en cuenta criterios técnicos, estéticos y de bioseguridad e higiene. | G32: =C32 -> 3. Realiza tratamiento capilar aplicando productos cosméticos y tomando en cuenta criterios técnicos, estéticos y de bioseguridad e higiene. | H32: 3 | I32: =CONCATENATE(H32,". ",C32) -> 3. 3. Realiza tratamiento capilar aplicando productos cosméticos y tomando en cuenta criterios técnicos, estéticos y de bioseguridad e higiene.
C33: 4. Realiza la decoloración y/o coloración del cabello, según incluye la morfología del rostro, cabeza, cuello, cuerpo, entre otras que correspondan. | G33: =C33 -> 4. Realiza la decoloración y/o coloración del cabello, según incluye la morfología del rostro, cabeza, cuello, cuerpo, entre otras que correspondan. | H33: 4 | I33: =CONCATENATE(H33,". ",C33) -> 4. 4. Realiza la decoloración y/o coloración del cabello, según incluye la morfología del rostro, cabeza, cuello, cuerpo, entre otras que correspondan.
C34: 5. Realiza cambios permanentes o temporales en el cabello, según requerimientos del cliente, criterios técnicos, y de bioseguridad e higiene. | G34: =C34 -> 5. Realiza cambios permanentes o temporales en el cabello, según requerimientos del cliente, criterios técnicos, y de bioseguridad e higiene. | H34: 5 | I34: =CONCATENATE(H34,". ",C34) -> 5. 5. Realiza cambios permanentes o temporales en el cabello, según requerimientos del cliente, criterios técnicos, y de bioseguridad e higiene.
C35: 6. Brinda recomendaciones post servicio realizado, según procedimiento o tratamiento realizado | G35: =C35 -> 6. Brinda recomendaciones post servicio realizado, según procedimiento o tratamiento realizado | H35: 6 | I35: =CONCATENATE(H35,". ",C35) -> 6. 6. Brinda recomendaciones post servicio realizado, según procedimiento o tratamiento realizado
G36: =C36 -> 0 | H36: 7 | I36: =CONCATENATE(H36,". ",C36) -> 7.
G37: =C37 -> 0 | H37: 8 | I37: =CONCATENATE(H37,". ",C37) -> 8.
G38: =C38 -> 0 | H38: 9 | I38: =CONCATENATE(H38,". ",C38) -> 9.
G39: =C39 -> 0 | H39: 10 | I39: =CONCATENATE(H39,". ",C39) -> 10.
G40: =C40 -> 0 | H40: 11 | I40: =CONCATENATE(H40,". ",C40) -> 11.
G41: =C41 -> 0 | H41: 12 | I41: =CONCATENATE(H41,". ",C41) -> 12.
G42: =C42 -> 0 | H42: 13 | I42: =CONCATENATE(H42,". ",C42) -> 13.
G43: =C43 -> 0 | H43: 14 | I43: =CONCATENATE(H43,". ",C43) -> 14.
G44: =C44 -> 0 | H44: 15 | I44: =CONCATENATE(H44,". ",C44) -> 15.
A45: =CONCATENATE("Unidad de Competencia N° 03 (UC3): ",Perfil_Egreso!A22) -> Unidad de Competencia N° 03 (UC3): UC3. Efectuar el servicio de maquillaje de belleza de acuerdo con los requerimientos del cliente, criterios técnicos, estéticos y de bioseguridad e higiene. | C45: 1. Identifica el biotipo cutáneo, teniendo en cuenta sus características (graso, alípico, mixto) y sus condiciones (color, alteraciones, rasgos y morfología facial). | G45: =C45 -> 1. Identifica el biotipo cutáneo, teniendo en cuenta sus características (graso, alípico, mixto) y sus condiciones (color, alteraciones, rasgos y morfología facial). | H45: 1 | I45: =CONCATENATE(H45,". ",C45) -> 1. 1. Identifica el biotipo cutáneo, teniendo en cuenta sus características (graso, alípico, mixto) y sus condiciones (color, alteraciones, rasgos y morfología facial).
C46: 2. Propone estilos de maquillaje, tomando en cuenta la ocasión, criterios estéticos, así como la morfología facial y requerimientos del cliente. | G46: =C46 -> 2. Propone estilos de maquillaje, tomando en cuenta la ocasión, criterios estéticos, así como la morfología facial y requerimientos del cliente. | H46: 2 | I46: =CONCATENATE(H46,". ",C46) -> 2. 2. Propone estilos de maquillaje, tomando en cuenta la ocasión, criterios estéticos, así como la morfología facial y requerimientos del cliente.
...

Sheet Capacidades
A1: FORMATO DE PROCESO - FORMULACIÓN DE CAPACIDADES E INDICADORES POR UNIDAD DE COMPETENCIA
A5: Programa de estudios: | E5: =Perfil_Egreso!B11 -> ESTILISMO | L5: RESUMEN
D7: Capacidades asociadas a la Unidad de Competencia Específica y de Empleabilidad | H7: Indicadores de la Capacidad
A9: MÓDULOS | B9: Tipo de capacidad | C9: Código Capacidad | D9: Verbo | E9: Objeto | F9: Condición | G9: Código Indicador | H9: Verbo | I9: Objeto | J9: Condición | K9: Observaciones de los facilitadores opcional | L9: Capacidades | M9: Indicadores
A10: Módulo I | B10: Capacidad técnica | C10: UC1C1 | D10: Ejecutar | E10: cortes de cabello | F10: tomando en cuenta tendencias y criterios estéticos, así como las diferentes morfologías y requerimientos del cliente. | G10: C1I1 | H10: Acondiciona | I10: su zona de trabajo, herramientas, materiales, presupuesto y control de calidad para el corte de cabello | J10: teniendo en cuenta las condiciones de seguridad y salubridad | L10: =CONCATENATE(C10," ",D10," ",E10," ",F10," ",C11," ",D11," ",E11," ",F11) -> UC1C1 Ejecutar cortes de cabello tomando en cuenta tendencias y criterios estéticos, así como las diferentes morfologías y requerimientos del cliente. | M10: =CONCATENATE(G10," ",H10," ",I10," ",J10) -> C1I1 Acondiciona su zona de trabajo, herramientas, materiales, presupuesto y control de calidad para el corte de cabello teniendo en cuenta las condiciones de seguridad y salubridad
G11: C1I2 | H11: Realiza | I11: el servicio de atenciòn al cliente | J11: teniendo en cuenta los protocolos y requerimientos del cliente | L11: =CONCATENATE(C11," ",D11," ",E11," ",F11," ",C12," ",D12," ",E12," ",F12) | M11: =CONCATENATE(G11," ",H11," ",I11," ",J11) -> C1I2 Realiza el servicio de atenciòn al cliente teniendo en cuenta los protocolos y requerimientos del cliente
G12: C1I3 | H12: Realiza | I12: el diagnóstico tricológico, dermatológico y morfológico al cliente | J12: tomando en cuenta tendencia y estilos de corte de cabello | L12: =CONCATENATE(C12," ",D12," ",E12," ",F12," ",C13," ",D13," ",E13," ",F13) | M12: =CONCATENATE(G12," ",H12," ",I12," ",J12) -> C1I3 Realiza el diagnóstico tricológico, dermatológico y morfológico al cliente tomando en cuenta tendencia y estilos de corte de cabello
G13: C1I4 | H13: Propone | I13: estilos de cortes de cabello, | J13: tomando en cuenta el diagnostico, tendencias, estilos y requerimientos del cliente. | L13: =CONCATENATE(C13," ",D13," ",E13," ",F13," ",C14," ",D14," ",E14," ",F14) | M13: =CONCATENATE(G13," ",H13," ",I13," ",J13) -> C1I4 Propone estilos de cortes de cabello, tomando en cuenta el diagnostico, tendencias, estilos y requerimientos del cliente.
G14: C1I5 | H14: Aplica | I14: técnicas de cortes de cabello | J14: tomando en cuenta la ficha de servicio y requerimiento del cliente | L14: =CONCATENATE(C14," ",D14," ",E14," ",F14," ",C15," ",D15," ",E15," ",F15) | M14: =CONCATENATE(G14," ",H14," ",I14," ",J14) -> C1I5 Aplica técnicas de cortes de cabello tomando en cuenta la ficha de servicio y requerimiento del cliente
L15: =CONCATENATE(C15," ",D15," ",E15," ",F15," ",C16," ",D16," ",E16," ",F16) | M15: =CONCATENATE(G15," ",H15," ",I15," ",J15)
L16: =CONCATENATE(C16," ",D16," ",E16," ",F16," ",C17," ",D17," ",E17," ",F17) | M16: =CONCATENATE(G16," ",H16," ",I16," ",J16)
L17: =CONCATENATE(C17," ",D17," ",E17," ",F17," ",C18," ",D18," ",E18," ",F18) | M17: =CONCATENATE(G17," ",H17," ",I17," ",J17)
L18: =CONCATENATE(C18," ",D18," ",E18," ",F18," ",C19," ",D19," ",E19," ",F19) | M18: =CONCATENATE(G18," ",H18," ",I18," ",J18)
L19: =CONCATENATE(C19," ",D19," ",E19," ",F19) | M19: =CONCATENATE(G19," ",H19," ",I19," ",J19)
A20: Módulo I | B20: Capacidad técnica | C20: UC1C2 | D20: Ejecutar | E20: cortes y diseño de barba y bigote | F20: tomando en cuenta tendencias y criterios estéticos, así como las diferentes morfologías y requerimientos del cliente. | G20: C2I1 | H20: Acondiciona | I20: su zona de trabajo, herramientas, materiales, presupuesto y control de calidad para cortes de barberia | J20: según estilo determinado, aplicando criterios técnicos, estéticos y de bioseguridad e higiene. | L20: =CONCATENATE(C20," ",D20," ",E20," ",F20," ",C21," ",D21," ",E21," ",F21) -> UC1C2 Ejecutar cortes y diseño de barba y bigote tomando en cuenta tendencias y criterios estéticos, así como las diferentes morfologías y requerimientos del cliente. | M20: =CONCATENATE(G20," ",H20," ",I20," ",J20) -> C2I1 Acondiciona su zona de trabajo, herramientas, materiales, presupuesto y control de calidad para cortes de barberia según estilo determinado, aplicando criterios técnicos, estéticos y de bioseguridad e higiene.
G21: C2I2 | H21: Realiza | I21: el diagnóstico dermatológico y morfológico al cliente | J21: tomando en cuenta tendencia y estilos de corte de barba y bigote | L21: =CONCATENATE(C21," ",D21," ",E21," ",F21," ",C22," ",D22," ",E22," ",F22) | M21: =CONCATENATE(G21," ",H21," ",I21," ",J21) -> C2I2 Realiza el diagnóstico dermatológico y morfológico al cliente tomando en cuenta tendencia y estilos de corte de barba y bigote
G22: C2I3 | H22: Realiza | I22: rasurado de barba con o sin diseño | J22: tomando en cuenta tendencias y criterios estéticos y aplicando procedimientos técnicos establecidos. | L22: =CONCATENATE(C22," ",D22," ",E22," ",F22," ",C23," ",D23," ",E23," ",F23) | M22: =CONCATENATE(G22," ",H22," ",I22," ",J22) -> C2I3 Realiza rasurado de barba con o sin diseño tomando en cuenta tendencias y criterios estéticos y aplicando procedimientos técnicos establecidos.
G23: C2I4 | H23: Realiza | I23: cortes con o sin diseño de bigote | J23: teniendo en cuenta las características morfologías y requerimientos del cliente y aplicando procedimientos técnicos establecidos. | L23: =CONCATENATE(C23," ",D23," ",E23," ",F23," ",C24," ",D24," ",E24," ",F24) | M23: =CONCATENATE(G23," ",H23," ",I23," ",J23) -> C2I4 Realiza cortes con o sin diseño de bigote teniendo en cuenta las características morfologías y requerimientos del cliente y aplicando procedimientos técnicos establecidos.
G24: C2I5 | H24: Verifica | I24: el acabado del corte realizado | J24: considerando los criterios estéticos, procedimientos tecnicos establecidos y de bioseguridad e higiene personal. | L24: =CONCATENATE(C24," ",D24," ",E24," ",F24," ",C25," ",D25," ",E25," ",F25) | M24: =CONCATENATE(G24," ",H24," ",I24," ",J24) -> C2I5 Verifica el acabado del corte realizado considerando los criterios estéticos, procedimientos tecnicos establecidos y de bioseguridad e higiene personal.
L25: =CONCATENATE(C25," ",D25," ",E25," ",F25," ",C26," ",D26," ",E26," ",F26) | M25: =CONCATENATE(G25," ",H25," ",I25," ",J25)
L26: =CONCATENATE(C26," ",D26," ",E26," ",F26," ",C27," ",D27," ",E27," ",F27) | M26: =CONCATENATE(G26," ",H26," ",I26," ",J26)
L27: =CONCATENATE(C27," ",D27," ",E27," ",F27," ",C28," ",D28," ",E28," ",F28) | M27: =CONCATENATE(G27," ",H27," ",I27," ",J27)
L28: =CONCATENATE(C28," ",D28," ",E28," ",F28," ",C29," ",D29," ",E29," ",F29) | M28: =CONCATENATE(G28," ",H28," ",I28," ",J28)
L29: =CONCATENATE(C29," ",D29," ",E29," ",F29) | M29: =CONCATENATE(G29," ",H29," ",I29," ",J29)
A30: Módulo I | B30: Capacidad técnica | C30: UC1C3 | D30: Ejecutar | E30: peinados | F30: según procedimientos tècnicos, creatividad y normas de bioseguridad e higiene. | G30: C3I1 | H30: Acondiciona | I30: su zona de trabajo, herramientas y productos para peinados | J30: teniendo en cuenta las condiciones de bioseguridad e higiene | L30: =CONCATENATE(C30," ",D30," ",E30," ",F30," ",C31," ",D31," ",E31," ",F31) -> UC1C3 Ejecutar peinados según procedimientos tècnicos, creatividad y normas de bioseguridad e higiene. | M30: =CONCATENATE(G30," ",H30," ",I30," ",J30) -> C3I1 Acondiciona su zona de trabajo, herramientas y productos para peinados teniendo en cuenta las condiciones de bioseguridad e higiene
G31: C3I2 | H31: Prepara | I31: el cabello para el peinado, | J31: considerando el diagnostico, aplicando técnicas y utilizando equipos térmicos. | L31: =CONCATENATE(C31," ",D31," ",E31," ",F31," ",C32," ",D32," ",E32," ",F32) | M31: =CONCATENATE(G31," ",H31," ",I31," ",J31) -> C3I2 Prepara el cabello para el peinado, considerando el diagnostico, aplicando técnicas y utilizando equipos térmicos.
G32: C3I3 | H32: Realiza | I32: diversos peinados | J32: tomando en cuenta tendencias y criterios estéticos, diagnostico y requerimientos del cliente. | L32: =CONCATENATE(C32," ",D32," ",E32," ",F32," ",C33," ",D33," ",E33," ",F33) | M32: =CONCATENATE(G32," ",H32," ",I32," ",J32) -> C3I3 Realiza diversos peinados tomando en cuenta tendencias y criterios estéticos, diagnostico y requerimientos del cliente.
G33: C3I4 | H33: Aplica | I33: postizos y/o extensiones en los peinados | J33: considerando técnicas, criterios estéticos y requerimientos del cliente. | L33: =CONCATENATE(C33," ",D33," ",E33," ",F33," ",C34," ",D34," ",E34," ",F34) | M33: =CONCATENATE(G33," ",H33," ",I33," ",J33) -> C3I4 Aplica postizos y/o extensiones en los peinados considerando técnicas, criterios estéticos y requerimientos del cliente.
G34: C3I5 | H34: Verifica | I34: el acabado del peinado | J34: considerando los criterios estéticos, procedimientos tecnicos establecidos y de bioseguridad e higiene personal. | L34: =CONCATENATE(C34," ",D34," ",E34," ",F34," ",C35," ",D35," ",E35," ",F35) | M34: =CONCATENATE(G34," ",H34," ",I34," ",J34) -> C3I5 Verifica el acabado del peinado considerando los criterios estéticos, procedimientos tecnicos establecidos y de bioseguridad e higiene personal.
L35: =CONCATENATE(C35," ",D35," ",E35," ",F35," ",C36," ",D36," ",E36," ",F36) | M35: =CONCATENATE(G35," ",H35," ",I35," ",J35)
L36: =CONCATENATE(C36," ",D36," ",E36," ",F36," ",C37," ",D37," ",E37," ",F37) | M36: =CONCATENATE(G36," ",H36," ",I36," ",J36)
L37: =CONCATENATE(C37," ",D37," ",E37," ",F37," ",C38," ",D38," ",E38," ",F38) | M37: =CONCATENATE(G37," ",H37," ",I37," ",J37)
L38: =CONCATENATE(C38," ",D38," ",E38," ",F38," ",C39," ",D39," ",E39," ",F39) | M38: =CONCATENATE(G38," ",H38," ",I38," ",J38)
L39: =CONCATENATE(C39," ",D39," ",E39," ",F39) | M39: =CONCATENATE(G39," ",H39," ",I39," ",J39)
A40: Módulo I | B40: Capacidad técnica | L40: =CONCATENATE(C40," ",D40," ",E40," ",F40," ",C41," ",D41," ",E41," ",F41) | M40: =CONCATENATE(G40," ",H40," ",I40," ",J40)
L41: =CONCATENATE(C41," ",D41," ",E41," ",F41," ",C42," ",D42," ",E42," ",F42) | M41: =CONCATENATE(G41," ",H41," ",I41," ",J41)
L42: =CONCATENATE(C42," ",D42," ",E42," ",F42," ",C43," ",D43," ",E43," ",F43) | M42: =CONCATENATE(G42," ",H42," ",I42," ",J42)
L43: =CONCATENATE(C43," ",D43," ",E43," ",F43," ",C44," ",D44," ",E44," ",F44) | M43: =CONCATENATE(G43," ",H43," ",I43," ",J43)
L44: =CONCATENATE(C44," ",D44," ",E44," ",F44," ",C45," ",D45," ",E45," ",F45) | M44: =CONCATENATE(G44," ",H44," ",I44," ",J44)
L45: =CONCATENATE(C45," ",D45," ",E45," ",F45," ",C46," ",D46," ",E46," ",F46) | M45: =CONCATENATE(G45," ",H45," ",I45," ",J45)
...

Sheet Organización_Modular
A1: ORGANIZACIÓN MODULAR
A3: DENOMINACIÓN DE LA INSTITUCIÓN | C3: =Perfil_Egreso!B3 -> CETPRO JUANJUI | F3: CÓDIGO MODULAR | G3: =Perfil_Egreso!E3 -> 533836
A5: =Perfil_Egreso!A11 -> DENOMINACIÓN DEL PROGRAMA DE ESTUDIOS | C5: =Perfil_Egreso!B11 -> ESTILISMO | D5: CÓDIGO * | E5: =Perfil_Egreso!E11 -> S3496-2-001 | F5: NIVEL FORMATIVO | G5: =Perfil_Egreso!B15 -> TÉCNICO
A7: =Perfil_Egreso!A13 -> FORMACIÓN** | C7: =Perfil_Egreso!B13 -> 0 | E7: MODALIDAD DEL SERVICIO EDUCATIVO | F7: =Perfil_Egreso!D13 -> PRESENCIAL
H8: Información solo de proceso
A9: MÓDULO | B9: DESCRIPCIÓN DE LA COMPETENCIA | D9: CAPACIDADES | F9: UNIDAD DIDÁCTICA | G9: PERIODO ACADÉMICO | H9: Crédito teórico | I9: Crédito práctico | J9: T.créditos (Filtrar)
A10: M1. PELUQUERIA, BARBERÍA Y PEINADOS | B10: Competencias técnicas (Unidad de competencia) | C10: UC1. Ejecutar el servicio de peluquería y barbería, teniendo en cuenta el diagnóstico capilar, requerimientos del cliente, procedimientos del establecimiento, criterios técnicos, estéticos y de bioseguridad e higiene. . | D10: =OFFSET(Capacidades!$A$1,(ROW()-9)*10-1,11) -> UC1C1 Ejecutar cortes de cabello tomando en cuenta tendencias y criterios estéticos, así como las diferentes morfologías y requerimientos del cliente. | F10: CORTE DE CABELLO | G10: I | H10: 2 | I10: 5 | J10: =SUM(H10:I10) -> 7 | L10: UC1 C3 Ejecutar peinados según procedimientos tecnicos, creatividad y normas de bioseguridad e higiene
D11: =OFFSET(Capacidades!$A$1,(ROW()-9)*10-1,11) -> UC1C2 Ejecutar cortes y diseño de barba y bigote tomando en cuenta tendencias y criterios estéticos, así como las diferentes morfologías y requerimientos del cliente. | F11: CORTE Y DISEÑO DE BARBA | G11: I | H11: 1 | I11: 2 | J11: =SUM(H11:I11) -> 3
D12: =OFFSET(Capacidades!$A$1,(ROW()-9)*10-1,11) -> UC1C3 Ejecutar peinados según procedimientos tècnicos, creatividad y normas de bioseguridad e higiene. | F12: PEINADOS | G12: I | H12: 1 | I12: 2 | J12: =SUM(H12:I12) -> 3
D13: =OFFSET(Capacidades!$A$1,(ROW()-9)*10-1,11) | J13: =SUM(H13:I13) -> 0 | M13: 1 | N13: 1
D14: =OFFSET(Capacidades!$A$1,(ROW()-9)*10-1,11) | J14: =SUM(H14:I14) -> 0 | M14: 0 | N14: 1
D15: =OFFSET(Capacidades!$A$1,(ROW()-9)*10-1,11) | J15: =SUM(H15:I15) -> 0
D16: =OFFSET(Capacidades!$A$1,(ROW()-9)*10-1,11) | J16: =SUM(H16:I16) -> 0
D17: =OFFSET(Capacidades!$A$1,(ROW()-9)*10-1,11) | J17: =SUM(H17:I17) -> 0
D18: =OFFSET(Capacidades!$A$1,(ROW()-9)*10-1,11) | J18: =SUM(H18:I18) -> 0
D19: =OFFSET(Capacidades!$A$1,(ROW()-9)*10-1,11) | J19: =SUM(H19:I19) -> 0
D20: =OFFSET(Capacidades!$A$1,(ROW()-9)*10-1,11) | J20: =SUM(H20:I20) -> 0
D21: =OFFSET(Capacidades!$A$1,(ROW()-9)*10-1,11) | J21: =SUM(H21:I21) -> 0
D22: =OFFSET(Capacidades!$A$1,(ROW()-9)*10-1,11) | J22: =SUM(H22:I22) -> 0
D23: =OFFSET(Capacidades!$A$1,(ROW()-9)*10-1,11) | J23: =SUM(H23:I23) -> 0
D24: =OFFSET(Capacidades!$A$1,(ROW()-9)*10-1,11) | J24: =SUM(H24:I24) -> 0
D25: =OFFSET(Capacidades!$A$1,(ROW()-9)*10-1,11) | J25: =SUM(H25:I25) -> 0
D26: =OFFSET(Capacidades!$A$1,(ROW()-9)*10-1,11) | J26: =SUM(H26:I26) -> 0
... D29: =OFFSET(Capacidades!$A$1,(ROW()-9)*10-1,11) | J29: =SUM(H29:I29) -> 0
B30: Competencias para la empleabilidad | C30: CE1 Comunicación efectiva.- expresar y comprender de manera clara conceptos, ideas, sentimientos, hechos y opiniones en forma oral y escrita para comunicarse e interactuar con otras personas en contextos sociales y laborales diversos. | D30: =OFFSET(Capacidades!$A$1,(ROW()-9)*10-1,11) -> CE1. C1 Expresar conceptos, ideas, sentimientos y hechos en la forma oral en la interacción con otras personas en diferentes contextos. | F30: COMUNICACIÓN VERBAL EFECTIVA | G30: I | H30: 1 | I30: 1 | J30: =SUM(H30:I30) -> 2
D31: =OFFSET(Capacidades!$A$1,(ROW()-9)*10-1,11) -> CE1. C2 Interpretar conceptos, ideas y hechos expresados de manera escrita en diferentes contextos. | F31: COMUNICACIÓN ESCRITA | G31: I | H31: 0 | I31: 1 | J31: =SUM(H31:I31) -> 1
D32: =OFFSET(Capacidades!$A$1,(ROW()-9)*10-1,11) | J32: =SUM(H32:I32) -> 0
D33: =OFFSET(Capacidades!$A$1,(ROW()-9)*10-1,11) | J33: =SUM(H33:I33) -> 0
D34: =OFFSET(Capacidades!$A$1,(ROW()-9)*10-1,11) | J34: =SUM(H34:I34) -> 0
D35: =OFFSET(Capacidades!$A$1,(ROW()-9)*10-1,11) | J35: =SUM(H35:I35) -> 0
D36: =OFFSET(Capacidades!$A$1,(ROW()-9)*10-1,11) | J36: =SUM(H36:I36) -> 0
D37: =OFFSET(Capacidades!$A$1,(ROW()-9)*10-1,11) | J37: =SUM(H37:I37) -> 0
D38: =OFFSET(Capacidades!$A$1,(ROW()-9)*10-1,11) | J38: =SUM(H38:I38) -> 0
D39: =OFFSET(Capacidades!$A$1,(ROW()-9)*10-1,11) | J39: =SUM(H39:I39) -> 0
B40: Experiencias formativas en situaciones reales de trabajo (EFSRT) | G40: I | H40: 0 | I40: 4 | J40: =SUM(H40:I40) -> 4
A41: M2. ONDULACIÓN, LACEADO Y TINTURACIÓN DEL CABELLO | B41: =$B$10 -> Competencias técnicas (Unidad de competencia) | C41: UC2. Realizar procedimientos técnicos capilares, tomando en cuenta su diagnóstico, requerimientos del cliente, y de bioseguridad e higiene técnicos capilares, tomando en cuenta su diagnóstico, requerimientos del cliente, y de bioseguridad e higiene. | D41: =OFFSET(Capacidades!$A$302,(ROW()-40)*10-1,11) -> UC2C1 Ejecutar el tratamiento capilar tomando en cuenta el diagnostico tricologico y dermatologico | F41: TRATAMIENTO CAPILAR | G41: II | H41: 2 | I41: 3 | J41: =SUM(H41:I41) -> 5
D42: =OFFSET(Capacidades!$A$302,(ROW()-40)*10-1,11) -> UC2C2 Ejecutar cambios permanentes o temporales del cabello según requerimientos del cliente, criterios técnicos, esteticos y de bioseguridad e higiene. | F42: ONDULACIÓN Y LACEADO | G42: II | H42: 2 | I42: 4 | J42: =SUM(H42:I42) -> 6
D43: =OFFSET(Capacidades!$A$302,(ROW()-40)*10-1,11) -> UC2C3 Ejecutar cambios en la decoloración y/o coloración del cabello con tecnicas directas e indirectas aplicando criterios técnicos, estéticos y de bioseguridad e higiene.. | F43: TINTURACIÓN Y DECOLORACION DEL CABELLO | G43: II | H43: 2 | I43: 2 | J43: =SUM(H43:I43) -> 4
D44: =OFFSET(Capacidades!$A$302,(ROW()-40)*10-1,11) | J44: =SUM(H44:I44) -> 0
D45: =OFFSET(Capacidades!$A$302,(ROW()-40)*10-1,11) | J45: =SUM(H45:I45) -> 0
...

Sheet M1
A1: ORGANIZACIÓN DE LOS ELEMENTOS DEL MÓDULO
A3: DENOMINACIÓN DE LA INSTITUCIÓN | B3: =Perfil_Egreso!B3 -> CETPRO JUANJUI | F3: CÓDIGO MODULAR DEL INSTITUTO | I3: =Perfil_Egreso!E3 -> 533836
A5: SECTOR ECONÓMICO | B5: =Perfil_Egreso!B5 -> OTRAS ACTIVIDADES DE SERVICIO | C5: FAMILIA PRODUCTIVA | D5: =Perfil_Egreso!D5 -> SERVICIOS PERSONALES Y DE HOGARES | F5: ACTIVIDAD ECONÓMICA | I5: =Perfil_Egreso!B7 -> OTRAS ACTIVIDADES DE SERVICIOS PERSONALES
A7: =Perfil_Egreso!A11 -> DENOMINACIÓN DEL PROGRAMA DE ESTUDIOS | B7: =Perfil_Egreso!B11 -> ESTILISMO | C7: CÓDIGO * | D7: =Perfil_Egreso!E11 -> S3496-2-001
A9: =Perfil_Egreso!A13 -> FORMACIÓN** | B9: =Perfil_Egreso!B13 -> 0 | C9: N°. HORAS: | D9: =Itinerario!W17 -> 2272 | F9: N° CRÉDITOS: | I9: =Itinerario!T17 -> 83
A11: =Perfil_Egreso!C13 -> MODALIDAD DEL SERVICIO EDUCATIVO *** | B11: =Perfil_Egreso!D13 -> PRESENCIAL | F11: =Perfil_Egreso!A15 -> CICLO FORMATIVO | I11: =Perfil_Egreso!B15 -> TÉCNICO
A13: UNIDAD DE COMPETENCIA DEL CATÁLOGO NACIONAL DE LA OFERTA FORMATIVA
A14: =Organización_Modular!C10 -> UC1. Ejecutar el servicio de peluquería y barbería, teniendo en cuenta el diagnóstico capilar, requerimientos del cliente, procedimientos del establecimiento, criterios técnicos, estéticos y de bioseguridad e higiene. .
A15: DENOMINACIÓN DEL MÓDULO | B15: =Organización_Modular!A10 -> M1. PELUQUERIA, BARBERÍA Y PEINADOS
A16: CAPACIDADES TÉCNICAS O ESPECÍFICAS | B16: INDICADORES DE LOGRO DE LA CAPACIDAD | C16: CONTENIDOS | D16: UNIDAD DIDÁCTICA | E16: Periodo | F16: CRÉDITOS | H16: CRÉDITOS | I16: HORAS | K16: HORAS | L16: PERFIL DOCENTE | M16: Filtrar
F17: Teórico | G17: Práctica | I17: Teórico | J17: Práctica
A18: =Capacidades!L10 -> UC1C1 Ejecutar cortes de cabello tomando en cuenta tendencias y criterios estéticos, así como las diferentes morfologías y requerimientos del cliente. | B18: =Capacidades!M10 -> C1I1 Acondiciona su zona de trabajo, herramientas, materiales, presupuesto y control de calidad para el corte de cabello teniendo en cuenta las condiciones de seguridad y salubridad | C18: •Organizacion del taller - tipos - señalizacion- normas de seguridad e higiene •Tecnologia de los equipos de peluqueria- tipos- Caracteristicas - usos. mantenimiento preventivo •Normas de Bioseguridad •Costos y presupuesto •Control de calidad | D18: =Organización_Modular!F10 -> CORTE DE CABELLO | E18: =Organización_Modular!G10 -> I | F18: =Organización_Modular!H10 -> 2 | G18: =Organización_Modular!I10 -> 5 | H18: =SUM(F18:G18) -> 7 | I18: =F18*16 -> 32 | J18: =G18*32 -> 160 | K18: =SUM(I18:J18) -> 192 | L18: Docente de Educación Técnica con especialidad en en Peluqueria y/o Cosmetología | M18: =B18 -> C1I1 Acondiciona su zona de trabajo, herramientas, materiales, presupuesto y control de calidad para el corte de cabello teniendo en cuenta las condiciones de seguridad y salubridad
B19: =Capacidades!M11 -> C1I2 Realiza el servicio de atenciòn al cliente teniendo en cuenta los protocolos y requerimientos del cliente | C19: • Cliente - Atención al cliente- caracteristicas -protocolos Tecnologia de los materiales - tipos- marcas-caracteristicas- uso- conservación | M19: =B19 -> C1I2 Realiza el servicio de atenciòn al cliente teniendo en cuenta los protocolos y requerimientos del cliente
B20: =Capacidades!M12 -> C1I3 Realiza el diagnóstico tricológico, dermatológico y morfológico al cliente tomando en cuenta tendencia y estilos de corte de cabello | C20: • Historia de Corte de Cabello - tipos • El cabello - caracteristicas - Alteraciones - Lavado de cabello- procedimientos- frecuencia •Cuero cabelludo - alteraciones • Morfologia (Rostro - Caracteristicas - Perfil - craneo, etc) •Diagnóstico - importancia- estructura - Ficha Diagnòstica del cliente - Recomendaciones | M20: =B20 -> C1I3 Realiza el diagnóstico tricológico, dermatológico y morfológico al cliente tomando en cuenta tendencia y estilos de corte de cabello
B21: =Capacidades!M13 -> C1I4 Propone estilos de cortes de cabello, tomando en cuenta el diagnostico, tendencias, estilos y requerimientos del cliente. | C21: • La Tijera : partes y tipos. uso- mantenimiento. •La Maquina Cliper: uso .clasificacion -mantenimiento. •La Navaja:tipos- uso - mantenimiento •Productos de Limpieza . Productos de Pre y post tratamiento del Corte de cabello - Recomendaciones •Corte de cabello - Técnicas - Angulos y grados de elevaciòn: 0º, 45º,90º, 135º y 180º - lineas de corte • Técnicas de rasurado de cuello y patilla Tipos de corte (tijera, maquina clipper, navaja)- Estilos de corte -Formas de corte: (Texturizado -degradado, encapado uniforme . encapado incrementado, desgrafilado). | M21: =B21 -> C1I4 Propone estilos de cortes de cabello, tomando en cuenta el diagnostico, tendencias, estilos y requerimientos del cliente.
M22: =B22
B23: =Capacidades!M15 | M23: =B23
B24: =Capacidades!M16 | M24: =B24
B25: =Capacidades!M17 | M25: =B25
B26: =Capacidades!M18 | M26: =B26
B27: =Capacidades!M19 | M27: =B27
A28: =Capacidades!L20 -> UC1C2 Ejecutar cortes y diseño de barba y bigote tomando en cuenta tendencias y criterios estéticos, así como las diferentes morfologías y requerimientos del cliente. | B28: =Capacidades!M20 -> C2I1 Acondiciona su zona de trabajo, herramientas, materiales, presupuesto y control de calidad para cortes de barberia según estilo determinado, aplicando criterios técnicos, estéticos y de bioseguridad e higiene. | C28: • Organización del área de trabajo - señalizacion- normas de seguridad e higiene •Tecnologia de los equipos de peluqueria- tipos- Caracteristicas - usos. mantenimiento preventivo - Normas de bioseguridad- desinfeccion, esterilizacion • Tecnología de los materiales - tipos- marcas- caractetristicas- conservaciòn. • Manejo de presupuestos, Control de calidad | D28: =Organización_Modular!F11 -> CORTE Y DISEÑO DE BARBA | E28: =Organización_Modular!G11 -> I | F28: =Organización_Modular!H11 -> 1 | G28: =Organización_Modular!I11 -> 2 | H28: =SUM(F28:G28) -> 3 | I28: =F28*16 -> 16 | J28: =G28*32 -> 64 | K28: =SUM(I28:J28) -> 80 | L28: Docente de Educación Técnica con especialidad en en Peluqueria y/o Cosmetología | M28: =B28 -> C2I1 Acondiciona su zona de trabajo, herramientas, materiales, presupuesto y control de calidad para cortes de barberia según estilo determinado, aplicando criterios técnicos, estéticos y de bioseguridad e higiene.
B29: =Capacidades!M21 -> C2I2 Realiza el diagnóstico dermatológico y morfológico al cliente tomando en cuenta tendencia y estilos de corte de barba y bigote | C29: • Estudio dermatologico - Morfológico Tendencias . Estilos | M29: =B29 -> C2I2 Realiza el diagnóstico dermatológico y morfológico al cliente tomando en cuenta tendencia y estilos de corte de barba y bigote
B30: =Capacidades!M22 -> C2I3 Realiza rasurado de barba con o sin diseño tomando en cuenta tendencias y criterios estéticos y aplicando procedimientos técnicos establecidos. | C30: Técnicas de rasurado tendencias | M30: =B30 -> C2I3 Realiza rasurado de barba con o sin diseño tomando en cuenta tendencias y criterios estéticos y aplicando procedimientos técnicos establecidos.
B31: =Capacidades!M23 -> C2I4 Realiza cortes con o sin diseño de bigote teniendo en cuenta las características morfologías y requerimientos del cliente y aplicando procedimientos técnicos establecidos. | C31: • Técnica de corte y diseño de barba • Técnica de corte y diseños de bigotes | M31: =B31 -> C2I4 Realiza cortes con o sin diseño de bigote teniendo en cuenta las características morfologías y requerimientos del cliente y aplicando procedimientos técnicos establecidos.
B32: =Capacidades!M24 -> C2I5 Verifica el acabado del corte realizado considerando los criterios estéticos, procedimientos tecnicos establecidos y de bioseguridad e higiene personal. | C32: • Técnicas de acabados. Control de calidad - Recomendaciones post servicio | M32: =B32 -> C2I5 Verifica el acabado del corte realizado considerando los criterios estéticos, procedimientos tecnicos establecidos y de bioseguridad e higiene personal.
B33: =Capacidades!M25 | M33: =B33
B34: =Capacidades!M26 | M34: =B34
B35: =Capacidades!M27 | M35: =B35
B36: =Capacidades!M28 | M36: =B36
B37: =Capacidades!M29 | M37: =B37
A38: =Capacidades!L30 -> UC1C3 Ejecutar peinados según procedimientos tècnicos, creatividad y normas de bioseguridad e higiene. | B38: =Capacidades!M30 -> C3I1 Acondiciona su zona de trabajo, herramientas y productos para peinados teniendo en cuenta las condiciones de bioseguridad e higiene | C38: • Organización del área de trabajo - señalización- normas de seguridad e higiene •Tecnología de los equipos de peluqueria- tipos- Características - usos. mantenimiento preventivo - Normas de bioseguridad- desinfección, esterilizacion • Manejo de presupuestos, Control de calidad y bioseguridad | D38: =Organización_Modular!F12 -> PEINADOS | E38: =Organización_Modular!G12 -> I | F38: =Organización_Modular!H12 -> 1 | G38: =Organización_Modular!I12 -> 2 | H38: =SUM(F38:G38) -> 3 | I38: =F38*16 -> 16 | J38: =G38*32 -> 64 | K38: =SUM(I38:J38) -> 80 | M38: =B38 -> C3I1 Acondiciona su zona de trabajo, herramientas y productos para peinados teniendo en cuenta las condiciones de bioseguridad e higiene
B39: =Capacidades!M31 -> C3I2 Prepara el cabello para el peinado, considerando el diagnostico, aplicando técnicas y utilizando equipos térmicos. | C39: •Peinado - tipos - estilos- • Ficha diagnóstica •Tecnología de los materiales, - tipos- marcas- características-usos • Limpieza - secado del cabello | M39: =B39 -> C3I2 Prepara el cabello para el peinado, considerando el diagnostico, aplicando técnicas y utilizando equipos térmicos.
B40: =Capacidades!M32 -> C3I3 Realiza diversos peinados tomando en cuenta tendencias y criterios estéticos, diagnostico y requerimientos del cliente. | C40: • Peinado - tipos - estilos- • Técnicas de Trenzado • Técnicas de cepillado • Técnicas de Moños • Técnicas de Cepillado • Técnicas de planchado y rizado • Técnicass de peinados recogidos • Tecnicas de peinados de fantasia | M40: =B40 -> C3I3 Realiza diversos peinados tomando en cuenta tendencias y criterios estéticos, diagnostico y requerimientos del cliente.
B41: =Capacidades!M33 -> C3I4 Aplica postizos y/o extensiones en los peinados considerando técnicas, criterios estéticos y requerimientos del cliente. | C41: • Técnicas de peinados con postizos • Técnicas de peinados con extensiones | M41: =B41 -> C3I4 Aplica postizos y/o extensiones en los peinados considerando técnicas, criterios estéticos y requerimientos del cliente.
B42: =Capacidades!M34 -> C3I5 Verifica el acabado del peinado considerando los criterios estéticos, procedimientos tecnicos establecidos y de bioseguridad e higiene personal. | C42: Técnicas de Acabados Recomendaciones post servicio | M42: =B42 -> C3I5 Verifica el acabado del peinado considerando los criterios estéticos, procedimientos tecnicos establecidos y de bioseguridad e higiene personal.
B43: =Capacidades!M35 | M43: =B43
B44: =Capacidades!M36 | M44: =B44
B45: =Capacidades!M37 | M45: =B45
B46: =Capacidades!M38 | M46: =B46
...

Sheet M2
A1: ='M1'!A1:L1 -> ORGANIZACIÓN DE LOS ELEMENTOS DEL MÓDULO
A3: DENOMINACIÓN DE LA INSTITUCIÓN | B3: =Perfil_Egreso!B3 -> CETPRO JUANJUI | F3: CÓDIGO MODULAR DEL INSTITUTO | I3: =Perfil_Egreso!E3 -> 533836
A5: SECTOR ECONÓMICO | B5: =Perfil_Egreso!B5 -> OTRAS ACTIVIDADES DE SERVICIO | C5: FAMILIA PRODUCTIVA | D5: =Perfil_Egreso!D5 -> SERVICIOS PERSONALES Y DE HOGARES | F5: ACTIVIDAD ECONÓMICA | I5: =Perfil_Egreso!B7 -> OTRAS ACTIVIDADES DE SERVICIOS PERSONALES
A7: =Perfil_Egreso!A11 -> DENOMINACIÓN DEL PROGRAMA DE ESTUDIOS | B7: =Perfil_Egreso!B11 -> ESTILISMO | C7: CÓDIGO * | D7: =Perfil_Egreso!E11 -> S3496-2-001 | F7: =Perfil_Egreso!A9 -> DENOMINACIÓN VARIANTE | I7: =Perfil_Egreso!B9 -> 0
A9: =Perfil_Egreso!A13 -> FORMACIÓN** | B9: =Perfil_Egreso!B13 -> 0 | C9: N°. HORAS: | D9: =Itinerario!W17 -> 2272 | F9: N° CRÉDITOS: | I9: =Itinerario!T17 -> 83
A11: =Perfil_Egreso!C13 -> MODALIDAD DEL SERVICIO EDUCATIVO *** | B11: =Perfil_Egreso!D13 -> PRESENCIAL | F11: =Perfil_Egreso!A15 -> CICLO FORMATIVO | I11: =Perfil_Egreso!B15 -> TÉCNICO
A13: UNIDAD DE COMPETENCIA DEL CATÁLOGO NACIONAL DE LA OFERTA FORMATIVA
A14: =Organización_Modular!C41 -> UC2. Realizar procedimientos técnicos capilares, tomando en cuenta su diagnóstico, requerimientos del cliente, y de bioseguridad e higiene técnicos capilares, tomando en cuenta su diagnóstico, requerimientos del cliente, y de bioseguridad e higiene.
A15: DENOMINACIÓN DEL MÓDULO | B15: =Organización_Modular!A41 -> M2. ONDULACIÓN, LACEADO Y TINTURACIÓN DEL CABELLO
A16: CAPACIDADES TÉCNICAS O ESPECÍFICAS | B16: INDICADORES DE LOGRO DE LA CAPACIDAD | C16: CONTENIDOS | D16: UNIDAD DIDÁCTICA | E16: Periodo | F16: CRÉDITOS | H16: CRÉDITOS | I16: HORAS | K16: HORAS | L16: PERFIL DOCENTE | M16: Filtrar
F17: Teórico | G17: Práctica | I17: Teórico | J17: Práctica
A18: =Capacidades!L311 -> UC2C1 Ejecutar el tratamiento capilar tomando en cuenta el diagnostico tricologico y dermatologico | B18: =Capacidades!M311 -> C1I1 Acondiciona su zona de trabajo, herramientas, materiales para el tratamiento capilar teniendo en cuenta los procedimientos del establecimiento, estandares de calidad según el servicio a realizar. | C18: • Organización del área de trabajo, Manejo y mantenimiento de herramientas para el tratamiento capilar • Manejo de presupuestos, Control de calidad • Normas de bioseguridad e higiene. | D18: =Organización_Modular!F41 -> TRATAMIENTO CAPILAR | E18: =Organización_Modular!G41 -> II | F18: =Organización_Modular!H41 -> 2 | G18: =Organización_Modular!I41 -> 3 | H18: =SUM(F18:G18) -> 5 | I18: =F18*16 -> 32 | J18: =G18*32 -> 96 | K18: =SUM(I18:J18) -> 128 | L18: Docente de Educación Técnica con especialidad en en Peluqueria y/o Cosmetología | M18: =B18 -> C1I1 Acondiciona su zona de trabajo, herramientas, materiales para el tratamiento capilar teniendo en cuenta los procedimientos del establecimiento, estandares de calidad según el servicio a realizar.
B19: =Capacidades!M312 -> C1I2 Diagnostica el cuero cabelludo y la hebra capilar siguiendo los criterios técnicos establecidos y de bioseguridad e higiene. | C19: • Estructura del cuero cabelludo y la hebra capilar. • Diagnóstico Tricológico: Alteraciones, caracteristicas del cuero cabelludo y de la hebra capilar. . | M19: =B19 -> C1I2 Diagnostica el cuero cabelludo y la hebra capilar siguiendo los criterios técnicos establecidos y de bioseguridad e higiene.
B20: =Capacidades!M313 -> C1I3 Verifica los productos a utilizar siguiendo los procedimientos establecidos | C20: • Aplicación de ficha técnica de diagnóstico. • Tecnología de los equipos, materiales y productos cosméticos capilares. Importancia del pH en el cabello. Mascarillas naturales para cabellos no tratados/tratados. | M20: =B20 -> C1I3 Verifica los productos a utilizar siguiendo los procedimientos establecidos
B21: =Capacidades!M314 -> C1I4 Aplica el tratamiento capilar con productos naturales verificando las condiciones del producto natural a utilizar siguiendo criterios de bioseguridad e higiene. | C21: •Tipos de productos y tratamientos • Acondicionador. Ampolletas, Cremas. Mascarillas. Lociones capilares Tratamiento con keratina y recomendaciones post servicio • Tratamiento con botox y recomendaciones post servicio | M21: =B21 -> C1I4 Aplica el tratamiento capilar con productos naturales verificando las condiciones del producto natural a utilizar siguiendo criterios de bioseguridad e higiene.
B22: =Capacidades!M315 -> C1I5 Aplica el tratamiento capilar con productos quimicos verificando las condiciones del producto o productos quimicos a utilizar siguiendo criterios de bioseguridad e higiene. | C22: •Tratamiento capilar con Productos naturales. Mascarillas, tónicos, lociones naturales para cabellos no tratados /tratados. | M22: =B22 -> C1I5 Aplica el tratamiento capilar con productos quimicos verificando las condiciones del producto o productos quimicos a utilizar siguiendo criterios de bioseguridad e higiene.
B23: =Capacidades!M316 -> C1I6 Elabora el presupuesto teniendo en cuenta el servicio a realizar | C23: Costos- Presupuesto Costos directos e indirectos- costo total | M23: =B23 -> C1I6 Elabora el presupuesto teniendo en cuenta el servicio a realizar
M24: =B24 -> 0
B25: =Capacidades!M318 | M25: =B25
B26: =Capacidades!M319 | M26: =B26
B27: =Capacidades!M320 | M27: =B27
A28: =Capacidades!L321 -> UC2C2 Ejecutar cambios permanentes o temporales del cabello según requerimientos del cliente, criterios técnicos, esteticos y de bioseguridad e higiene. | B28: =Capacidades!M321 -> C2I1 Acondiciona su zona de trabajo, herramientas y materiales, teniendo en cuenta los procedimientos técnicos establecidos y según el servicio a realizar. | C28: • Organización del área de trabajo, manejo de presupuestos, control de calidad y bioseguridad • Tecnología de los equipos - tipos- caracteristicas- usos- mantenimiento. | D28: =Organización_Modular!F42 -> ONDULACIÓN Y LACEADO | E28: =Organización_Modular!G42 -> II | F28: =Organización_Modular!H42 -> 2 | G28: =Organización_Modular!I42 -> 4 | H28: =SUM(F28:G28) -> 6 | I28: =F28*16 -> 32 | J28: =G28*32 -> 128 | K28: =SUM(I28:J28) -> 160 | L28: Docente de Educación Técnica con especialidad en en Peluqueria y/o Cosmetología | M28: =B28 -> C2I1 Acondiciona su zona de trabajo, herramientas y materiales, teniendo en cuenta los procedimientos técnicos establecidos y según el servicio a realizar.
B29: =Capacidades!M322 -> C2I2 Identifica las características del cuero cabelludo y la hebra capilar, tomando en cuenta los procedimientos técnicos establecidos, tendencias y criterios estéticos, así como requerimientos del cliente. | C29: • Historia, concepto, característica,Ondulación . • Diagnóstico del cabello, (características, elasticidad, resistencia , porosidad) - Ficha Técnica. | M29: =B29 -> C2I2 Identifica las características del cuero cabelludo y la hebra capilar, tomando en cuenta los procedimientos técnicos establecidos, tendencias y criterios estéticos, así como requerimientos del cliente.
B30: =Capacidades!M323 -> C2I3 Identifica los productos a utilizar teniendo en cuenta los procedimientos técnicos establecidos y según el servicio a realizar. | C30: •Tecnología de los productos cosmético,medidas de seguridad e higiene •Propiedades - Usos- conservaciòn Formula | M30: =B30 -> C2I3 Identifica los productos a utilizar teniendo en cuenta los procedimientos técnicos establecidos y según el servicio a realizar.
B31: =Capacidades!M324 -> C2I4 Realiza la ondulacion del cabello tomando en cuenta tendencias y criterios estéticos, así como las diferentes morfologías y requerimientos del cliente. | C31: Técnicas de enrolle del cabello • Técnicas de ondulacion indirecta - Indirecta | M31: =B31 -> C2I4 Realiza la ondulacion del cabello tomando en cuenta tendencias y criterios estéticos, así como las diferentes morfologías y requerimientos del cliente.
B32: =Capacidades!M325 -> C2I5 Realiza el laceado del cabello tomando en cuenta tendencias y criterios estéticos, así como las diferentes morfologías y requerimientos del cliente. | C32: • Propiedades y uso de productos para el laceado del cabello. Técnicas de laceado -alisado | M32: =B32 -> C2I5 Realiza el laceado del cabello tomando en cuenta tendencias y criterios estéticos, así como las diferentes morfologías y requerimientos del cliente.
B33: =Capacidades!M326 | M33: =B33
B34: =Capacidades!M327 | M34: =B34
B35: =Capacidades!M328 | M35: =B35
B36: =Capacidades!M329 | M36: =B36
B37: =Capacidades!M330 | M37: =B37
A38: =Capacidades!L331 -> UC2C3 Ejecutar cambios en la decoloración y/o coloración del cabello con tecnicas directas e indirectas aplicando criterios técnicos, estéticos y de bioseguridad e higiene.. | B38: =Capacidades!M331 -> C3I1 Acondiciona su zona de trabajo, herramientas y materiales, teniendo en cuenta los procedimientos técnicos establecidos y según el servicio a realizar. | C38: • Organización del área de trabajo, manejo de presupuestos, control de calidad , bioseguridad e higiene. •Herramientas,materiales y productos cosméticos para la coloración y decoloración del cabello. | D38: =Organización_Modular!F43 -> TINTURACIÓN Y DECOLORACION DEL CABELLO | E38: =Organización_Modular!G43 -> II | F38: =Organización_Modular!H43 -> 2 | G38: =Organización_Modular!I43 -> 2 | H38: =SUM(F38:G38) -> 4 | I38: =F38*16 -> 32 | J38: =G38*32 -> 64 | K38: =SUM(I38:J38) -> 96 | M38: =B38 -> C3I1 Acondiciona su zona de trabajo, herramientas y materiales, teniendo en cuenta los procedimientos técnicos establecidos y según el servicio a realizar.
B39: =Capacidades!M332 -> C3I2 Realiza el diagnóstico del cuero cabelludo y la hebra capilar, tomando en cuenta los procedimientos técnicos establecidos, tendencias y criterios estéticos, así como requerimientos del cliente. | C39: • Diagnóstico del cabello,Características , elasticidad, resistencia, y porosidad . • -Prueba de sensibilidad, Prueba de mechón ,ficha diagnostica. | M39: =B39 -> C3I2 Realiza el diagnóstico del cuero cabelludo y la hebra capilar, tomando en cuenta los procedimientos técnicos establecidos, tendencias y criterios estéticos, así como requerimientos del cliente.
