Workbook

Sheet Perfil_Egreso
A1: ANEXO Nº 9 PERFIL DE EGRESO (PARA CICLOS FORMATIVOS: TÉCNICO Y AUXILIAR TÉCNICO)
A3: DENOMINACIÓN DE LA INSTITUCIÓN | B3: CETPRO JUANJUI | D3: CÓDIGO MODULAR DEL CETPRO | E3: 0533836
A5: SECTOR ECONÓMICO | B5: INFORMACIÓN Y COMUNICACIONES | C5: FAMILIA PRODUCTIVA | D5: TECNOLOGÍAS DE LA INFORMACIÓN Y COMUNICACIONES - TICS
A7: ACTIVIDAD ECONÓMICA | B7: PROGRAMACIÓN INFORMÁTICA, CONSULTORÍA DE INFORMÁTICA Y ACTIVIDADES CONEXAS
A9: DENOMINACIÓN VARIANTE
A11: DENOMINACIÓN DEL PROGRAMA DE ESTUDIOS SEGÚN CNOF (según corresponda) | B11: REDES Y COMUNICACIONES | D11: CÓDIGO * | E11: J2662-2-001
A13: FORMACIÓN** | B13: 0 | C13: MODALIDAD DEL SERVICIO EDUCATIVO | D13: PRESENCIAL
A15: NIVEL FORMATIVO | B15: TÉCNICO
A17: DESCRIPCIÓN DEL PERFIL DE EGRESO | F17: Filtrar
A18: El Técnico en redes y comunicaciones, es capaz de atender requerimientos, incidentes y problemas de primer nivel, brindar asistencia a nivel operativo y funcional en la etapa de puesta en marcha de los sistemas o servicios de TI, ejecutar acciones de monitore, y otras acciones operativas programadas; realizar la puesta en producción de los sistemas de información o servicios de TI, de acuerdo con la planificación efectuada e implementar y configurar las redes y servicios de comunicaciones efectuando las pruebas y certificaciones, de acuerdo con las necesidades del negocio, estándares internacionales de TI y políticas de seguridad de la organización. Asimismo, se comunica con otras personas en forma efectiva; busca y analiza información utilizando de manera adecuada las diversas herramientas de las TI; lidera emprendimientos con nuevas oportunidades de negocios y proyectos sostenibles; establece relaciones de respeto y justicia con los demás; soluciona problemas aplicando herramientas flexibles para atender las diversas necesidades y promueve una cultura ambiental en su entorno. | F18: =A18 -> El Técnico en redes y comunicaciones, es capaz de atender requerimientos, incidentes y problemas de primer nivel, brindar asistencia a nivel operativo y funcional en la etapa de puesta en marcha de los sistemas o servicios de TI, ejecutar acciones de monitore, y otras acciones operativas programadas; realizar la puesta en producción de los sistemas de información o servicios de TI, de acuerdo con la planificación efectuada e implementar y configurar las redes y servicios de comunicaciones efectuando las pruebas y certificaciones, de acuerdo con las necesidades del negocio, estándares internacionales de TI y políticas de seguridad de la organización. Asimismo, se comunica con otras personas en forma efectiva; busca y analiza información utilizando de manera adecuada las diversas herramientas de las TI; lidera emprendimientos con nuevas oportunidades de negocios y proyectos sostenibles; establece relaciones de respeto y justicia con los demás; soluciona problemas aplicando herramientas flexibles para atender las diversas necesidades y promueve una cultura ambiental en su entorno.
A19: COMPETENCIAS ESPECÍFICAS (UNIDAD DE COMPETENCIA) | F19: =A19 -> COMPETENCIAS ESPECÍFICAS (UNIDAD DE COMPETENCIA)
A20: UC1:Atender requerimientos, incidentes y problemas de primer nivel, asimismo brindar asistencia a nivel operativo y funcional en la etapa de puesta en marcha de los sistemas o servicios de TI, según los procedimientos internos de atención, diseño del sistema o servicios, plan de implantación y buenas prácticas de TI. | F20: =A20 -> UC1:Atender requerimientos, incidentes y problemas de primer nivel, asimismo brindar asistencia a nivel operativo y funcional en la etapa de puesta en marcha de los sistemas o servicios de TI, según los procedimientos internos de atención, diseño del sistema o servicios, plan de implantación y buenas prácticas de TI.
A21: UC2: Ejecutar acciones de monitoreo y otras acciones operativas programadas, de acuerdo con las buenas prácticas de aseguramiento de operación del CPD y salvaguarda de la información del negocio. | F21: =A21 -> UC2: Ejecutar acciones de monitoreo y otras acciones operativas programadas, de acuerdo con las buenas prácticas de aseguramiento de operación del CPD y salvaguarda de la información del negocio.
A22: UC3: Realizar la puesta en producción de los sistemas de información o servicios de TI, de acuerdo con la planificación efectuada. | F22: =A22 -> UC3: Realizar la puesta en producción de los sistemas de información o servicios de TI, de acuerdo con la planificación efectuada.
A23: UC4: Implementar y configurar las redes y servicios de comunicaciones efectuando las pruebas y certificaciones, de acuerdo con las necesidades del negocio, estándares internacionales de TI y políticas de seguridad de la organización. | F23: =A23 -> UC4: Implementar y configurar las redes y servicios de comunicaciones efectuando las pruebas y certificaciones, de acuerdo con las necesidades del negocio, estándares internacionales de TI y políticas de seguridad de la organización.
F24: =A24 -> 0
F25: =A25 -> 0
F26: =A26 -> 0
F27: =A27 -> 0
A28: COMPETENCIAS PARA LA EMPLEABILIDAD | F28: =A28 -> COMPETENCIAS PARA LA EMPLEABILIDAD
A29: CE1 Comunicación efectiva.- Expresar de manera clara los conceptos, ideas, sentimientos, hechos y opiniones en forma oral y escrita para comunicarse e interactuar con otras personas en contextos sociales y laborales diversos. (UD) | F29: =A29 -> CE1 Comunicación efectiva.- Expresar de manera clara los conceptos, ideas, sentimientos, hechos y opiniones en forma oral y escrita para comunicarse e interactuar con otras personas en contextos sociales y laborales diversos. (UD)
A30: CE2 Tecnologías de la información.- Manejar herramientas informáticas de las TIC para buscar y analizar información, comunicarse y realizar procedimientos o tareas vinculadas al área profesional, de acuerdo a los requerimientos de su entorno laboral.(UD) | F30: =A30 -> CE2 Tecnologías de la información.- Manejar herramientas informáticas de las TIC para buscar y analizar información, comunicarse y realizar procedimientos o tareas vinculadas al área profesional, de acuerdo a los requerimientos de su entorno laboral.(UD)
A31: CE3 Emprendimiento.- Identificar nuevas oportunidades de proyectos o negocios que generen valor y sean sostenibles, gestionando recursos para su funcionamiento con creatividad y ética, articulando acciones que permitan desarrollar innovaciones en la creación de bienes y/o servicios, así como en procesos o productos ya existentes. (UD) | F31: =A31 -> CE3 Emprendimiento.- Identificar nuevas oportunidades de proyectos o negocios que generen valor y sean sostenibles, gestionando recursos para su funcionamiento con creatividad y ética, articulando acciones que permitan desarrollar innovaciones en la creación de bienes y/o servicios, así como en procesos o productos ya existentes. (UD)
A32: CE4 Ética.- Establecer relaciones con respeto y justicia en los ámbitos personal, colectivo e institucional, contribuyendo a una convivencia democrática, orientada al bien común que considere la diversidad y dignidad de las personas, teniendo en cuenta las consideraciones aplicadas en su contexto laboral.(UD) | F32: =A32 -> CE4 Ética.- Establecer relaciones con respeto y justicia en los ámbitos personal, colectivo e institucional, contribuyendo a una convivencia democrática, orientada al bien común que considere la diversidad y dignidad de las personas, teniendo en cuenta las consideraciones aplicadas en su contexto laboral.(UD)
A33: CE5 Solución de problemas.- Identificar situaciones complejas para evaluar posibles soluciones, aplicando un conjunto de herramientas flexibles que conlleven a la atención de una necesidad.(UD) | F33: =A33 -> CE5 Solución de problemas.- Identificar situaciones complejas para evaluar posibles soluciones, aplicando un conjunto de herramientas flexibles que conlleven a la atención de una necesidad.(UD)
A34: CE6 Liderazgo personal y profesional. - Demostrar comportamiento de liderazgo que permita coordinar y organizar eficazmente las ideas, decisiones y actividades en el desempeño laboral y social. (T) | F34: =A34 -> CE6 Liderazgo personal y profesional. - Demostrar comportamiento de liderazgo que permita coordinar y organizar eficazmente las ideas, decisiones y actividades en el desempeño laboral y social. (T)
A35: CE7 Cultura ambiental. - Convivir de manera ética, autónoma, responsable y sostenible, previniendo, reduciendo y controlando permanente y progresivamente los impactos ambientales. (T) | F35: =A35 -> CE7 Cultura ambiental. - Convivir de manera ética, autónoma, responsable y sostenible, previniendo, reduciendo y controlando permanente y progresivamente los impactos ambientales. (T)
F36: =A36 -> 0
F37: =A37 -> 0
F38: =A38 -> 0
F39: =A39 -> 0
F40: =A40 -> 0
A41: ÁMBITOS DE DESEMPEÑO | F41: =A41 -> ÁMBITOS DE DESEMPEÑO
A42: El egresado de este programa podrá desempeñarse en las siguientes áreas: • Informática, tecnologías de la información y sistemas de cualquier organización. • Desarrollo de infraestructura tecnológica de redes, servidores y comunicaciones. • Cableado, estructurado en fibra y cobre. • Mantenimiento de redes de comunicaciones y redes fijas ADSL. • Instalación y Manteminiento de Redes Wi Fi. • Soporte tecnico de computadoras • Administración de servicios de TI • Implementación y monitoreo de sistemas de redes ó en consultoras especializadas en desarrollo de infraestructura tecnológica de redes, servidores y comunicaciones. | F42: =A42 -> El egresado de este programa podrá desempeñarse en las siguientes áreas: • Informática, tecnologías de la información y sistemas de cualquier organización. • Desarrollo de infraestructura tecnológica de redes, servidores y comunicaciones. • Cableado, estructurado en fibra y cobre. • Mantenimiento de redes de comunicaciones y redes fijas ADSL. • Instalación y Manteminiento de Redes Wi Fi. • Soporte tecnico de computadoras • Administración de servicios de TI • Implementación y monitoreo de sistemas de redes ó en consultoras especializadas en desarrollo de infraestructura tecnológica de redes, servidores y comunicaciones.
A43: Pautas Generales: 1. Descripción del perfil de egreso: Descripción general y breve de los desempeños que será capaz de realizar el egresado en el campo laboral, al concluir el programa de estudio en correspondencia con las competencias técnicas y de empleabilidad. 2. Competencias específicas: Transcripción de las unidades de competencia del programa de estudio, establecido en el CNOF. En caso de que el programa no se encuentre en el CNOF se tomarán las Unidades de Competencias definidas mediante el análisis de la actividad económica correspondiente. 3. Las competencias para la empleabilidad: son priorizadas por la institución educativa, en concordancia con los Lineamientos Académicos Generales establecidos por el MINEDU y su modelo educativo. Se debe distinguir los que se abordarán como unidad didáctica (UD), de manera transversal (T) o ambas (UD/T) 4. Ámbitos de desempeño: Listar los campos o áreas laborales en los cuales el egresado del programa de estudio se podrá insertar. *Se considera el código del programa de estudios del CNOF, de ser el caso. ** Indicar sólo en el caso de que sea Dual o En Alternancia, caso contrario dejar la celda en blanco. | F43: =A43 -> Pautas Generales: 1. Descripción del perfil de egreso: Descripción general y breve de los desempeños que será capaz de realizar el egresado en el campo laboral, al concluir el programa de estudio en correspondencia con las competencias técnicas y de empleabilidad. 2. Competencias específicas: Transcripción de las unidades de competencia del programa de estudio, establecido en el CNOF. En caso de que el programa no se encuentre en el CNOF se tomarán las Unidades de Competencias definidas mediante el análisis de la actividad económica correspondiente. 3. Las competencias para la empleabilidad: son priorizadas por la institución educativa, en concordancia con los Lineamientos Académicos Generales establecidos por el MINEDU y su modelo educativo. Se debe distinguir los que se abordarán como unidad didáctica (UD), de manera transversal (T) o ambas (UD/T) 4. Ámbitos de desempeño: Listar los campos o áreas laborales en los cuales el egresado del programa de estudio se podrá insertar. *Se considera el código del programa de estudios del CNOF, de ser el caso. ** Indicar sólo en el caso de que sea Dual o En Alternancia, caso contrario dejar la celda en blanco.

Sheet Programa_Estudio
A1: ANEXO Nº 8 PROGRAMA DE ESTUDIO (PARA CICLOS FORMATIVOS: TÉCNICO Y AUXILIAR TÉCNICO)
A3: =Perfil_Egreso!A3 -> DENOMINACIÓN DE LA INSTITUCIÓN | B3: =Perfil_Egreso!B3 -> CETPRO JUANJUI | D3: =Perfil_Egreso!D3 -> CÓDIGO MODULAR DEL CETPRO | E3: =Perfil_Egreso!E3 -> 0533836
A5: SECTOR ECONÓMICO | B5: =Perfil_Egreso!B5 -> INFORMACIÓN Y COMUNICACIONES | C5: FAMILIA PRODUCTIVA | D5: =Perfil_Egreso!D5 -> TECNOLOGÍAS DE LA INFORMACIÓN Y COMUNICACIONES - TICS | E5: ACTIVIDAD ECONÓMICA | F5: =Perfil_Egreso!B7 -> PROGRAMACIÓN INFORMÁTICA, CONSULTORÍA DE INFORMÁTICA Y ACTIVIDADES CONEXAS
A7: DENOMINACIÓN | B7: =Perfil_Egreso!B9 -> 0 | C7: DENOMINACIÓN DEL PROGRAMA DE ESTUDIOS SEGÚN CNOF (según corresponda) | D7: =Perfil_Egreso!B11 -> REDES Y COMUNICACIONES | E7: CÓDIGO DE SER EL CASO * | F7: =Perfil_Egreso!E11 -> J2662-2-001
A9: NIVEL FORMATIVO | B9: =Perfil_Egreso!B15 -> TÉCNICO | C9: N°. HORAS: | D9: =Itinerario!W17 -> 2112 | E9: N° CRÉDITOS: | F9: =Itinerario!T17 -> 80
A11: FORMACIÓN** | B11: =Perfil_Egreso!B13 -> 0 | D11: MODALIDAD DEL SERVICIO EDUCATIVO | E11: =Perfil_Egreso!D13 -> PRESENCIAL
A13: COMPETENCIAS ESPECÍFICAS (UNIDAD DE COMPETENCIA)
A14: UNIDAD DE COMPETENCIA | C14: INDICADORES DE LOGRO DE LA COMPETENCIA | G14: Filtro
A15: =CONCATENATE("Unidad de Competencia N° 01 (UC1): ",Perfil_Egreso!A20) -> Unidad de Competencia N° 01 (UC1): UC1:Atender requerimientos, incidentes y problemas de primer nivel, asimismo brindar asistencia a nivel operativo y funcional en la etapa de puesta en marcha de los sistemas o servicios de TI, según los procedimientos internos de atención, diseño del sistema o servicios, plan de implantación y buenas prácticas de TI. | C15: 1. Interactúa con el usuario escuchando e interpretando los reportes de incidentes ante un mal funcionamiento del sistema en producción o puesta en marcha, aislando la causa de los efectos, reportando de ser necesario a un siguiente nivel de atención, según las funciones y alcance de los sistemas comprometidos, buenas prácticas de gestión de incidentes, acuerdos de nivel de servicio (SLA), continuidad de negocio y políticas de la organización. | G15: =C15 -> 1. Interactúa con el usuario escuchando e interpretando los reportes de incidentes ante un mal funcionamiento del sistema en producción o puesta en marcha, aislando la causa de los efectos, reportando de ser necesario a un siguiente nivel de atención, según las funciones y alcance de los sistemas comprometidos, buenas prácticas de gestión de incidentes, acuerdos de nivel de servicio (SLA), continuidad de negocio y políticas de la organización. | H15: 1 | I15: =CONCATENATE(H15,". ",C15) -> 1. 1. Interactúa con el usuario escuchando e interpretando los reportes de incidentes ante un mal funcionamiento del sistema en producción o puesta en marcha, aislando la causa de los efectos, reportando de ser necesario a un siguiente nivel de atención, según las funciones y alcance de los sistemas comprometidos, buenas prácticas de gestión de incidentes, acuerdos de nivel de servicio (SLA), continuidad de negocio y políticas de la organización.
C16: 2. Atiende requerimientos, accesos y otras solicitudes, reportando de ser necesario a un siguiente nivel de atención, de acuerdo con la documentación de sistemas y servicios, recomendación del fabricante, buenas prácticas de gestión de incidentes, acuerdos de nivel de servicio (SLA), continuidad de negocio y políticas de la organización. | G16: =C16 -> 2. Atiende requerimientos, accesos y otras solicitudes, reportando de ser necesario a un siguiente nivel de atención, de acuerdo con la documentación de sistemas y servicios, recomendación del fabricante, buenas prácticas de gestión de incidentes, acuerdos de nivel de servicio (SLA), continuidad de negocio y políticas de la organización. | H16: 2 | I16: =CONCATENATE(H16,". ",C16) -> 2. 2. Atiende requerimientos, accesos y otras solicitudes, reportando de ser necesario a un siguiente nivel de atención, de acuerdo con la documentación de sistemas y servicios, recomendación del fabricante, buenas prácticas de gestión de incidentes, acuerdos de nivel de servicio (SLA), continuidad de negocio y políticas de la organización.
C17: 3. Capacita al grupo de usuarios en el uso de los sistemas mediante técnicas didácticas y transferencia de conocimiento, interpretando los manuales de usuario y realizando talleres prácticos, de acuerdo con el perfil de usuario y accesos del operador, según su participación en el sistema. | G17: =C17 -> 3. Capacita al grupo de usuarios en el uso de los sistemas mediante técnicas didácticas y transferencia de conocimiento, interpretando los manuales de usuario y realizando talleres prácticos, de acuerdo con el perfil de usuario y accesos del operador, según su participación en el sistema. | H17: 3 | I17: =CONCATENATE(H17,". ",C17) -> 3. 3. Capacita al grupo de usuarios en el uso de los sistemas mediante técnicas didácticas y transferencia de conocimiento, interpretando los manuales de usuario y realizando talleres prácticos, de acuerdo con el perfil de usuario y accesos del operador, según su participación en el sistema.
C18: 4. Asiste a los usuarios en el uso del sistema, de acuerdo con el diseño funcional del sistema y buenas prácticas de entrega de servicio. | G18: =C18 -> 4. Asiste a los usuarios en el uso del sistema, de acuerdo con el diseño funcional del sistema y buenas prácticas de entrega de servicio. | H18: 4 | I18: =CONCATENATE(H18,". ",C18) -> 4. 4. Asiste a los usuarios en el uso del sistema, de acuerdo con el diseño funcional del sistema y buenas prácticas de entrega de servicio.
C19: 5. Interactúa con el operador de gestión de incidentes y usuarios escuchando e interpretando los reportes y aislando la causa de los efectos del problema de primer nivel, de acuerdo con las funciones y alcance de los sistemas comprometidos, buenas prácticas de gestión de problemas, acuerdos de nivel de servicio (SLA), continuidad de negocio y políticas de la organización. | G19: =C19 -> 5. Interactúa con el operador de gestión de incidentes y usuarios escuchando e interpretando los reportes y aislando la causa de los efectos del problema de primer nivel, de acuerdo con las funciones y alcance de los sistemas comprometidos, buenas prácticas de gestión de problemas, acuerdos de nivel de servicio (SLA), continuidad de negocio y políticas de la organización. | H19: 5 | I19: =CONCATENATE(H19,". ",C19) -> 5. 5. Interactúa con el operador de gestión de incidentes y usuarios escuchando e interpretando los reportes y aislando la causa de los efectos del problema de primer nivel, de acuerdo con las funciones y alcance de los sistemas comprometidos, buenas prácticas de gestión de problemas, acuerdos de nivel de servicio (SLA), continuidad de negocio y políticas de la organización.
C20: 6. Ejecuta acciones de resolución de problemas de primer nivel, eliminando la causa del incidente o reportando de ser necesario a un siguiente nivel de atención, de acuerdo con la documentación del sistema, servicios, recomendación del fabricante, buenas prácticas de gestión de problemas, acuerdos de nivel de servicio (SLA), continuidad de negocio y políticas de la organización. | G20: =C20 -> 6. Ejecuta acciones de resolución de problemas de primer nivel, eliminando la causa del incidente o reportando de ser necesario a un siguiente nivel de atención, de acuerdo con la documentación del sistema, servicios, recomendación del fabricante, buenas prácticas de gestión de problemas, acuerdos de nivel de servicio (SLA), continuidad de negocio y políticas de la organización. | H20: 6 | I20: =CONCATENATE(H20,". ",C20) -> 6. 6. Ejecuta acciones de resolución de problemas de primer nivel, eliminando la causa del incidente o reportando de ser necesario a un siguiente nivel de atención, de acuerdo con la documentación del sistema, servicios, recomendación del fabricante, buenas prácticas de gestión de problemas, acuerdos de nivel de servicio (SLA), continuidad de negocio y políticas de la organización.
C21: 7. Documenta las acciones de gestión de incidentes, problemas y lecciones aprendidas para el seguimiento de atenciones o gestión del conocimiento según corresponda, generando reporte de cumplimiento de acuerdos de nivel de servicio (SLA) y calidad del servicio, de acuerdo con las buenas prácticas de gestión de incidentes, problemas, gestión de la configuración, gestión del conocimiento y políticas de la organización. | G21: =C21 -> 7. Documenta las acciones de gestión de incidentes, problemas y lecciones aprendidas para el seguimiento de atenciones o gestión del conocimiento según corresponda, generando reporte de cumplimiento de acuerdos de nivel de servicio (SLA) y calidad del servicio, de acuerdo con las buenas prácticas de gestión de incidentes, problemas, gestión de la configuración, gestión del conocimiento y políticas de la organización. | H21: 7 | I21: =CONCATENATE(H21,". ",C21) -> 7. 7. Documenta las acciones de gestión de incidentes, problemas y lecciones aprendidas para el seguimiento de atenciones o gestión del conocimiento según corresponda, generando reporte de cumplimiento de acuerdos de nivel de servicio (SLA) y calidad del servicio, de acuerdo con las buenas prácticas de gestión de incidentes, problemas, gestión de la configuración, gestión del conocimiento y políticas de la organización.
G22: =C22 -> 0 | H22: 8 | I22: =CONCATENATE(H22,". ",C22) -> 8.
G23: =C23 -> 0 | H23: 9 | I23: =CONCATENATE(H23,". ",C23) -> 9.
G24: =C24 -> 0 | H24: 10 | I24: =CONCATENATE(H24,". ",C24) -> 10.
G25: =C25 -> 0 | H25: 11 | I25: =CONCATENATE(H25,". ",C25) -> 11.
G26: =C26 -> 0 | H26: 12 | I26: =CONCATENATE(H26,". ",C26) -> 12.
G27: =C27 -> 0 | H27: 13 | I27: =CONCATENATE(H27,". ",C27) -> 13.
G28: =C28 -> 0 | H28: 14 | I28: =CONCATENATE(H28,". ",C28) -> 14.
G29: =C29 -> 0 | H29: 15 | I29: =CONCATENATE(H29,". ",C29) -> 15.
A30: =CONCATENATE("Unidad de Competencia N° 02 (UC2): ",Perfil_Egreso!A21) -> Unidad de Competencia N° 02 (UC2): UC2: Ejecutar acciones de monitoreo y otras acciones operativas programadas, de acuerdo con las buenas prácticas de aseguramiento de operación del CPD y salvaguarda de la información del negocio. | C30: 1. Realiza las lecturas de rendimiento y eventos de la infraestructura, plataformas y servicios de TI y la organiza, consolida, indaga e interpreta los resultados para ser reportados de manera periódica o de grado urgencia al administrador del CPD, de acuerdo con los umbrales de operación y de riesgos, arquitectura de infraestructura de TI, continuidad de negocio, políticas de seguridad y políticas de la organización. | G30: =C30 -> 1. Realiza las lecturas de rendimiento y eventos de la infraestructura, plataformas y servicios de TI y la organiza, consolida, indaga e interpreta los resultados para ser reportados de manera periódica o de grado urgencia al administrador del CPD, de acuerdo con los umbrales de operación y de riesgos, arquitectura de infraestructura de TI, continuidad de negocio, políticas de seguridad y políticas de la organización. | H30: 1 | I30: =CONCATENATE(H30,". ",C30) -> 1. 1. Realiza las lecturas de rendimiento y eventos de la infraestructura, plataformas y servicios de TI y la organiza, consolida, indaga e interpreta los resultados para ser reportados de manera periódica o de grado urgencia al administrador del CPD, de acuerdo con los umbrales de operación y de riesgos, arquitectura de infraestructura de TI, continuidad de negocio, políticas de seguridad y políticas de la organización.
C31: 2. Elabora reportes de cumplimiento de niveles de operación, según los acuerdos de nivel de operación, unidades de contratos con proveedores, continuidad del negocio y políticas de la organización. | G31: =C31 -> 2. Elabora reportes de cumplimiento de niveles de operación, según los acuerdos de nivel de operación, unidades de contratos con proveedores, continuidad del negocio y políticas de la organización. | H31: 2 | I31: =CONCATENATE(H31,". ",C31) -> 2. 2. Elabora reportes de cumplimiento de niveles de operación, según los acuerdos de nivel de operación, unidades de contratos con proveedores, continuidad del negocio y políticas de la organización.
C32: 3. Ejecuta acciones de operación, mantenimiento preventivo y correctivo de rutina, de acuerdo al cumplimiento del buen estado de la infraestructura, plataformas y servicios de TI y salvaguarda de la información, plan de actividades programadas, recomendaciones del fabricante, gestión de riesgos, continuidad de negocio y políticas de seguridad. | G32: =C32 -> 3. Ejecuta acciones de operación, mantenimiento preventivo y correctivo de rutina, de acuerdo al cumplimiento del buen estado de la infraestructura, plataformas y servicios de TI y salvaguarda de la información, plan de actividades programadas, recomendaciones del fabricante, gestión de riesgos, continuidad de negocio y políticas de seguridad. | H32: 3 | I32: =CONCATENATE(H32,". ",C32) -> 3. 3. Ejecuta acciones de operación, mantenimiento preventivo y correctivo de rutina, de acuerdo al cumplimiento del buen estado de la infraestructura, plataformas y servicios de TI y salvaguarda de la información, plan de actividades programadas, recomendaciones del fabricante, gestión de riesgos, continuidad de negocio y políticas de seguridad.
C33: 4. Reporta las acciones ejecutadas y los eventos inesperados de manera programada o de grado urgencia, de acuerdo con el plan de actividades programadas, gestión de riesgos, continuidad de negocio y políticas de seguridad. | G33: =C33 -> 4. Reporta las acciones ejecutadas y los eventos inesperados de manera programada o de grado urgencia, de acuerdo con el plan de actividades programadas, gestión de riesgos, continuidad de negocio y políticas de seguridad. | H33: 4 | I33: =CONCATENATE(H33,". ",C33) -> 4. 4. Reporta las acciones ejecutadas y los eventos inesperados de manera programada o de grado urgencia, de acuerdo con el plan de actividades programadas, gestión de riesgos, continuidad de negocio y políticas de seguridad.
G34: =C34 -> 0 | H34: 5 | I34: =CONCATENATE(H34,". ",C34) -> 5.
G35: =C35 -> 0 | H35: 6 | I35: =CONCATENATE(H35,". ",C35) -> 6.
G36: =C36 -> 0 | H36: 7 | I36: =CONCATENATE(H36,". ",C36) -> 7.
G37: =C37 -> 0 | H37: 8 | I37: =CONCATENATE(H37,". ",C37) -> 8.
G38: =C38 -> 0 | H38: 9 | I38: =CONCATENATE(H38,". ",C38) -> 9.
G39: =C39 -> 0 | H39: 10 | I39: =CONCATENATE(H39,". ",C39) -> 10.
G40: =C40 -> 0 | H40: 11 | I40: =CONCATENATE(H40,". ",C40) -> 11.
G41: =C41 -> 0 | H41: 12 | I41: =CONCATENATE(H41,". ",C41) -> 12.
G42: =C42 -> 0 | H42: 13 | I42: =CONCATENATE(H42,". ",C42) -> 13.
G43: =C43 -> 0 | H43: 14 | I43: =CONCATENATE(H43,". ",C43) -> 14.
G44: =C44 -> 0 | H44: 15 | I44: =CONCATENATE(H44,". ",C44) -> 15.
A45: =CONCATENATE("Unidad de Competencia N° 03 (UC3): ",Perfil_Egreso!A22) -> Unidad de Competencia N° 03 (UC3): UC3: Realizar la puesta en producción de los sistemas de información o servicios de TI, de acuerdo con la planificación efectuada. | C45: 1. Instala y/o despliega los componentes del sistema en el ambiente de producción de acuerdo con la arquitectura del sistema o servicio de TI, recomendaciones del fabricante y plan de implementación. | G45: =C45 -> 1. Instala y/o despliega los componentes del sistema en el ambiente de producción de acuerdo con la arquitectura del sistema o servicio de TI, recomendaciones del fabricante y plan de implementación. | H45: 1 | I45: =CONCATENATE(H45,". ",C45) -> 1. 1. Instala y/o despliega los componentes del sistema en el ambiente de producción de acuerdo con la arquitectura del sistema o servicio de TI, recomendaciones del fabricante y plan de implementación.
C46: 2. Desarrolla el plan de pruebas unitarias de cada arreglo y componente informático por separado y de manera conjunta, según el alcance de la función que se le ha asignado en el proceso de implantación. | G46: =C46 -> 2. Desarrolla el plan de pruebas unitarias de cada arreglo y componente informático por separado y de manera conjunta, según el alcance de la función que se le ha asignado en el proceso de implantación. | H46: 2 | I46: =CONCATENATE(H46,". ",C46) -> 2. 2. Desarrolla el plan de pruebas unitarias de cada arreglo y componente informático por separado y de manera conjunta, según el alcance de la función que se le ha asignado en el proceso de implantación.
...

Sheet Capacidades
C1: FORMATO DE PROCESO - FORMULACIÓN DE CAPACIDADES E INDICADORES POR UNIDAD DE COMPETENCIA
C5: Programa de estudios: | E5: =Perfil_Egreso!B11 -> REDES Y COMUNICACIONES | L5: RESUMEN
D7: Capacidades asociadas a la Unidad de Competencia Específica y de Empleabilidad | H7: Indicadores de la Capacidad
A9: MÓDULOS | B9: Tipo de capacidad | C9: Código Capacidad | D9: Verbo | E9: Objeto | F9: Condición | G9: Código Indicador | H9: Verbo | I9: Objeto | J9: Condición | K9: Observaciones de los facilitadores opcional | L9: Capacidades | M9: Indicadores
A10: Módulo I | B10: Capacidad técnica | C10: UC1 C1 | D10: Identificar | E10: las necesidades o requerimientos del cliente | F10: considerando procedimientos establecidos y buenas prácticas de gestión de incidentes. | G10: C1 I1 | H10: Interpreta | I10: los reportes del funcionamiento del sistema de información en producción o puesta en marcha | J10: según las funciones y alcance de los sistemas. | L10: =CONCATENATE(C10," ",D10," ",E10," ",F10," ",C11," ",D11," ",E11," ",F11) -> UC1 C1 Identificar las necesidades o requerimientos del cliente considerando procedimientos establecidos y buenas prácticas de gestión de incidentes. | M10: =CONCATENATE(G10," ",H10," ",I10," ",J10) -> C1 I1 Interpreta los reportes del funcionamiento del sistema de información en producción o puesta en marcha según las funciones y alcance de los sistemas.
G11: C1 I2 | H11: Detecta | I11: las fallas e incidencias del sistema de información en producción o puesta en marcha | J11: considerando procedimientos establecidos y buenas prácticas de gestión de incidentes. | M11: =CONCATENATE(G11," ",H11," ",I11," ",J11) -> C1 I2 Detecta las fallas e incidencias del sistema de información en producción o puesta en marcha considerando procedimientos establecidos y buenas prácticas de gestión de incidentes.
G12: C1 I3 | H12: Clasifica | I12: las fallas e incidencias del sistema de información en producción o puesta en marcha | J12: considerando procedimientos establecidos y buenas prácticas de gestión de incidentes. | M12: =CONCATENATE(G12," ",H12," ",I12," ",J12) -> C1 I3 Clasifica las fallas e incidencias del sistema de información en producción o puesta en marcha considerando procedimientos establecidos y buenas prácticas de gestión de incidentes.
M13: =CONCATENATE(G13," ",H13," ",I13," ",J13)
M14: =CONCATENATE(G14," ",H14," ",I14," ",J14)
M15: =CONCATENATE(G15," ",H15," ",I15," ",J15)
M16: =CONCATENATE(G16," ",H16," ",I16," ",J16)
M17: =CONCATENATE(G17," ",H17," ",I17," ",J17)
M18: =CONCATENATE(G18," ",H18," ",I18," ",J18)
M19: =CONCATENATE(G19," ",H19," ",I19," ",J19)
A20: Módulo I | B20: Capacidad técnica | C20: UC1 C2 | D20: Resolver | E20: las incidencias o fallas del sistema de información en el primer nivel | F20: considerando procedimientos establecidos y buenas prácticas de gestión de TI (marco metodologias COBIT y ITIL) | G20: C2 I1 | H20: Analiza | I20: las incidencias o fallas del sistema de información en el primer nivel | J20: considerando procedimientos establecidos y buenas prácticas de gestión de TI (marco metodologias COBIT y ITIL) | L20: =CONCATENATE(C20," ",D20," ",E20," ",F20," ",C21," ",D21," ",E21," ",F21) -> UC1 C2 Resolver las incidencias o fallas del sistema de información en el primer nivel considerando procedimientos establecidos y buenas prácticas de gestión de TI (marco metodologias COBIT y ITIL) | M20: =CONCATENATE(G20," ",H20," ",I20," ",J20) -> C2 I1 Analiza las incidencias o fallas del sistema de información en el primer nivel considerando procedimientos establecidos y buenas prácticas de gestión de TI (marco metodologias COBIT y ITIL)
G21: C2 I2 | H21: Plantea | I21: estrategias de solución | J21: teniendo en cuenta las incidencia o falla del sistema de información, los procedimiento establecidos y buenas prácticas de gestión de TI | M21: =CONCATENATE(G21," ",H21," ",I21," ",J21) -> C2 I2 Plantea estrategias de solución teniendo en cuenta las incidencia o falla del sistema de información, los procedimiento establecidos y buenas prácticas de gestión de TI
G22: C2 I3 | H22: Determina | I22: la estrategia de solución | J22: teniendo en cuenta las incidencia o falla del sistema de información, los procedimiento establecidos y buenas prácticas de gestión de TI | M22: =CONCATENATE(G22," ",H22," ",I22," ",J22) -> C2 I3 Determina la estrategia de solución teniendo en cuenta las incidencia o falla del sistema de información, los procedimiento establecidos y buenas prácticas de gestión de TI
G23: C2 I4 | H23: Aplica | I23: estrategia de solución | J23: siguiendo los procedimiento establecidos y buenas prácticas de gestión de TI | M23: =CONCATENATE(G23," ",H23," ",I23," ",J23) -> C2 I4 Aplica estrategia de solución siguiendo los procedimiento establecidos y buenas prácticas de gestión de TI
G24: C2 I5 | H24: Comprueba | I24: el funcionamiento del sistema de información | J24: considerando los estándares de calidad establecidos. | M24: =CONCATENATE(G24," ",H24," ",I24," ",J24) -> C2 I5 Comprueba el funcionamiento del sistema de información considerando los estándares de calidad establecidos.
M25: =CONCATENATE(G25," ",H26," ",I26," ",J25)
M28: =CONCATENATE(G28," ",H28," ",I28," ",J28)
M29: =CONCATENATE(G29," ",H29," ",I29," ",J29)
A30: Módulo I | B30: Capacidad técnica | C30: UC1 C3 | D30: Elaborar | E30: los reportes de las incidencia de los sistemas de información | F30: considerando procedimientos establecidos y buenas prácticas de gestión de TI (marco metodologias COBIT y ITIL) | G30: C2 I1 | H30: Identifica | I30: los incidentes o requerimientos de los usuarios atendidos | J30: aplicando los procedimientos establecidos según la política de la organización. | L30: =CONCATENATE(C30," ",D30," ",E30," ",F30," ",C31," ",D31," ",E31," ",F31) -> UC1 C3 Elaborar los reportes de las incidencia de los sistemas de información considerando procedimientos establecidos y buenas prácticas de gestión de TI (marco metodologias COBIT y ITIL) | M30: =CONCATENATE(G30," ",H30," ",I30," ",J30) -> C2 I1 Identifica los incidentes o requerimientos de los usuarios atendidos aplicando los procedimientos establecidos según la política de la organización.
G31: C2 I2 | H31: Señala | I31: las lecciones aprendidas | J31: considerando procedimientos establecidos y buenas practicas de gestión de TI. | M31: =CONCATENATE(G31," ",H31," ",I31," ",J31) -> C2 I2 Señala las lecciones aprendidas considerando procedimientos establecidos y buenas practicas de gestión de TI.
G32: C2 I3 | H32: Clasifica | I32: los incidentes o requerimientos de los usuarios atendidos en una BD o repositorio | J32: considerando procedimientos establecidos y buenas practicas de gestión de TI. | M32: =CONCATENATE(G32," ",H32," ",I32," ",J32) -> C2 I3 Clasifica los incidentes o requerimientos de los usuarios atendidos en una BD o repositorio considerando procedimientos establecidos y buenas practicas de gestión de TI.
G33: C2 I4 | H33: Documenta | I33: las acciones de gestión de inicdenicias y/o requerimientos | J33: generando reportes de cumplimiento, de acuerdo a los niveles de servicio TI. | M33: =CONCATENATE(G33," ",H33," ",I33," ",J33) -> C2 I4 Documenta las acciones de gestión de inicdenicias y/o requerimientos generando reportes de cumplimiento, de acuerdo a los niveles de servicio TI.
G34: C2 I5 | H34: Realiza | I34: copias de seguridad | J34: según los procedimientos establecidos. | M34: =CONCATENATE(G34," ",H34," ",I34," ",J34) -> C2 I5 Realiza copias de seguridad según los procedimientos establecidos.
M35: =CONCATENATE(G35," ",H35," ",I35," ",J35)
M36: =CONCATENATE(G36," ",H36," ",I36," ",J36)
M37: =CONCATENATE(G37," ",H37," ",I37," ",J37)
M38: =CONCATENATE(G38," ",H38," ",I38," ",J38)
M39: =CONCATENATE(G39," ",H39," ",I39," ",J39)
A40: Módulo I | B40: Capacidad técnica | L40: =CONCATENATE(C40," ",D40," ",E40," ",F40," ",C41," ",D41," ",E41," ",F41) | M40: =CONCATENATE(G40," ",H40," ",I40," ",J40)
M41: =CONCATENATE(G41," ",H41," ",I41," ",J41)
M42: =CONCATENATE(G42," ",H42," ",I42," ",J42)
M43: =CONCATENATE(G43," ",H43," ",I43," ",J43)
M44: =CONCATENATE(G44," ",H44," ",I44," ",J44)
M45: =CONCATENATE(G45," ",H45," ",I45," ",J45)
M46: =CONCATENATE(G46," ",H46," ",I46," ",J46)
M47: =CONCATENATE(G47," ",H47," ",I47," ",J47)
...

Sheet Organización_Modular
A1: ORGANIZACIÓN MODULAR
A3: DENOMINACIÓN DE LA INSTITUCIÓN | C3: =Perfil_Egreso!B3 -> CETPRO JUANJUI | F3: CÓDIGO MODULAR | G3: =Perfil_Egreso!E3 -> 0533836
A5: =Perfil_Egreso!A11 -> DENOMINACIÓN DEL PROGRAMA DE ESTUDIOS SEGÚN CNOF (según corresponda) | C5: =Perfil_Egreso!B11 -> REDES Y COMUNICACIONES | D5: CÓDIGO * | E5: =Perfil_Egreso!E11 -> J2662-2-001 | F5: NIVEL FORMATIVO | G5: =Perfil_Egreso!B15 -> TÉCNICO
A7: =Perfil_Egreso!A13 -> FORMACIÓN** | C7: =Perfil_Egreso!B13 -> 0 | E7: MODALIDAD DEL SERVICIO EDUCATIVO | F7: =Perfil_Egreso!D13 -> PRESENCIAL
H8: Información solo de proceso
A9: MÓDULO | B9: DESCRIPCIÓN DE LA COMPETENCIA | D9: CAPACIDADES | F9: UNIDAD DIDÁCTICA | G9: PERIODO ACADÉMICO | H9: Crédito teórico | I9: Crédito práctico | J9: T.créditos (Filtrar)
A10: MÓDULO 1: GESTION DE SERVICIOS TECNOLOGICOS | B10: Competencias técnicas (Unidad de competencia) | C10: UC1: Atender requerimientos, incidentes y problemas de primer nivel, asimismo brindar asistencia a nivel operativo y funcional en la etapa de puesta en marcha de los sistemas o servicios de TI, según los procedimientos internos de atención, diseño del sistema o servicios, plan de implantación y buenas prácticas. | D10: =OFFSET(Capacidades!$A$1,(ROW()-9)*10-1,11) -> UC1 C1 Identificar las necesidades o requerimientos del cliente considerando procedimientos establecidos y buenas prácticas de gestión de incidentes. | F10: Análisis de requerimientos de Tecnología de la Información. | G10: I | H10: 2 | I10: 3 | J10: =SUM(H10:I10) -> 5
D11: =OFFSET(Capacidades!$A$1,(ROW()-9)*10-1,11) -> UC1 C2 Resolver las incidencias o fallas del sistema de información en el primer nivel considerando procedimientos establecidos y buenas prácticas de gestión de TI (marco metodologias COBIT y ITIL) | F11: Atención de incidencias del sistema de infomación | G11: I | H11: 2 | I11: 3 | J11: =SUM(H11:I11) -> 5
D12: =OFFSET(Capacidades!$A$1,(ROW()-9)*10-1,11) -> UC1 C3 Elaborar los reportes de las incidencia de los sistemas de información considerando procedimientos establecidos y buenas prácticas de gestión de TI (marco metodologias COBIT y ITIL) | F12: Reporte de incidencia del sistema de información | G12: I | H12: 2 | I12: 2 | J12: =SUM(H12:I12) -> 4
D13: =OFFSET(Capacidades!$A$1,(ROW()-9)*10-1,11) | J13: =SUM(H13:I13) -> 0
D14: =OFFSET(Capacidades!$A$1,(ROW()-9)*10-1,11) | J14: =SUM(H14:I14) -> 0
D15: =OFFSET(Capacidades!$A$1,(ROW()-9)*10-1,11) | J15: =SUM(H15:I15) -> 0
D16: =OFFSET(Capacidades!$A$1,(ROW()-9)*10-1,11) | J16: =SUM(H16:I16) -> 0
D17: =OFFSET(Capacidades!$A$1,(ROW()-9)*10-1,11) | J17: =SUM(H17:I17) -> 0
D18: =OFFSET(Capacidades!$A$1,(ROW()-9)*10-1,11) | J18: =SUM(H18:I18) -> 0
D19: =OFFSET(Capacidades!$A$1,(ROW()-9)*10-1,11) | J19: =SUM(H19:I19) -> 0
D20: =OFFSET(Capacidades!$A$1,(ROW()-9)*10-1,11) | J20: =SUM(H20:I20) -> 0
D21: =OFFSET(Capacidades!$A$1,(ROW()-9)*10-1,11) | J21: =SUM(H21:I21) -> 0
D22: =OFFSET(Capacidades!$A$1,(ROW()-9)*10-1,11) | J22: =SUM(H22:I22) -> 0
D23: =OFFSET(Capacidades!$A$1,(ROW()-9)*10-1,11) | J23: =SUM(H23:I23) -> 0
D24: =OFFSET(Capacidades!$A$1,(ROW()-9)*10-1,11) | J24: =SUM(H24:I24) -> 0
... D29: =OFFSET(Capacidades!$A$1,(ROW()-9)*10-1,11) | J29: =SUM(H29:I29) -> 0
B30: Competencias para la empleabilidad | C30: CE1 Comunicación efectiva.- Expresar de manera clara los conceptos, ideas, sentimientos, hechos y opiniones en forma oral y escrita para comunicarse e interactuar con otras personas en contextos sociales y laborales diversos. (UD) | D30: =OFFSET(Capacidades!$A$1,(ROW()-9)*10-1,11) -> CE1 C1 Comunicar conceptos, ideas, opiniones, sentimientos y hechos en forma oral en situaciones relacionadas a su entorno personal y profesional. | F30: Comunicación Oral | G30: I | H30: 1 | I30: 1 | J30: =SUM(H30:I30) -> 2
D31: =OFFSET(Capacidades!$A$1,(ROW()-9)*10-1,11) -> CE1 C2 Comunicar conceptos, ideas, opiniones, sentimientos y hechos en forma escrita en situaciones relacionadas a su entorno social, educativo y laboral. | F31: Comunicación Escrita | G31: I | H31: 0 | I31: 1 | J31: =SUM(H31:I31) -> 1
D32: =OFFSET(Capacidades!$A$1,(ROW()-9)*10-1,11) | J32: =SUM(H32:I32) -> 0
D33: =OFFSET(Capacidades!$A$1,(ROW()-9)*10-1,11) | J33: =SUM(H33:I33) -> 0
D34: =OFFSET(Capacidades!$A$1,(ROW()-9)*10-1,11) | J34: =SUM(H34:I34) -> 0
D35: =OFFSET(Capacidades!$A$1,(ROW()-9)*10-1,11) | J35: =SUM(H35:I35) -> 0
D36: =OFFSET(Capacidades!$A$1,(ROW()-9)*10-1,11) | J36: =SUM(H36:I36) -> 0
D37: =OFFSET(Capacidades!$A$1,(ROW()-9)*10-1,11) | J37: =SUM(H37:I37) -> 0
D38: =OFFSET(Capacidades!$A$1,(ROW()-9)*10-1,11) | J38: =SUM(H38:I38) -> 0
D39: =OFFSET(Capacidades!$A$1,(ROW()-9)*10-1,11) | J39: =SUM(H39:I39) -> 0
B40: Experiencias formativas en situaciones reales de trabajo (ESRT) | H40: 0 | I40: 3 | J40: =SUM(H40:I40) -> 3
A41: MÓDULO 2: INFRAESTRUCTURA TI | B41: =$B$10 -> Competencias técnicas (Unidad de competencia) | C41: UC2: Ejecuta acciones de monitoreo y otras acciones operativas programadas, de acuerdo a las buenas prácticas de aseguramiento de operaciones del CPD (Centro de Procesamiento de Datos) y salvaguarda de la información de negocio | D41: =OFFSET(Capacidades!$A$302,(ROW()-40)*10-1,11) -> UC2 C1 Realizar el seguimiento de la infraestructua de TI de acuerdo a las buenas prácticas y normativa vigente. | F41: Monitoreo de infraestructura de TI | G41: II | H41: 2 | I41: 2 | J41: =SUM(H41:I41) -> 4
D42: =OFFSET(Capacidades!$A$302,(ROW()-40)*10-1,11) -> UC2 C2 Realizar el mantenimiento preventivo de la infraestructura de plataformas y servicios de TI teniendo en cuenta las especificaciones técnicas y políticas del servicio. | F42: Mantenimiento preventivo de Tecnologías de la Información | G42: II | H42: 2 | I42: 2 | J42: =SUM(H42:I42) -> 4
D43: =OFFSET(Capacidades!$A$302,(ROW()-40)*10-1,11) -> UC2 C3 Realizar el mantenimiento correctivo de la infraestructura de plataformas y servicios de TI teniendo en cuenta las especificaciones técnicas y políticas del servicio. | F43: Mantenimiento correctivo de Tecnologías de la Información | G43: II | H43: 2 | I43: 2 | J43: =SUM(H43:I43) -> 4
D44: =OFFSET(Capacidades!$A$302,(ROW()-40)*10-1,11) -> UC2 C4 Reportar incidencias y/o acciones relacionadas a la infraestructura de sistemas de información | F44: Reporte de incidencia de Tecnología de la Información | G44: II | H44: 1 | I44: 1 | J44: =SUM(H44:I44) -> 2
D45: =OFFSET(Capacidades!$A$302,(ROW()-40)*10-1,11) | J45: =SUM(H45:I45) -> 0
D46: =OFFSET(Capacidades!$A$302,(ROW()-40)*10-1,11) | J46: =SUM(H46:I46) -> 0
D47: =OFFSET(Capacidades!$A$302,(ROW()-40)*10-1,11) | J47: =SUM(H47:I47) -> 0
...

Sheet M1
A1: ORGANIZACIÓN DE LOS ELEMENTOS DEL MÓDULO
A3: DENOMINACIÓN DE LA INSTITUCIÓN | B3: =Perfil_Egreso!B3 -> CETPRO JUANJUI | F3: CÓDIGO MODULAR DEL CETPRO | I3: =Perfil_Egreso!E3 -> 0533836
A5: SECTOR ECONÓMICO | B5: =Perfil_Egreso!B5 -> INFORMACIÓN Y COMUNICACIONES | C5: FAMILIA PRODUCTIVA | D5: =Perfil_Egreso!D5 -> TECNOLOGÍAS DE LA INFORMACIÓN Y COMUNICACIONES - TICS | F5: ACTIVIDAD ECONÓMICA | I5: =Perfil_Egreso!B7 -> PROGRAMACIÓN INFORMÁTICA, CONSULTORÍA DE INFORMÁTICA Y ACTIVIDADES CONEXAS
A7: =Perfil_Egreso!A11 -> DENOMINACIÓN DEL PROGRAMA DE ESTUDIOS SEGÚN CNOF (según corresponda) | B7: =Perfil_Egreso!B11 -> REDES Y COMUNICACIONES | C7: CÓDIGO * | D7: =Perfil_Egreso!E11 -> J2662-2-001 | F7: =Perfil_Egreso!A9 -> DENOMINACIÓN VARIANTE | I7: =Perfil_Egreso!B9 -> 0
A9: =Perfil_Egreso!A13 -> FORMACIÓN** | B9: =Perfil_Egreso!B13 -> 0 | C9: N°. HORAS: | D9: =Itinerario!W17 -> 2112 | F9: N° CRÉDITOS: | I9: =Itinerario!T17 -> 80
A11: =Perfil_Egreso!C13 -> MODALIDAD DEL SERVICIO EDUCATIVO | B11: =Perfil_Egreso!D13 -> PRESENCIAL | F11: =Perfil_Egreso!A15 -> NIVEL FORMATIVO | I11: =Perfil_Egreso!B15 -> TÉCNICO
A13: UNIDAD DE COMPETENCIA DEL CATÁLOGO NACIONAL DE LA OFERTA FORMATIVA
A14: =Organización_Modular!C10 -> UC1: Atender requerimientos, incidentes y problemas de primer nivel, asimismo brindar asistencia a nivel operativo y funcional en la etapa de puesta en marcha de los sistemas o servicios de TI, según los procedimientos internos de atención, diseño del sistema o servicios, plan de implantación y buenas prácticas.
A15: DENOMINACIÓN DEL MÓDULO | B15: =Organización_Modular!A10 -> MÓDULO 1: GESTION DE SERVICIOS TECNOLOGICOS
A16: CAPACIDADES TÉCNICAS O ESPECÍFICAS | B16: INDICADORES DE LOGRO DE LA CAPACIDAD | C16: CONTENIDOS | D16: UNIDAD DIDÁCTICA | E16: Periodo | F16: CRÉDITOS | H16: CRÉDITOS | I16: HORAS | K16: HORAS | L16: PERFIL DOCENTE | M16: Filtrar
F17: Teórico | G17: Práctica | I17: Teórico | J17: Práctica
A18: =Capacidades!L10 -> UC1 C1 Identificar las necesidades o requerimientos del cliente considerando procedimientos establecidos y buenas prácticas de gestión de incidentes. | B18: =Capacidades!M10 -> C1 I1 Interpreta los reportes del funcionamiento del sistema de información en producción o puesta en marcha según las funciones y alcance de los sistemas. | C18: •Sistemas de información (Alcance, tipos, arquitectura, componentes y funcionalidad). •Ciclo de vida del software. •Reportes de funcionalidad del sistema de información. | D18: =Organización_Modular!F10 -> Análisis de requerimientos de Tecnología de la Información. | E18: =Organización_Modular!G10 -> I | F18: =Organización_Modular!H10 -> 2 | G18: =Organización_Modular!I10 -> 3 | H18: =SUM(F18:G18) -> 5 | I18: =F18*16 -> 32 | J18: =G18*32 -> 96 | K18: =SUM(I18:J18) -> 128 | L18: PROFESIONAL EN COMPUTACION E INFORMATICA, TECNICO PROFESIONAL EN COMPUTACION E INFORMATICA, TECNICO EN OPEFRACION DE COMPUTADORAS - PROFESIONAL EN PEDAGOGIA | M18: =B18 -> C1 I1 Interpreta los reportes del funcionamiento del sistema de información en producción o puesta en marcha según las funciones y alcance de los sistemas.
B19: =Capacidades!M11 -> C1 I2 Detecta las fallas e incidencias del sistema de información en producción o puesta en marcha considerando procedimientos establecidos y buenas prácticas de gestión de incidentes. | C19: •Gestión de incidencias •Buenas prácticas de gestion de TI según ITIL (deteccion de fallos e incidencias) •Gestión de control de TI según COBIT (deteccion de fallos e incidencias) | M19: =B19 -> C1 I2 Detecta las fallas e incidencias del sistema de información en producción o puesta en marcha considerando procedimientos establecidos y buenas prácticas de gestión de incidentes.
B20: =Capacidades!M12 -> C1 I3 Clasifica las fallas e incidencias del sistema de información en producción o puesta en marcha considerando procedimientos establecidos y buenas prácticas de gestión de incidentes. | C20: •Gestion de incidencias •Buenas prácticas de gestion de TI según ITIL (interpretación, clasificación) •Gestión de control de TI según COBIT (interpretación, clasificación) | M20: =B20 -> C1 I3 Clasifica las fallas e incidencias del sistema de información en producción o puesta en marcha considerando procedimientos establecidos y buenas prácticas de gestión de incidentes.
A21: =Capacidades!L20 -> UC1 C2 Resolver las incidencias o fallas del sistema de información en el primer nivel considerando procedimientos establecidos y buenas prácticas de gestión de TI (marco metodologias COBIT y ITIL) | B21: =Capacidades!M20 -> C2 I1 Analiza las incidencias o fallas del sistema de información en el primer nivel considerando procedimientos establecidos y buenas prácticas de gestión de TI (marco metodologias COBIT y ITIL) | C21: •Gestión de incidencias. •Análisis de fallas. •Fallas de sistema. •Fallas de hardware. •Fallas de software. •Gestión de control de TI según COBIT e ITIL (interpretación, clasificación) | D21: =Organización_Modular!F11 -> Atención de incidencias del sistema de infomación | E21: =Organización_Modular!G11 -> I | F21: =Organización_Modular!H11 -> 2 | G21: =Organización_Modular!I11 -> 3 | H21: =SUM(F21:G21) -> 5 | I21: =F21*16 -> 32 | J21: =G21*32 -> 96 | K21: =SUM(I21:J21) -> 128 | M21: =B21 -> C2 I1 Analiza las incidencias o fallas del sistema de información en el primer nivel considerando procedimientos establecidos y buenas prácticas de gestión de TI (marco metodologias COBIT y ITIL)
B22: =Capacidades!M21 -> C2 I2 Plantea estrategias de solución teniendo en cuenta las incidencia o falla del sistema de información, los procedimiento establecidos y buenas prácticas de gestión de TI | C22: •Análisis de sistemas de información. •Elaboración de estrategias de solucion de fallo en TI. •Patrones de fallo de sistemas. •Funcionalidad integral de sistemas de informacion. | M22: =B22 -> C2 I2 Plantea estrategias de solución teniendo en cuenta las incidencia o falla del sistema de información, los procedimiento establecidos y buenas prácticas de gestión de TI
B23: =Capacidades!M22 -> C2 I3 Determina la estrategia de solución teniendo en cuenta las incidencia o falla del sistema de información, los procedimiento establecidos y buenas prácticas de gestión de TI | C23: •Metodologías de selección de estrategias. •Buenas prácticas y control según COBIT e ITIL para selección de estrategias de solución. | M23: =B23 -> C2 I3 Determina la estrategia de solución teniendo en cuenta las incidencia o falla del sistema de información, los procedimiento establecidos y buenas prácticas de gestión de TI
B24: =Capacidades!M23 -> C2 I4 Aplica estrategia de solución siguiendo los procedimiento establecidos y buenas prácticas de gestión de TI | C24: •Solucion de problemas de primer nivel en Sistemas de información. •Buenas prácticas y control según COBIT e ITIL para solucion de problemas de primer nivel en Sistemas de información. | M24: =B24 -> C2 I4 Aplica estrategia de solución siguiendo los procedimiento establecidos y buenas prácticas de gestión de TI
B25: =Capacidades!M24 -> C2 I5 Comprueba el funcionamiento del sistema de información considerando los estándares de calidad establecidos. | C25: •Verificación y seguimiento de actividades correctivas de primer nivel en fallos de sistemas de información. •Buenas prácticas y control según COBIT e ITIL en la verificación y el seguimiento. | M25: =B25 -> C2 I5 Comprueba el funcionamiento del sistema de información considerando los estándares de calidad establecidos.
B26: =Capacidades!M25 | M26: =B26
M27: =B27 -> 0
M28: =B28 -> 0
M29: =B29 -> 0
B30: =Capacidades!M29 | M30: =B30
A31: =Capacidades!L30 -> UC1 C3 Elaborar los reportes de las incidencia de los sistemas de información considerando procedimientos establecidos y buenas prácticas de gestión de TI (marco metodologias COBIT y ITIL) | B31: =Capacidades!M30 -> C2 I1 Identifica los incidentes o requerimientos de los usuarios atendidos aplicando los procedimientos establecidos según la política de la organización. | C31: •Flujogramas y politicas de atención de la organización. •Buenas prácticas y control según COBIT e ITIL en el proceso de finalización de atención de reportes. | D31: =Organización_Modular!F12 -> Reporte de incidencia del sistema de información | E31: =Organización_Modular!G12 -> I | F31: =Organización_Modular!H12 -> 2 | G31: =Organización_Modular!I12 -> 2 | H31: =SUM(F31:G31) -> 4 | I31: =F31*16 -> 32 | J31: =G31*32 -> 64 | K31: =SUM(I31:J31) -> 96 | L31: PROFESIONAL EN COMPUTACION E INFORMATICA, TECNICO PROFESIONAL EN COMPUTACION E INFORMATICA, TECNICO EN OPEFRACION DE COMPUTADORAS - PROFESIONAL EN PEDAGOGIA | M31: =B31 -> C2 I1 Identifica los incidentes o requerimientos de los usuarios atendidos aplicando los procedimientos establecidos según la política de la organización.
B32: =Capacidades!M31 -> C2 I2 Señala las lecciones aprendidas considerando procedimientos establecidos y buenas practicas de gestión de TI. | C32: •Capacidad de autoanalisis. •Retroalimentación. •Optimización de procesos. | M32: =B32 -> C2 I2 Señala las lecciones aprendidas considerando procedimientos establecidos y buenas practicas de gestión de TI.
B33: =Capacidades!M32 -> C2 I3 Clasifica los incidentes o requerimientos de los usuarios atendidos en una BD o repositorio considerando procedimientos establecidos y buenas practicas de gestión de TI. | C33: •Buenas prácticas y control según COBIT e ITIL en la gestión de clasificacion de incidentes en bases de datos y repositorios. | M33: =B33 -> C2 I3 Clasifica los incidentes o requerimientos de los usuarios atendidos en una BD o repositorio considerando procedimientos establecidos y buenas practicas de gestión de TI.
B34: =Capacidades!M33 -> C2 I4 Documenta las acciones de gestión de inicdenicias y/o requerimientos generando reportes de cumplimiento, de acuerdo a los niveles de servicio TI. | C34: •Buenas prácticas y control según COBIT e ITIL en la documentación relacionada a manejo de incidencias. | M34: =B34 -> C2 I4 Documenta las acciones de gestión de inicdenicias y/o requerimientos generando reportes de cumplimiento, de acuerdo a los niveles de servicio TI.
B35: =Capacidades!M34 -> C2 I5 Realiza copias de seguridad según los procedimientos establecidos. | C35: •Copias de seguridad. •Herramientas de gestion de copias de seguridad. •Bases de datos y repositorios. •Buenas prácticas y control según COBIT e ITIL en el manejo de repositorios y/o backups de respaldo de información. | M35: =B35 -> C2 I5 Realiza copias de seguridad según los procedimientos establecidos.
B36: =Capacidades!M35 | M36: =B36
B37: =Capacidades!M36 | M37: =B37
B38: =Capacidades!M37 | M38: =B38
B39: =Capacidades!M38 | M39: =B39
B40: =Capacidades!M39 | M40: =B40
A41: =Capacidades!L40 | B41: =Capacidades!M40 | D41: =Organización_Modular!F13 -> 0 | E41: =Organización_Modular!G13 -> 0 | F41: =Organización_Modular!H13 -> 0 | G41: =Organización_Modular!I13 -> 0 | H41: =SUM(F41:G41) -> 0 | I41: =F41*16 -> 0 | J41: =G41*32 -> 0 | K41: =SUM(I41:J41) -> 0 | M41: =B41
B42: =Capacidades!M41 | M42: =B42
B43: =Capacidades!M42 | M43: =B43
B44: =Capacidades!M43 | M44: =B44
B45: =Capacidades!M44 | M45: =B45
B46: =Capacidades!M45 | M46: =B46
...

Sheet M2
A1: ='M1'!A1:L1 -> ORGANIZACIÓN DE LOS ELEMENTOS DEL MÓDULO
A3: DENOMINACIÓN DE LA INSTITUCIÓN | B3: =Perfil_Egreso!B3 -> CETPRO JUANJUI | F3: CÓDIGO MODULAR DEL CETPRO | I3: =Perfil_Egreso!E3 -> 0533836
A5: SECTOR ECONÓMICO | B5: =Perfil_Egreso!B5 -> INFORMACIÓN Y COMUNICACIONES | C5: FAMILIA PRODUCTIVA | D5: =Perfil_Egreso!D5 -> TECNOLOGÍAS DE LA INFORMACIÓN Y COMUNICACIONES - TICS | F5: ACTIVIDAD ECONÓMICA | I5: =Perfil_Egreso!B7 -> PROGRAMACIÓN INFORMÁTICA, CONSULTORÍA DE INFORMÁTICA Y ACTIVIDADES CONEXAS
A7: =Perfil_Egreso!A11 -> DENOMINACIÓN DEL PROGRAMA DE ESTUDIOS SEGÚN CNOF (según corresponda) | B7: =Perfil_Egreso!B11 -> REDES Y COMUNICACIONES | C7: CÓDIGO * | D7: =Perfil_Egreso!E11 -> J2662-2-001 | F7: =Perfil_Egreso!A9 -> DENOMINACIÓN VARIANTE | I7: =Perfil_Egreso!B9 -> 0
A9: =Perfil_Egreso!A13 -> FORMACIÓN** | B9: =Perfil_Egreso!B13 -> 0 | C9: N°. HORAS: | D9: =Itinerario!W17 -> 2112 | F9: N° CRÉDITOS: | I9: =Itinerario!T17 -> 80
A11: =Perfil_Egreso!C13 -> MODALIDAD DEL SERVICIO EDUCATIVO | B11: =Perfil_Egreso!D13 -> PRESENCIAL | F11: =Perfil_Egreso!A15 -> NIVEL FORMATIVO | I11: =Perfil_Egreso!B15 -> TÉCNICO
A13: UNIDAD DE COMPETENCIA DEL CATÁLOGO NACIONAL DE LA OFERTA FORMATIVA
A14: =Organización_Modular!C41 -> UC2: Ejecuta acciones de monitoreo y otras acciones operativas programadas, de acuerdo a las buenas prácticas de aseguramiento de operaciones del CPD (Centro de Procesamiento de Datos) y salvaguarda de la información de negocio
A15: DENOMINACIÓN DEL MÓDULO | B15: =Organización_Modular!A41 -> MÓDULO 2: INFRAESTRUCTURA TI
A16: CAPACIDADES TÉCNICAS O ESPECÍFICAS | B16: INDICADORES DE LOGRO DE LA CAPACIDAD | C16: CONTENIDOS | D16: UNIDAD DIDÁCTICA | E16: Periodo | F16: CRÉDITOS | H16: CRÉDITOS | I16: HORAS | K16: HORAS | L16: PERFIL DOCENTE | M16: Filtrar
F17: Teórico | G17: Práctica | I17: Teórico | J17: Práctica
A18: =Capacidades!L311 -> UC2 C1 Realizar el seguimiento de la infraestructua de TI de acuerdo a las buenas prácticas y normativa vigente. | B18: =Capacidades!M311 -> C1 I1 Identifica las incidencias y/o acciones operativas durante el monitoreo relacionadas a la infraestructura de TI. | C18: • Infraestructura de TI. • Hardware. • Redes inalámbricas. • Redes cableadas. • Telefonía. • Equipos básicos de cómputo. • Monitoreo de infraestructura de TI. • Acciónes operativas de monitoreo en el CPD. • Gestión de incidencias. | D18: =Organización_Modular!F41 -> Monitoreo de infraestructura de TI | E18: =Organización_Modular!G41 -> II | F18: =Organización_Modular!H41 -> 2 | G18: =Organización_Modular!I41 -> 2 | H18: =SUM(F18:G18) -> 4 | I18: =F18*16 -> 32 | J18: =G18*32 -> 64 | K18: =SUM(I18:J18) -> 96 | L18: PROFESIONAL EN COMPUTACION E INFORMATICA, TECNICO PROFESIONAL EN COMPUTACION E INFORMATICA, TECNICO EN OPEFRACION DE COMPUTADORAS - PROFESIONAL EN PEDAGOGIA | M18: =B18 -> C1 I1 Identifica las incidencias y/o acciones operativas durante el monitoreo relacionadas a la infraestructura de TI.
B19: =Capacidades!M312 -> C1 I2 Organiza los reportes de incidencias y/o acciones durante el monitoreo relacionadas a la infraestructura de TI. | C19: •Analisis de incidencias y/o acciones. •Buenas prácticas y control según COBIT e ITIL en la organización de reportes e incidencias. | M19: =B19 -> C1 I2 Organiza los reportes de incidencias y/o acciones durante el monitoreo relacionadas a la infraestructura de TI.
B20: =Capacidades!M313 -> C1 I3 Elabora un informe de incidencias y/o acciones de monitoreo teniendo en cuenta las estándares establecidos y las políticas de la organización | C20: •Buenas prácticas y control según COBIT e ITIL en la documentación e informes parciales relaciconados a las incidencias y/o acciones de monitoreo. | M20: =B20 -> C1 I3 Elabora un informe de incidencias y/o acciones de monitoreo teniendo en cuenta las estándares establecidos y las políticas de la organización
B21: =Capacidades!M314 | M21: =B21
B22: =Capacidades!M315 | M22: =B22
B23: =Capacidades!M316 | M23: =B23
B24: =Capacidades!M317 | M24: =B24
B25: =Capacidades!M318 | M25: =B25
B26: =Capacidades!M319 | M26: =B26
B27: =Capacidades!M320 | M27: =B27
